Workbook

Sheet AuT+D损益
A1: SGE Au(T+D) P&L Attribution (Single Sheet, Gross Long/Short) — CNY
A4: Parameter | B4: Value | C4: Notes | K4: Item | L4: Amount (CNY) | M4: Meaning
A5: TradeDate 估值日 | B5: 46038 | C5: e.g., 2025-12-27 | K5: PD_NetLots 上一交易日净持仓 | L5: =$B$9-$B$10 -> 10 | M5: Prior net lots (gross long - gross short)
A6: Unit_g_per_lot 交易单位 | B6: 1000 | C6: Au(T+D) = 1 kg/lot = 1000 g | K6: BuyLots_Today 今日买入 | L6: =SUMIF($B$24:$B$222,"B",$C$24:$C$222)+SUMIF($B$24:$B$222,"BUY",$C$24:$C$222)+SUMIF($B$24:$B$222,"买",$C$24:$C$222) -> 15 | M6: buys today (lots)
A7: PD_settle_RMB_per_g 昨日收盘价/克 | B7: ='上海金vsComex Future'!D110 -> 1030.92 | C7: Prior day settlement (元/克) | K7: SellLots_Today 今日卖出 | L7: =SUMIF($B$24:$B$222,"S",$C$24:$C$222)+SUMIF($B$24:$B$222,"SELL",$C$24:$C$222)+SUMIF($B$24:$B$222,"卖",$C$24:$C$222) -> 10 | M7: sells today (lots)
A8: CD_settle_RMB_per_g 今日收盘价/克 | B8: ='上海金vsComex Future'!D111 -> 1030.66 | C8: Today settlement (元/克) | K8: Trade_NetLots 日内净头寸 | L8: =L6-L7 -> 5 | M8: Net trade lots (buy - sell)
A9: PD_long_lots 上一交易日累计买入手数 | B9: 20 | C9: Prior day gross long lots | K9: EOD_NetLots_Derived 当前净持仓（手） | L9: =L5+L8 -> 15 | M9: Derived EOD net lots (may differ from statement if gross is used)
A10: PD_short_lots 上一交易日累计卖出手数 | B10: 10 | C10: Prior day gross short lots | K10: EOD_LongLots_Gross 买入总手数 | L10: =B9+L6 -> 35 | M10: EOD gross long lots (statement input)
A11: FeeRate 手续费率 | B11: 0.0002 | C11: Transaction fee rate (万分之二) | K11: EOD_ShortLots_Gross 卖出总手数 | L11: =B10+L7 -> 20 | M11: EOD gross short lots (statement input)
A12: DeferredRate_per_day 延期补偿费率 | B12: 0.00011 | C12: Deferred fee rate per calendar day | K12: EOD_NetLots_Gross | L12: =L8+L5 -> 15 | M12: EOD net lots computed from gross inputs
A13: DeferredDirection 延期补偿费方向 | B13: 多付空 | C13: Enter: 多付空 or 空付多
A14: DayCount 延期补偿费天数 | B14: 1 | C14: Calendar days applied (1 normally; 3 on Friday, etc.) | K14: Position_MTM_CNY 头寸损益 | L14: =($B$8-$B$7)*L12*$B$6 -> -3900 | M14: Prior net lots MTM from PD settle to CD settle
A15: Margin Required 保证金比例 | B15: 0.16 | K15: Trade_ExecPnL_CNY 日内损益 | L15: =SUM($I$24:$I$222) -> 64300 | M15: Execution P&L vs CD settlement
A16: EOD_long_lots_gross 买入总手数 | B16: 25 | C16: End-of-day gross long lots (from statement) | K16: Price_Total_CNY 今日交易损益 | L16: =L14+L15+B20 -> 70400 | M16: Total price P&L
A17: EOD_short_lots_gross 卖出总手数 | B17: 10 | C17: End-of-day gross short lots (from statement)
A18: DirectionSign | B18: =IF($B$13="多付空",1,IF($B$13="空付多",-1,0)) -> 1 | C18: Computed: 多付空=+1, 空付多=-1 | K18: Notional_Long_EOD_CNY 买入总支出 | L18: =L10*$B$8*$B$6 -> 36073100 | M18: Gross long notional at CD settle
A19: Margin Required Amt 保证金金额 | B19: =B15*L14 -> -624 | K19: Notional_Short_EOD_CNY 卖出总支出 | L19: =L11*$B$8*$B$6 -> 20613200 | M19: Gross short notional at CD settle
A20: PD_Trade_ExecPnL_CNY 累计日内损益 | B20: 10000
A22: TradeDate 今日交易 | B22: =B5 -> 46038
A23: TradeTime | B23: Side | C23: QtyLots | D23: TradePrice_RMB_per_g | E23: Unit_g | F23: CD_Settle | G23: TradeNotional_CNY | H23: Fee_CNY | I23: ExecPnL_vs_Settle_CNY | K23: Deferred_PnL_Gross_CNY 延期补偿费 | L23: =(-$B$18)*L18*$B$12*$B$14 + ($B$18)*L19*$B$12*$B$14 -> -1700.589 | M23: Gross deferred fee P&L (uses EOD gross long/short, direction sign, rate, daycount)
A24: 10:05 | B24: S | C24: 10 | D24: 1035.8 | E24: =$B$6 -> 1000 | F24: =$B$8 -> 1030.66 | G24: =$C24*$D24*$E24 -> 10358000 | H24: =$G24*$B$11 -> 2071.6 | I24: =IF(OR($B24="B",$B24="BUY",$B24="买"),($F24-$D24)*$C24*$E24,IF(OR($B24="S",$B24="SELL",$B24="卖"),($D24-$F24)*$C24*$E24,0)) -> 51400 | K24: Residual_vs_Statement | L24: =IF($B$15="",$B$15-L24) -> FALSE | M24: Statement total - explained
A25: 11:20 | B25: B | C25: 5 | D25: 1029.2 | E25: =$B$6 -> 1000 | F25: =$B$8 -> 1030.66 | G25: =$C25*$D25*$E25 -> 5146000 | H25: =$G25*$B$11 -> 1029.2 | I25: =IF(OR($B25="B",$B25="BUY",$B25="买"),($F25-$D25)*$C25*$E25,IF(OR($B25="S",$B25="SELL",$B25="卖"),($D25-$F25)*$C25*$E25,0)) -> 7300 | K25: Fees_PnL_CNY 日内手续费 | L25: =-SUM($H$24:$H$222) -> -5161 | M25: Transaction fees (negative)
A26: 13:45 | B26: B | C26: 10 | D26: 1030.1 | E26: =$B$6 -> 1000 | F26: =$B$8 -> 1030.66 | G26: =$C26*$D26*$E26 -> 10301000 | H26: =$G26*$B$11 -> 2060.2 | I26: =IF(OR($B26="B",$B26="BUY",$B26="买"),($F26-$D26)*$C26*$E26,IF(OR($B26="S",$B26="SELL",$B26="卖"),($D26-$F26)*$C26*$E26,0)) -> 5600 | K26: Total_Explained_CNY 今日总损益 | L26: =L16+L22+L23 -> 68699.411 | M26: Explained total (Price + Deferred + Fees)

Sheet AuT+D对冲AU99.99现货持仓
A1: Au(T+D) + Spot Hedge (Daily P&L Explain) - Spot vs Basis vs Deferred Fee
A3: Inputs
A4: Name | B4: Value
A5: SpotQty_g (physical grams, +long) Ag99.99现货持仓（克） | B5: 5000
A6: TD_Lots (Au(T+D), +long / -short) Au(T+D)合约 | B6: -5
A7: TD_Unit_g_per_lot 交易单位 | B7: 1000
A8: Default_DeferredRate_per_day 延期补偿费率 | B8: 0.00011
A9: Default_DirectionSign (+1=多付空, -1=空付多) 延期补偿费方向 | B9: 1
A10: Default_DayCount 延期补偿费天数 | B10: 1
A11: Default_FeesPnL_CNY_per_day (negative) 其他费用， 资金成本等 | B11: -50
A12: Margin Required 保证金比例 | B12: 0.16
A14: Date | B14: Au(T+D)价格/g | C14: AU99.99价格 | D14: Basis_CNYg (=Spot-TD)基差 | E14: Au(T+D)_MTM_PnL_CNY， Au(T+D)损益 | F14: AU99.99_MTM_PnL_CNY， AU99.99损益 | G14: NetPrice_PnL_CNY (=Spot+TD) 对冲后净损益 | H14: Basis_PnL_CNY (diag) 基差损益分析 | I14: DeferredRate延期补偿费率 | J14: DirSign延期补偿费支付方向 | K14: DayCount延期补偿费天数 | L14: DeferredFee_PnL_CNY-延期补偿费 | M14: Fees_PnL_CNY-其他费用 | N14: Total_PnL_CNY-今日综合损益 | O14: Margin Required Amt 保证金金额
A15: 2026-01-05 | B15: ='上海金vsComex Future'!D102 -> 989.68 | C15: ='上海金vsComex Future'!E102 -> 990.83 | D15: =B15-C15 -> -1.15 | I15: =$B$8 -> 0.00011 | J15: =$B$9 -> 1 | K15: =$B$10 -> 1 | L15: =-SIGN($B$6)*J15*ABS($B$6)*$B$7*C15*I15*K15 -> 544.9565 | M15: =$B$11 -> -50 | N15: =G15+L15+M15 -> 494.9565 | O15: =$B$5*B15*$B$12 -> 791744
A16: 2026-01-06 | B16: ='上海金vsComex Future'!D103 -> 1000.04 | C16: ='上海金vsComex Future'!E103 -> 1001.92 | D16: =B16-C16 -> -1.88 | E16: =$B$6*$B$7*(B16-B15) -> -51800 | F16: =$B$5*(C16-C15) -> 55450 | G16: =E16+F16 -> 3650 | H16: =$B$6*$B$7*(D16-D15) -> 3650 | I16: =$B$8 -> 0.00011 | J16: =$B$9*-1 -> -1 | K16: =$B$10 -> 1 | L16: =-SIGN($B$6)*J16*ABS($B$6)*$B$7*C16*I16*K16 -> -551.056 | M16: =$B$11 -> -50 | N16: =G16+L16+M16 -> 3048.944 | O16: =$B$5*B16*$B$12 -> 800032
A17: 2026-01-07 | B17: ='上海金vsComex Future'!D104 -> 1001.05 | C17: ='上海金vsComex Future'!E104 -> 1002.02 | D17: =B17-C17 -> -0.97 | E17: =$B$6*$B$7*(B17-B16) -> -5050 | F17: =$B$5*(C17-C16) -> 500 | G17: =E17+F17 -> -4550 | H17: =$B$6*$B$7*(D17-D16) -> -4550 | I17: =$B$8 -> 0.00011 | J17: =$B$9 -> 1 | K17: =$B$10 -> 1 | L17: =-SIGN($B$6)*J17*ABS($B$6)*$B$7*C17*I17*K17 -> 551.111 | M17: =$B$11 -> -50 | N17: =G17+L17+M17 -> -4048.889 | O17: =$B$5*B17*$B$12 -> 800840
A18: 2026-01-08 | B18: ='上海金vsComex Future'!D105 -> 996.19 | C18: ='上海金vsComex Future'!E105 -> 996.57 | D18: =B18-C18 -> -0.38 | E18: =$B$6*$B$7*(B18-B17) -> 24300 | F18: =$B$5*(C18-C17) -> -27250 | G18: =E18+F18 -> -2950 | H18: =$B$6*$B$7*(D18-D17) -> -2950 | I18: =$B$8 -> 0.00011 | J18: =$B$9 -> 1 | K18: =$B$10 -> 1 | L18: =-SIGN($B$6)*J18*ABS($B$6)*$B$7*C18*I18*K18 -> 548.1135 | M18: =$B$11 -> -50 | N18: =G18+L18+M18 -> -2451.8865 | O18: =$B$5*B18*$B$12 -> 796952
A19: 2026-01-09 | B19: ='上海金vsComex Future'!D106 -> 1000 | C19: ='上海金vsComex Future'!E106 -> 1002.51 | D19: =B19-C19 -> -2.51 | E19: =$B$6*$B$7*(B19-B18) -> -19050 | F19: =$B$5*(C19-C18) -> 29700 | G19: =E19+F19 -> 10650 | H19: =$B$6*$B$7*(D19-D18) -> 10650 | I19: =$B$8 -> 0.00011 | J19: =$B$9 -> 1 | K19: =$B$10 -> 1 | L19: =-SIGN($B$6)*J19*ABS($B$6)*$B$7*C19*I19*K19 -> 551.3805 | M19: =$B$11 -> -50 | N19: =G19+L19+M19 -> 11151.38 | O19: =$B$5*B19*$B$12 -> 800000
A20: 2026-01-12 | B20: ='上海金vsComex Future'!D107 -> 1019 | C20: ='上海金vsComex Future'!E107 -> 1022.57 | D20: =B20-C20 -> -3.57 | E20: =$B$6*$B$7*(B20-B19) -> -95000 | F20: =$B$5*(C20-C19) -> 100300 | G20: =E20+F20 -> 5300 | H20: =$B$6*$B$7*(D20-D19) -> 5300 | I20: =$B$8 -> 0.00011 | J20: =$B$9*-1 -> -1 | K20: 3 | L20: =-SIGN($B$6)*J20*ABS($B$6)*$B$7*C20*I20*K20 -> -1687.2405 | M20: =$B$11 -> -50 | N20: =G20+L20+M20 -> 3562.7595 | O20: =$B$5*B20*$B$12 -> 815200
A21: 2026-01-13 | B21: ='上海金vsComex Future'!D108 -> 1025.84 | C21: ='上海金vsComex Future'!E108 -> 1025.84 | D21: =B21-C21 -> 0 | E21: =$B$6*$B$7*(B21-B20) -> -34200 | F21: =$B$5*(C21-C20) -> 16350 | G21: =E21+F21 -> -17850 | H21: =$B$6*$B$7*(D21-D20) -> -17850 | I21: =$B$8 -> 0.00011 | J21: =$B$9*-1 -> -1 | K21: =$B$10 -> 1 | L21: =-SIGN($B$6)*J21*ABS($B$6)*$B$7*C21*I21*K21 -> -564.212 | M21: =$B$11 -> -50 | N21: =G21+L21+M21 -> -18464.212 | O21: =$B$5*B21*$B$12 -> 820672
A22: 2026-01-14 | B22: ='上海金vsComex Future'!D109 -> 1033.49 | C22: ='上海金vsComex Future'!E109 -> 1035.39 | D22: =B22-C22 -> -1.9 | E22: =$B$6*$B$7*(B22-B21) -> -38250 | F22: =$B$5*(C22-C21) -> 47750 | G22: =E22+F22 -> 9500 | H22: =$B$6*$B$7*(D22-D21) -> 9500 | I22: =$B$8 -> 0.00011 | J22: =$B$9 -> 1 | K22: =$B$10 -> 1 | L22: =-SIGN($B$6)*J22*ABS($B$6)*$B$7*C22*I22*K22 -> 569.4645 | M22: =$B$11 -> -50 | N22: =G22+L22+M22 -> 10019.465 | O22: =$B$5*B22*$B$12 -> 826792
A23: 2026-01-15 | B23: ='上海金vsComex Future'!D110 -> 1030.92 | C23: ='上海金vsComex Future'!E110 -> 1031.07 | D23: =B23-C23 -> -0.15 | E23: =$B$6*$B$7*(B23-B22) -> 12850 | F23: =$B$5*(C23-C22) -> -21600 | G23: =E23+F23 -> -8750 | H23: =$B$6*$B$7*(D23-D22) -> -8750 | I23: =$B$8 -> 0.00011 | J23: =$B$9*-1 -> -1 | K23: =$B$10 -> 1 | L23: =-SIGN($B$6)*J23*ABS($B$6)*$B$7*C23*I23*K23 -> -567.0885 | M23: =$B$11 -> -50 | N23: =G23+L23+M23 -> -9367.0885 | O23: =$B$5*B23*$B$12 -> 824736
A24: 2026-01-16 | B24: ='上海金vsComex Future'!D111 -> 1030.66 | C24: ='上海金vsComex Future'!E111 -> 1030.91 | D24: =B24-C24 -> -0.25 | E24: =$B$6*$B$7*(B24-B23) -> 1300 | F24: =$B$5*(C24-C23) -> -800 | G24: =E24+F24 -> 500 | H24: =$B$6*$B$7*(D24-D23) -> 500 | I24: =$B$8 -> 0.00011 | J24: =$B$9 -> 1 | K24: =$B$10 -> 1 | L24: =-SIGN($B$6)*J24*ABS($B$6)*$B$7*C24*I24*K24 -> 567.0005 | M24: =$B$11 -> -50 | N24: =G24+L24+M24 -> 1017.0005 | O24: =$B$5*B24*$B$12 -> 824528

Sheet 上海金vsComex Future
A1: SGE vs COMEX Relative Value
A2: Parameters
A3: Name | B3: Value | C3: Notes
A4: Lookback_N (days) | B4: 60
A5: MinEdge_CNYg (must exceed costs) | B5: 0.3
A6: EntryZ | B6: 2
A7: ExitZ | B7: 0.5
A8: StopZ | B8: 3.5
A9: MaxAbsPrem_CNYg (regime filter) | B9: 5
A10: MaxHoldDays | B10: 10
A11: BaseSize_kg | B11: 5
A12: MaxSizeMultiple | B12: 2
A13: UseFXHedge (1=yes,0=no) | B13: 1
A14: g_per_oz | B14: 31.1035
A15: GC_oz_per_contract | B15: 100
... A17: CostBuffer_CNYg (fees+slip est.) | B17: 0.1
A19: Legend: | B19: Premium = SGE - (GC*USDCNY/31.1035). Signals trade premium mean reversion. Not risk-free without import.
A20: Date | B20: CME_GC_Settle (USD/oz) | C20: USDCNY | D20: SGE_AuTD_Settle (CNY/g) | E20: SGE_Au9999_Settle (CNY/g) | F20: SGE_Au9995_Settle (CNY/g) | G20: Parity_CNYg (GC*FX/31.1035) Comex 转换人民币/克 | H20: Prem_TD_CNYg 上海金TD和Comex差值 | I20: Prem_9999_CNYg，上海金9999和Comex差值 | J20: Prem_9995_CNYg | K20: Prem_Comex_Gold (Δ prem)期货价格变化（CNY/g） | L20: Prem_Comex_FX (Δ prem)汇率价格变化（CNY/g） | M20: Prem_SGE_TD_Local (Δ prem))延迟合约价格变化（CNY/g） | N20: Prem_SGE_9999_Local (Δ prem)现货价格变化（CNY/g） | O20: Basis_CNYg (=Spot-TD)基差 | P20: Prem_TD_Comex Moving Ave 60日平局变化 | Q20: Prem_TD_SDEV | R20: Prem_TD_Zscore | S20: Signal | T20: SizeMultiple | U20: TradeSize_g | V20: TD_Lots | W20: GC_Contracts | X20: FXHedge_USDNotional | Y20: EdgeToMean_CNY | Z20: Go_NoGo
A21: 2025-09-01 | B21: 3592.2 | C21: 7.1378 | D21: 792.77 | E21: 795.03 | F21: 557.827 | G21: =(B21*C21)/$B$14 -> 824.35755 | H21: =D21-G21 -> -31.587553 | I21: =E21-G21 -> -29.327553 | J21: =F21-G21 -> -266.53055 | P21: =IF(COUNT($H$21:H21)<$B$4,"",AVERAGE(INDEX($H$21:H21,COUNT($H$21:H21)-$B$4+1):H21)) | Q21: =IF(COUNT($H$21:H21)<$B$4,"",_xludf.STDEV.S(INDEX($H$21:H21,COUNT($H$21:H21)-$B$4+1):H21)) | R21: =IF(OR(P21="",Q21=""),"",(H21-P21)/Q21) | T21: =IF(R21="","",MIN($B$12,ABS(R21)/$B$6)) | U21: =IF(R21="","",$B$11*1000*T21) | X21: =IF(OR(R21="",$B$13=0),0,-W21*$B$15*B21) -> 0 | Z21: =IF(R21="","",IF(AND(ABS(R21)>=$B$6,ABS(H21)>=$B$5,ABS(H21)<=$B$9,ABS(Y21)>=U21*($B$5+$B$17)),"GO",IF(ABS(R21)>=$B$6,"NO_GO","")))
A22: 2025-09-02 | B22: 3592.2 | C22: 7.1395 | D22: 800.94 | E22: 801.72 | F22: 557.652 | G22: =(B22*C22)/$B$14 -> 824.55389 | H22: =D22-G22 -> -23.613889 | I22: =E22-G22 -> -22.833889 | J22: =F22-G22 -> -266.90189 | K22: =-(C21/$B$14)*(B22-B21) -> 0 | L22: =(B22/$B$14)*(C22-C21) -> 0.1963361 | M22: =D22-D21 -> 8.17 | N22: =E22-E21 -> 6.69 | O22: =N22-M22 -> -1.48 | P22: =IF(COUNT($H$21:H22)<$B$4,"",AVERAGE(INDEX($H$21:H22,COUNT($H$21:H22)-$B$4+1):H22)) | Q22: =IF(COUNT($H$21:H22)<$B$4,"",_xludf.STDEV.S(INDEX($H$21:H22,COUNT($H$21:H22)-$B$4+1):H22)) | R22: =IF(OR(P22="",Q22=""),"",(H22-P22)/Q22) | T22: =IF(R22="","",MIN($B$12,ABS(R22)/$B$6)) | U22: =IF(R22="","",$B$11*1000*T22) | X22: =IF(OR(R22="",$B$13=0),0,-W22*$B$15*B22) -> 0 | Z22: =IF(R22="","",IF(AND(ABS(R22)>=$B$6,ABS(H22)>=$B$5,ABS(H22)<=$B$9,ABS(Y22)>=U22*($B$5+$B$17)),"GO",IF(ABS(R22)>=$B$6,"NO_GO","")))
A23: 2025-09-03 | B23: 3635.5 | C23: 7.1422 | D23: 808.12 | E23: 810.44 | F23: 557.477 | G23: =(B23*C23)/$B$14 -> 834.80856 | H23: =D23-G23 -> -26.688562 | I23: =E23-G23 -> -24.368562 | J23: =F23-G23 -> -277.33156 | K23: =-(C22/$B$14)*(B23-B22) -> -9.9390856 | L23: =(B23/$B$14)*(C23-C22) -> 0.31558667 | M23: =D23-D22 -> 7.18 | N23: =E23-E22 -> 8.72 | O23: =N23-M23 -> 1.54 | P23: =IF(COUNT($H$21:H23)<$B$4,"",AVERAGE(INDEX($H$21:H23,COUNT($H$21:H23)-$B$4+1):H23)) | Q23: =IF(COUNT($H$21:H23)<$B$4,"",_xludf.STDEV.S(INDEX($H$21:H23,COUNT($H$21:H23)-$B$4+1):H23)) | R23: =IF(OR(P23="",Q23=""),"",(H23-P23)/Q23) | T23: =IF(R23="","",MIN($B$12,ABS(R23)/$B$6)) | U23: =IF(R23="","",$B$11*1000*T23) | X23: =IF(OR(R23="",$B$13=0),0,-W23*$B$15*B23) -> 0 | Z23: =IF(R23="","",IF(AND(ABS(R23)>=$B$6,ABS(H23)>=$B$5,ABS(H23)<=$B$9,ABS(Y23)>=U23*($B$5+$B$17)),"GO",IF(ABS(R23)>=$B$6,"NO_GO","")))
A24: 2025-09-04 | B24: 3606.7 | C24: 7.1417 | D24: 810.63 | E24: 809.52 | F24: 557.58 | G24: =(B24*C24)/$B$14 -> 828.13733 | H24: =D24-G24 -> -17.507328 | I24: =E24-G24 -> -18.617328 | J24: =F24-G24 -> -270.55733 | K24: =-(C23/$B$14)*(B24-B23) -> 6.6132545 | L24: =(B24/$B$14)*(C24-C23) -> -0.057979006 | M24: =D24-D23 -> 2.51 | N24: =E24-E23 -> -0.92 | O24: =N24-M24 -> -3.43 | P24: =IF(COUNT($H$21:H24)<$B$4,"",AVERAGE(INDEX($H$21:H24,COUNT($H$21:H24)-$B$4+1):H24)) | Q24: =IF(COUNT($H$21:H24)<$B$4,"",_xludf.STDEV.S(INDEX($H$21:H24,COUNT($H$21:H24)-$B$4+1):H24)) | R24: =IF(OR(P24="",Q24=""),"",(H24-P24)/Q24) | T24: =IF(R24="","",MIN($B$12,ABS(R24)/$B$6)) | U24: =IF(R24="","",$B$11*1000*T24) | X24: =IF(OR(R24="",$B$13=0),0,-W24*$B$15*B24) -> 0 | Z24: =IF(R24="","",IF(AND(ABS(R24)>=$B$6,ABS(H24)>=$B$5,ABS(H24)<=$B$9,ABS(Y24)>=U24*($B$5+$B$17)),"GO",IF(ABS(R24)>=$B$6,"NO_GO","")))
A25: 2025-09-05 | B25: 3606.7 | C25: 7.1329 | D25: 811.18 | E25: 811.74 | F25: 557.421 | G25: =(B25*C25)/$B$14 -> 827.1169 | H25: =D25-G25 -> -15.936898 | I25: =E25-G25 -> -15.376898 | J25: =F25-G25 -> -269.6959 | K25: =-(C24/$B$14)*(B25-B24) -> 0 | L25: =(B25/$B$14)*(C25-C24) -> -1.0204305 | M25: =D25-D24 -> 0.55 | N25: =E25-E24 -> 2.22 | O25: =N25-M25 -> 1.67 | P25: =IF(COUNT($H$21:H25)<$B$4,"",AVERAGE(INDEX($H$21:H25,COUNT($H$21:H25)-$B$4+1):H25)) | Q25: =IF(COUNT($H$21:H25)<$B$4,"",_xludf.STDEV.S(INDEX($H$21:H25,COUNT($H$21:H25)-$B$4+1):H25)) | R25: =IF(OR(P25="",Q25=""),"",(H25-P25)/Q25) | T25: =IF(R25="","",MIN($B$12,ABS(R25)/$B$6)) | U25: =IF(R25="","",$B$11*1000*T25) | X25: =IF(OR(R25="",$B$13=0),0,-W25*$B$15*B25) -> 0 | Z25: =IF(R25="","",IF(AND(ABS(R25)>=$B$6,ABS(H25)>=$B$5,ABS(H25)<=$B$9,ABS(Y25)>=U25*($B$5+$B$17)),"GO",IF(ABS(R25)>=$B$6,"NO_GO","")))
A26: 2025-09-08 | B26: 3677.4 | C26: 7.1299 | D26: 817.55 | E26: 817.98 | F26: 557.477 | G26: =(B26*C26)/$B$14 -> 842.97569 | H26: =D26-G26 -> -25.425686 | I26: =E26-G26 -> -24.995686 | J26: =F26-G26 -> -285.49869 | K26: =-(C25/$B$14)*(B26-B25) -> -16.213482 | L26: =(B26/$B$14)*(C26-C25) -> -0.3546932 | M26: =D26-D25 -> 6.37 | N26: =E26-E25 -> 6.24 | O26: =N26-M26 -> -0.13 | P26: =IF(COUNT($H$21:H26)<$B$4,"",AVERAGE(INDEX($H$21:H26,COUNT($H$21:H26)-$B$4+1):H26)) | Q26: =IF(COUNT($H$21:H26)<$B$4,"",_xludf.STDEV.S(INDEX($H$21:H26,COUNT($H$21:H26)-$B$4+1):H26)) | R26: =IF(OR(P26="",Q26=""),"",(H26-P26)/Q26) | T26: =IF(R26="","",MIN($B$12,ABS(R26)/$B$6)) | U26: =IF(R26="","",$B$11*1000*T26) | X26: =IF(OR(R26="",$B$13=0),0,-W26*$B$15*B26) -> 0 | Z26: =IF(R26="","",IF(AND(ABS(R26)>=$B$6,ABS(H26)>=$B$5,ABS(H26)<=$B$9,ABS(Y26)>=U26*($B$5+$B$17)),"GO",IF(ABS(R26)>=$B$6,"NO_GO","")))
A27: 2025-09-09 | B27: 3682.2 | C27: 7.1215 | D27: 829.2 | E27: 831.02 | F27: 557.58 | G27: =(B27*C27)/$B$14 -> 843.08156 | H27: =D27-G27 -> -13.88156 | I27: =E27-G27 -> -12.06156 | J27: =F27-G27 -> -285.50156 | K27: =-(C26/$B$14)*(B27-B26) -> -1.1003109 | L27: =(B27/$B$14)*(C27-C26) -> -0.99443728 | M27: =D27-D26 -> 11.65 | N27: =E27-E26 -> 13.04 | O27: =N27-M27 -> 1.39 | P27: =IF(COUNT($H$21:H27)<$B$4,"",AVERAGE(INDEX($H$21:H27,COUNT($H$21:H27)-$B$4+1):H27)) | Q27: =IF(COUNT($H$21:H27)<$B$4,"",_xludf.STDEV.S(INDEX($H$21:H27,COUNT($H$21:H27)-$B$4+1):H27)) | R27: =IF(OR(P27="",Q27=""),"",(H27-P27)/Q27) | T27: =IF(R27="","",MIN($B$12,ABS(R27)/$B$6)) | U27: =IF(R27="","",$B$11*1000*T27) | X27: =IF(OR(R27="",$B$13=0),0,-W27*$B$15*B27) -> 0 | Z27: =IF(R27="","",IF(AND(ABS(R27)>=$B$6,ABS(H27)>=$B$5,ABS(H27)<=$B$9,ABS(Y27)>=U27*($B$5+$B$17)),"GO",IF(ABS(R27)>=$B$6,"NO_GO","")))
A28: 2025-09-10 | B28: 3682 | C28: 7.1212 | D28: 828.95 | E28: 828.78 | F28: 557.406 | G28: =(B28*C28)/$B$14 -> 843.00025 | H28: =D28-G28 -> -14.050254 | I28: =E28-G28 -> -14.220254 | J28: =F28-G28 -> -285.59425 | K28: =-(C27/$B$14)*(B28-B27) -> 0.045792274 | L28: =(B28/$B$14)*(C28-C27) -> -0.035513688 | M28: =D28-D27 -> -0.25 | N28: =E28-E27 -> -2.24 | O28: =N28-M28 -> -1.99 | P28: =IF(COUNT($H$21:H28)<$B$4,"",AVERAGE(INDEX($H$21:H28,COUNT($H$21:H28)-$B$4+1):H28)) | Q28: =IF(COUNT($H$21:H28)<$B$4,"",_xludf.STDEV.S(INDEX($H$21:H28,COUNT($H$21:H28)-$B$4+1):H28)) | R28: =IF(OR(P28="",Q28=""),"",(H28-P28)/Q28) | T28: =IF(R28="","",MIN($B$12,ABS(R28)/$B$6)) | U28: =IF(R28="","",$B$11*1000*T28) | X28: =IF(OR(R28="",$B$13=0),0,-W28*$B$15*B28) -> 0 | Z28: =IF(R28="","",IF(AND(ABS(R28)>=$B$6,ABS(H28)>=$B$5,ABS(H28)<=$B$9,ABS(Y28)>=U28*($B$5+$B$17)),"GO",IF(ABS(R28)>=$B$6,"NO_GO","")))
A29: 2025-09-11 | B29: 3673.6 | C29: 7.1187 | D29: 828.73 | E29: 828.75 | F29: 557.246 | G29: =(B29*C29)/$B$14 -> 840.78179 | H29: =D29-G29 -> -12.051787 | I29: =E29-G29 -> -12.031787 | J29: =F29-G29 -> -283.53579 | K29: =-(C28/$B$14)*(B29-B28) -> 1.9231945 | L29: =(B29/$B$14)*(C29-C28) -> -0.29527224 | M29: =D29-D28 -> -0.22 | N29: =E29-E28 -> -0.03 | O29: =N29-M29 -> 0.19 | P29: =IF(COUNT($H$21:H29)<$B$4,"",AVERAGE(INDEX($H$21:H29,COUNT($H$21:H29)-$B$4+1):H29)) | Q29: =IF(COUNT($H$21:H29)<$B$4,"",_xludf.STDEV.S(INDEX($H$21:H29,COUNT($H$21:H29)-$B$4+1):H29)) | R29: =IF(OR(P29="",Q29=""),"",(H29-P29)/Q29) | T29: =IF(R29="","",MIN($B$12,ABS(R29)/$B$6)) | U29: =IF(R29="","",$B$11*1000*T29) | X29: =IF(OR(R29="",$B$13=0),0,-W29*$B$15*B29) -> 0 | Z29: =IF(R29="","",IF(AND(ABS(R29)>=$B$6,ABS(H29)>=$B$5,ABS(H29)<=$B$9,ABS(Y29)>=U29*($B$5+$B$17)),"GO",IF(ABS(R29)>=$B$6,"NO_GO","")))
A30: 2025-09-12 | B30: 3673.6 | C30: 7.1248 | D30: 829.54 | E30: 830.1 | F30: 557.349 | G30: =(B30*C30)/$B$14 -> 841.50225 | H30: =D30-G30 -> -11.962252 | I30: =E30-G30 -> -11.402252 | J30: =F30-G30 -> -284.15325 | K30: =-(C29/$B$14)*(B30-B29) -> 0 | L30: =(B30/$B$14)*(C30-C29) -> 0.72046426 | M30: =D30-D29 -> 0.81 | N30: =E30-E29 -> 1.35 | O30: =N30-M30 -> 0.54 | P30: =IF(COUNT($H$21:H30)<$B$4,"",AVERAGE(INDEX($H$21:H30,COUNT($H$21:H30)-$B$4+1):H30)) | Q30: =IF(COUNT($H$21:H30)<$B$4,"",_xludf.STDEV.S(INDEX($H$21:H30,COUNT($H$21:H30)-$B$4+1):H30)) | R30: =IF(OR(P30="",Q30=""),"",(H30-P30)/Q30) | T30: =IF(R30="","",MIN($B$12,ABS(R30)/$B$6)) | U30: =IF(R30="","",$B$11*1000*T30) | X30: =IF(OR(R30="",$B$13=0),0,-W30*$B$15*B30) -> 0 | Z30: =IF(R30="","",IF(AND(ABS(R30)>=$B$6,ABS(H30)>=$B$5,ABS(H30)<=$B$9,ABS(Y30)>=U30*($B$5+$B$17)),"GO",IF(ABS(R30)>=$B$6,"NO_GO","")))
A31: 2025-09-15 | B31: 3719 | C31: 7.1191 | D31: 828.63 | E31: 828.61 | F31: 557.406 | G31: =(B31*C31)/$B$14 -> 851.22037 | H31: =D31-G31 -> -22.590374 | I31: =E31-G31 -> -22.610374 | J31: =F31-G31 -> -293.81437 | K31: =-(C30/$B$14)*(B31-B30) -> -10.399663 | L31: =(B31/$B$14)*(C31-C30) -> -0.68154066 | M31: =D31-D30 -> -0.91 | N31: =E31-E30 -> -1.49 | O31: =N31-M31 -> -0.58 | P31: =IF(COUNT($H$21:H31)<$B$4,"",AVERAGE(INDEX($H$21:H31,COUNT($H$21:H31)-$B$4+1):H31)) | Q31: =IF(COUNT($H$21:H31)<$B$4,"",_xludf.STDEV.S(INDEX($H$21:H31,COUNT($H$21:H31)-$B$4+1):H31)) | R31: =IF(OR(P31="",Q31=""),"",(H31-P31)/Q31) | T31: =IF(R31="","",MIN($B$12,ABS(R31)/$B$6)) | U31: =IF(R31="","",$B$11*1000*T31) | X31: =IF(OR(R31="",$B$13=0),0,-W31*$B$15*B31) -> 0 | Z31: =IF(R31="","",IF(AND(ABS(R31)>=$B$6,ABS(H31)>=$B$5,ABS(H31)<=$B$9,ABS(Y31)>=U31*($B$5+$B$17)),"GO",IF(ABS(R31)>=$B$6,"NO_GO","")))
A32: 2025-09-16 | B32: 3725.1 | C32: 7.1144 | D32: 834.94 | E32: 836.71 | F32: 557.231 | G32: =(B32*C32)/$B$14 -> 852.05367 | H32: =D32-G32 -> -17.113674 | I32: =E32-G32 -> -15.343674 | J32: =F32-G32 -> -294.82267 | K32: =-(C31/$B$14)*(B32-B31) -> -1.3961937 | L32: =(B32/$B$14)*(C32-C31) -> -0.56289389 | M32: =D32-D31 -> 6.31 | N32: =E32-E31 -> 8.1 | O32: =N32-M32 -> 1.79 | P32: =IF(COUNT($H$21:H32)<$B$4,"",AVERAGE(INDEX($H$21:H32,COUNT($H$21:H32)-$B$4+1):H32)) | Q32: =IF(COUNT($H$21:H32)<$B$4,"",_xludf.STDEV.S(INDEX($H$21:H32,COUNT($H$21:H32)-$B$4+1):H32)) | R32: =IF(OR(P32="",Q32=""),"",(H32-P32)/Q32) | T32: =IF(R32="","",MIN($B$12,ABS(R32)/$B$6)) | U32: =IF(R32="","",$B$11*1000*T32) | X32: =IF(OR(R32="",$B$13=0),0,-W32*$B$15*B32) -> 0 | Z32: =IF(R32="","",IF(AND(ABS(R32)>=$B$6,ABS(H32)>=$B$5,ABS(H32)<=$B$9,ABS(Y32)>=U32*($B$5+$B$17)),"GO",IF(ABS(R32)>=$B$6,"NO_GO","")))
A33: 2025-09-17 | B33: 3717.8 | C33: 7.1036 | D33: 834.73 | E33: 833.74 | F33: 557.349 | G33: =(B33*C33)/$B$14 -> 849.093 | H33: =D33-G33 -> -14.362999 | I33: =E33-G33 -> -15.352999 | J33: =F33-G33 -> -291.744 | K33: =-(C32/$B$14)*(B33-B32) -> 1.6697516 | L33: =(B33/$B$14)*(C33-C32) -> -1.2909235 | M33: =D33-D32 -> -0.21 | N33: =E33-E32 -> -2.97 | O33: =N33-M33 -> -2.76 | P33: =IF(COUNT($H$21:H33)<$B$4,"",AVERAGE(INDEX($H$21:H33,COUNT($H$21:H33)-$B$4+1):H33)) | Q33: =IF(COUNT($H$21:H33)<$B$4,"",_xludf.STDEV.S(INDEX($H$21:H33,COUNT($H$21:H33)-$B$4+1):H33)) | R33: =IF(OR(P33="",Q33=""),"",(H33-P33)/Q33) | T33: =IF(R33="","",MIN($B$12,ABS(R33)/$B$6)) | U33: =IF(R33="","",$B$11*1000*T33) | X33: =IF(OR(R33="",$B$13=0),0,-W33*$B$15*B33) -> 0 | Z33: =IF(R33="","",IF(AND(ABS(R33)>=$B$6,ABS(H33)>=$B$5,ABS(H33)<=$B$9,ABS(Y33)>=U33*($B$5+$B$17)),"GO",IF(ABS(R33)>=$B$6,"NO_GO","")))
... A79: 2025-12-01 | B79: 4274.8 | C79: 7.0718 | D79: 956.65 | E79: 957.2 | F79: 558.608 | G79: =(B79*C79)/$B$14 -> 971.9334 | H79: =D79-G79 -> -15.283404 | I79: =E79-G79 -> -14.733404 | J79: =F79-G79 -> -413.3254 | K79: =-(C78/$B$14)*(B79-B78) -> -16.492011 | L79: =(B79/$B$14)*(C79-C78) -> -0.48103268 | M79: =D79-D78 -> 9.34 | N79: =E79-E78 -> 8.99 | O79: =N79-M79 -> -0.35 | P79: =IF(COUNT($H$21:H79)<$B$4,"",AVERAGE(INDEX($H$21:H79,COUNT($H$21:H79)-$B$4+1):H79)) | Q79: =IF(COUNT($H$21:H79)<$B$4,"",_xludf.STDEV.S(INDEX($H$21:H79,COUNT($H$21:H79)-$B$4+1):H79)) | R79: =IF(OR(P79="",Q79=""),"",(H79-P79)/Q79) | T79: =IF(R79="","",MIN($B$12,ABS(R79)/$B$6)) | U79: =IF(R79="","",$B$11*1000*T79) | X79: =IF(OR(R79="",$B$13=0),0,-W79*$B$15*B79) -> 0 | Z79: =IF(R79="","",IF(AND(ABS(R79)>=$B$6,ABS(H79)>=$B$5,ABS(H79)<=$B$9,ABS(Y79)>=U79*($B$5+$B$17)),"GO",IF(ABS(R79)>=$B$6,"NO_GO","")))
A80: 2025-12-02 | B80: 4220.8 | C80: 7.0709 | D80: 955.66 | E80: 954.71 | F80: 558.433 | G80: =(B80*C80)/$B$14 -> 959.53364 | H80: =D80-G80 -> -3.8736448 | I80: =E80-G80 -> -4.8236448 | J80: =F80-G80 -> -401.10064 | K80: =-(C79/$B$14)*(B80-B79) -> 12.277628 | L80: =(B80/$B$14)*(C80-C79) -> -0.12213159 | M80: =D80-D79 -> -0.99 | N80: =E80-E79 -> -2.49 | O80: =N80-M80 -> -1.5 | P80: =IF(COUNT($H$21:H80)<$B$4,"",AVERAGE(INDEX($H$21:H80,COUNT($H$21:H80)-$B$4+1):H80)) -> -10.436193 | Q80: =_xlfn.SINGLE(IF(COUNT($H$21:H80)<$B$4,"",_xlfn.STDEV.S(INDEX($H$21:H80,COUNT($H$21:H80)-$B$4+1):H80))) -> 12.805826 | R80: =IF(OR(P80="",Q80=""),"",(H80-P80)/Q80) -> 0.5124658 | T80: =IF(R80="","",MIN($B$12,ABS(R80)/$B$6)) -> 0.2562329 | U80: =IF(R80="","",$B$11*1000*T80) -> 1281.1645 | X80: =IF(OR(R80="",$B$13=0),0,-W80*$B$15*B80) -> 0 | Z80: =IF(R80="","",IF(AND(ABS(R80)>=$B$6,ABS(H80)>=$B$5,ABS(H80)<=$B$9,ABS(Y80)>=U80*($B$5+$B$17)),"GO",IF(ABS(R80)>=$B$6,"NO_GO","")))
A81: 2025-12-03 | B81: 4232.5 | C81: 7.0638 | D81: 953.02 | E81: 953.48 | F81: 558.783 | G81: =(B81*C81)/$B$14 -> 961.22731 | H81: =D81-G81 -> -8.2073056 | I81: =E81-G81 -> -7.7473056 | J81: =F81-G81 -> -402.44431 | K81: =-(C80/$B$14)*(B81-B80) -> -2.6598142 | L81: =(B81/$B$14)*(C81-C80) -> -0.96615333 | M81: =D81-D80 -> -2.64 | N81: =E81-E80 -> -1.23 | O81: =N81-M81 -> 1.41 | P81: =IF(COUNT($H$21:H81)<$B$4,"",AVERAGE(INDEX($H$21:H81,COUNT($H$21:H81)-$B$4+1):H81)) -> -10.046522 | Q81: =_xlfn.SINGLE(IF(COUNT($H$21:H81)<$B$4,"",_xlfn.STDEV.S(INDEX($H$21:H81,COUNT($H$21:H81)-$B$4+1):H81))) -> 12.50345 | R81: =IF(OR(P81="",Q81=""),"",(H81-P81)/Q81) -> 0.14709671 | T81: =IF(R81="","",MIN($B$12,ABS(R81)/$B$6)) -> 0.073548354 | U81: =IF(R81="","",$B$11*1000*T81) -> 367.74177 | X81: =IF(OR(R81="",$B$13=0),0,-W81*$B$15*B81) -> 0 | Z81: =IF(R81="","",IF(AND(ABS(R81)>=$B$6,ABS(H81)>=$B$5,ABS(H81)<=$B$9,ABS(Y81)>=U81*($B$5+$B$17)),"GO",IF(ABS(R81)>=$B$6,"NO_GO","")))
A82: 2025-12-04 | B82: 4243 | C82: 7.0717 | D82: 950.43 | E82: 949.82 | F82: 558.608 | G82: =(B82*C82)/$B$14 -> 964.6896 | H82: =D82-G82 -> -14.259604 | I82: =E82-G82 -> -14.869604 | J82: =F82-G82 -> -406.0816 | K82: =-(C81/$B$14)*(B82-B81) -> -2.3846159 | L82: =(B82/$B$14)*(C82-C81) -> 1.0776826 | M82: =D82-D81 -> -2.59 | N82: =E82-E81 -> -3.66 | O82: =N82-M82 -> -1.07 | P82: =IF(COUNT($H$21:H82)<$B$4,"",AVERAGE(INDEX($H$21:H82,COUNT($H$21:H82)-$B$4+1):H82)) -> -9.8906171 | Q82: =_xlfn.SINGLE(IF(COUNT($H$21:H82)<$B$4,"",_xlfn.STDEV.S(INDEX($H$21:H82,COUNT($H$21:H82)-$B$4+1):H82))) -> 12.389209 | R82: =IF(OR(P82="",Q82=""),"",(H82-P82)/Q82) -> -0.35264455 | T82: =IF(R82="","",MIN($B$12,ABS(R82)/$B$6)) -> 0.17632227 | U82: =IF(R82="","",$B$11*1000*T82) -> 881.61137 | X82: =IF(OR(R82="",$B$13=0),0,-W82*$B$15*B82) -> 0 | Z82: =IF(R82="","",IF(AND(ABS(R82)>=$B$6,ABS(H82)>=$B$5,ABS(H82)<=$B$9,ABS(Y82)>=U82*($B$5+$B$17)),"GO",IF(ABS(R82)>=$B$6,"NO_GO","")))
A83: 2025-12-05 | B83: 4243 | C83: 7.0703 | D83: 953.06 | E83: 954.25 | F83: 558.433 | G83: =(B83*C83)/$B$14 -> 964.49862 | H83: =D83-G83 -> -11.438622 | I83: =E83-G83 -> -10.248622 | J83: =F83-G83 -> -406.06562 | K83: =-(C82/$B$14)*(B83-B82) -> 0 | L83: =(B83/$B$14)*(C83-C82) -> -0.19098172 | M83: =D83-D82 -> 2.63 | N83: =E83-E82 -> 4.43 | O83: =N83-M83 -> 1.8 | P83: =IF(COUNT($H$21:H83)<$B$4,"",AVERAGE(INDEX($H$21:H83,COUNT($H$21:H83)-$B$4+1):H83)) -> -9.6364515 | Q83: =_xlfn.SINGLE(IF(COUNT($H$21:H83)<$B$4,"",_xlfn.STDEV.S(INDEX($H$21:H83,COUNT($H$21:H83)-$B$4+1):H83))) -> 12.19364 | R83: =IF(OR(P83="",Q83=""),"",(H83-P83)/Q83) -> -0.14779597 | T83: =IF(R83="","",MIN($B$12,ABS(R83)/$B$6)) -> 0.073897985 | U83: =IF(R83="","",$B$11*1000*T83) -> 369.48992 | X83: =IF(OR(R83="",$B$13=0),0,-W83*$B$15*B83) -> 0 | Z83: =IF(R83="","",IF(AND(ABS(R83)>=$B$6,ABS(H83)>=$B$5,ABS(H83)<=$B$9,ABS(Y83)>=U83*($B$5+$B$17)),"GO",IF(ABS(R83)>=$B$6,"NO_GO","")))
A84: 2025-12-08 | B84: 4217.7 | C84: 7.0717 | D84: 953.36 | E84: 952.62 | F84: 558.535 | G84: =(B84*C84)/$B$14 -> 958.93739 | H84: =D84-G84 -> -5.5773894 | I84: =E84-G84 -> -6.3173894 | J84: =F84-G84 -> -400.40239 | K84: =-(C83/$B$14)*(B84-B83) -> 5.7510759 | L84: =(B84/$B$14)*(C84-C83) -> 0.18984294 | M84: =D84-D83 -> 0.3 | N84: =E84-E83 -> -1.63 | O84: =N84-M84 -> -1.93 | P84: =IF(COUNT($H$21:H84)<$B$4,"",AVERAGE(INDEX($H$21:H84,COUNT($H$21:H84)-$B$4+1):H84)) -> -9.4376192 | Q84: =_xlfn.SINGLE(IF(COUNT($H$21:H84)<$B$4,"",_xlfn.STDEV.S(INDEX($H$21:H84,COUNT($H$21:H84)-$B$4+1):H84))) -> 12.160341 | R84: =IF(OR(P84="",Q84=""),"",(H84-P84)/Q84) -> 0.31744421 | T84: =IF(R84="","",MIN($B$12,ABS(R84)/$B$6)) -> 0.1587221 | U84: =IF(R84="","",$B$11*1000*T84) -> 793.61051 | X84: =IF(OR(R84="",$B$13=0),0,-W84*$B$15*B84) -> 0 | Z84: =IF(R84="","",IF(AND(ABS(R84)>=$B$6,ABS(H84)>=$B$5,ABS(H84)<=$B$9,ABS(Y84)>=U84*($B$5+$B$17)),"GO",IF(ABS(R84)>=$B$6,"NO_GO","")))
A85: 2025-12-09 | B85: 4236.2 | C85: 7.0636 | D85: 948.26 | E85: 948.2 | F85: 558.376 | G85: =(B85*C85)/$B$14 -> 962.04036 | H85: =D85-G85 -> -13.780359 | I85: =E85-G85 -> -13.840359 | J85: =F85-G85 -> -403.66436 | K85: =-(C84/$B$14)*(B85-B84) -> -4.2061649 | L85: =(B85/$B$14)*(C85-C84) -> -1.1031948 | M85: =D85-D84 -> -5.1 | N85: =E85-E84 -> -4.42 | O85: =N85-M85 -> 0.68 | P85: =IF(COUNT($H$21:H85)<$B$4,"",AVERAGE(INDEX($H$21:H85,COUNT($H$21:H85)-$B$4+1):H85)) -> -9.4016769 | Q85: =_xlfn.SINGLE(IF(COUNT($H$21:H85)<$B$4,"",_xlfn.STDEV.S(INDEX($H$21:H85,COUNT($H$21:H85)-$B$4+1):H85))) -> 12.143982 | R85: =IF(OR(P85="",Q85=""),"",(H85-P85)/Q85) -> -0.360564 | T85: =IF(R85="","",MIN($B$12,ABS(R85)/$B$6)) -> 0.180282 | U85: =IF(R85="","",$B$11*1000*T85) -> 901.41 | X85: =IF(OR(R85="",$B$13=0),0,-W85*$B$15*B85) -> 0 | Z85: =IF(R85="","",IF(AND(ABS(R85)>=$B$6,ABS(H85)>=$B$5,ABS(H85)<=$B$9,ABS(Y85)>=U85*($B$5+$B$17)),"GO",IF(ABS(R85)>=$B$6,"NO_GO","")))
A86: 2025-12-10 | B86: 4224.7 | C86: 7.0646 | D86: 951.7 | E86: 952.38 | F86: 558.433 | G86: =(B86*C86)/$B$14 -> 959.56454 | H86: =D86-G86 -> -7.8645384 | I86: =E86-G86 -> -7.1845384 | J86: =F86-G86 -> -401.13154 | K86: =-(C85/$B$14)*(B86-B85) -> 2.6116482 | L86: =(B86/$B$14)*(C86-C85) -> 0.13582716 | M86: =D86-D85 -> 3.44 | N86: =E86-E85 -> 4.18 | O86: =N86-M86 -> 0.74 | P86: =IF(COUNT($H$21:H86)<$B$4,"",AVERAGE(INDEX($H$21:H86,COUNT($H$21:H86)-$B$4+1):H86)) -> -9.1089911 | Q86: =_xlfn.SINGLE(IF(COUNT($H$21:H86)<$B$4,"",_xlfn.STDEV.S(INDEX($H$21:H86,COUNT($H$21:H86)-$B$4+1):H86))) -> 11.961488 | R86: =IF(OR(P86="",Q86=""),"",(H86-P86)/Q86) -> 0.10403828 | T86: =IF(R86="","",MIN($B$12,ABS(R86)/$B$6)) -> 0.05201914 | U86: =IF(R86="","",$B$11*1000*T86) -> 260.0957 | X86: =IF(OR(R86="",$B$13=0),0,-W86*$B$15*B86) -> 0 | Z86: =IF(R86="","",IF(AND(ABS(R86)>=$B$6,ABS(H86)>=$B$5,ABS(H86)<=$B$9,ABS(Y86)>=U86*($B$5+$B$17)),"GO",IF(ABS(R86)>=$B$6,"NO_GO","")))
A87: 2025-12-11 | B87: 4313 | C87: 7.0581 | D87: 954.81 | E87: 954.51 | F87: 558.535 | G87: =(B87*C87)/$B$14 -> 978.71896 | H87: =D87-G87 -> -23.908964 | I87: =E87-G87 -> -24.208964 | J87: =F87-G87 -> -420.18396 | K87: =-(C86/$B$14)*(B87-B86) -> -20.055755 | L87: =(B87/$B$14)*(C87-C86) -> -0.90132943 | M87: =D87-D86 -> 3.11 | N87: =E87-E86 -> 2.13 | O87: =N87-M87 -> -0.98 | P87: =IF(COUNT($H$21:H87)<$B$4,"",AVERAGE(INDEX($H$21:H87,COUNT($H$21:H87)-$B$4+1):H87)) -> -9.2761145 | Q87: =_xlfn.SINGLE(IF(COUNT($H$21:H87)<$B$4,"",_xlfn.STDEV.S(INDEX($H$21:H87,COUNT($H$21:H87)-$B$4+1):H87))) -> 12.098565 | R87: =IF(OR(P87="",Q87=""),"",(H87-P87)/Q87) -> -1.2094699 | T87: =IF(R87="","",MIN($B$12,ABS(R87)/$B$6)) -> 0.60473493 | U87: =IF(R87="","",$B$11*1000*T87) -> 3023.6747 | X87: =IF(OR(R87="",$B$13=0),0,-W87*$B$15*B87) -> 0 | Z87: =IF(R87="","",IF(AND(ABS(R87)>=$B$6,ABS(H87)>=$B$5,ABS(H87)<=$B$9,ABS(Y87)>=U87*($B$5+$B$17)),"GO",IF(ABS(R87)>=$B$6,"NO_GO","")))
...
