Workbook
Name ailxcfjb: '[1]#REF'!$A$1
Name apyfcyhw: '[1]#REF'!$A$1
Name aujzarkj: '[2]#REF'!$A$1
Name avmpmedq: '[3]#REF'!$A$1
Name bdairnqd: '[4]#REF'!$A$1
Name bitfxntp: '[5]#REF'!$A$1
Name biukkekl: 本年累计!$A$1
Name biukkekl: Sheet54!$A$1
Name bknrcbtm: '[6]#REF'!$A$1
Name bmygeinz: '[1]#REF'!$A$1
Name boxvdrvn: '[7]#REF'!$A$1
Name bquckijz: '[2]#REF'!$A$1
Name buvomlnr: '[8]#REF'!$A$1
Name bvdepspo: '[2]#REF'!$A$1
Name bwqsqjza: '[2]#REF'!$E$3
Name bxrfmpue: '[7]#REF'!$A$1
Name byndfpoi: '[9]#REF'!$A$1
Name bzartlsc: '[8]#REF'!$A$1
Name caedeslv: '[7]#REF'!$A$1
Name cdcwryey: '[10]#REF'!$A$1
Name cpnllhur: '[1]#REF'!$A$1
Name cuyosutd: '[2]#REF'!$A$1
Name cvuklgsj: '[11]#REF'!$B$2
Name deqkwkzi: '[2]#REF'!$A$1
Name dftrqaiy: '[5]#REF'!$A$1
Name dmesnbje: '[12]#REF'!$A$1
Name dmfezyqy: '[13]#REF'!$A$1
Name dvqalzwz: '[6]#REF'!$A$1
Name dvutfafg: '[6]#REF'!$A$1
Name dxvlhjnw: '[14]#REF'!$A$1
Name dzcclxak: '[7]#REF'!$A$1
Name ebeqqinm: '[15]#REF'!$A$1
Name eizqawwj: '[2]#REF'!$A$1
Name envbgpbp: '[6]#REF'!$A$1
Name etthwfcb: '[12]#REF'!$A$1
Name feucnzqk: '[16]#REF'!$A$1
Name fftruyvd: '[2]#REF'!$A$1
Name fnlzvoxv: '[6]#REF'!$A$1
Name fnqdbnof: '[17]#REF'!$A$1
Name fufmbntk: '[18]#REF'!$A$1
Name fvgavnsv: '[19]#REF'!$A$1
Name fvwexuqp: '[8]#REF'!$A$1
Name fytaxufy: '[11]#REF'!$A$1
Name fzafntic: 本年累计!$A$1
Name fzafntic: Sheet54!$A$1
Name gaanfxcg: '[12]#REF'!$A$1
Name gjeooxbo: '[20]#REF'!$A$1
Name gmjryrwu: '[21]#REF'!$A$1
Name gnkvapru: '[22]#REF'!$A$1
Name gpbxymfw: '[6]#REF'!$A$1
Name gtyxyotn: '[6]#REF'!$A$1
Name guoaukrd: '[4]#REF'!$A$1
Name gzlmsitz: '[20]#REF'!$A$1
Name hgxswcaz: '[2]#REF'!$A$1
Name hhqfyrcr: '[3]#REF'!$A$1
Name hifqhofn: '[13]#REF'!$A$1
Name hkkjzqai: 本年累计!$A$1
Name hkkjzqai: Sheet54!$A$1
Name hliogioo: '[1]#REF'!$A$1
Name hlohimar: 本年累计!$A$1

Sheet Sheet54
A1: 绩效归因产品口径一级分类 | B1: 绩效归因产品口径二级分类 | C1: 六级科目名称 | D1: 绩效归因科目口径 | E1: 2026年初 | F1: 2026-01-01 | G1: 2026-01-02 | H1: 2026-01-03 | I1: 2026-01-04 | J1: 2026-01-05 | K1: 2026-01-06 | L1: 2026-01-07 | M1: 2026-01-08 | N1: 2026-01-09 | O1: 2026-01-10 | P1: 2026-01-11 | Q1: 2026-01-12 | R1: 2026-01-13 | S1: 2026-01-14 | T1: 2026-01-15 | U1: 2026-01-16 | V1: 2026-01-17 | W1: 2026-01-18 | X1: 2026-01-19 | Y1: 2026-01-20 | Z1: 2026-01-21 | AA1: 2026-01-22 | AB1: 2026-01-23 | AC1: 2026-01-24 | AD1: 2026-01-25 | AE1: 2026-01-26 | AF1: 2026-01-27 | AG1: 2026-01-28 | AH1: 2026-01-29 | AI1: 2026-01-30 | AJ1: 2026-01-31
A2: 权益类产品 | B2: 股票 | C2: 安徽皖通高速公路 | D2: 持仓成本 | E2: 12.061917 | F2: 0 | G2: 0 | H2: 0 | I2: 0 | J2: 0 | K2: 0 | L2: 0 | M2: 0 | N2: 0 | O2: 0 | P2: 0 | Q2: 0 | R2: 0 | S2: 0 | T2: 0 | U2: 0 | V2: 0 | W2: 0 | X2: 0 | Y2: 0 | Z2: 0 | AA2: 0 | AB2: 0 | AC2: 0 | AD2: 0 | AE2: 0 | AF2: 0 | AG2: 0 | AH2: 0 | AI2: 0 | AJ2: 0 | AK2: =ROUND(ABS(E2)+ABS(F2)+ABS(G2)+ABS(H2)+ABS(I2)+ABS(J2)+ABS(K2)+ABS(L2)+ABS(M2)+ABS(N2)+ABS(O2)+ABS(P2)+ABS(Q2)+ABS(R2)+ABS(S2)+ABS(T2)+ABS(U2)+ABS(V2)+ABS(W2)+ABS(X2)+ABS(Y2)+ABS(Z2)+ABS(AA2)+ABS(AB2)+ABS(AC2)+ABS(AD2)+ABS(AE2)+ABS(AF2)+ABS(AG2)+ABS(AH2)+ABS(AI2)+ABS(AJ2),6) -> 12.061917
D3: 持仓公允 | E3: -0.323925 | F3: 0 | G3: 0 | H3: 0 | I3: 0 | J3: -0.181052 | K3: -0.04591 | L3: 0.021777 | M3: -0.035832 | N3: 0.148425 | O3: 0 | P3: 0 | Q3: -0.056336 | R3: 0.007413 | S3: -0.151997 | T3: -0.070256 | U3: 0.116186 | V3: 0 | W3: 0 | X3: -0.111042 | Y3: 0.187432 | Z3: 0.015084 | AA3: -0.12726 | AB3: 0.077768 | AC3: 0 | AD3: 0 | AE3: -0.05227 | AF3: 0.142638 | AG3: 0.041984 | AH3: 0.299031 | AI3: 0.40917 | AJ3: 0 | AK3: =ROUND(ABS(E3)+ABS(F3)+ABS(G3)+ABS(H3)+ABS(I3)+ABS(J3)+ABS(K3)+ABS(L3)+ABS(M3)+ABS(N3)+ABS(O3)+ABS(P3)+ABS(Q3)+ABS(R3)+ABS(S3)+ABS(T3)+ABS(U3)+ABS(V3)+ABS(W3)+ABS(X3)+ABS(Y3)+ABS(Z3)+ABS(AA3)+ABS(AB3)+ABS(AC3)+ABS(AD3)+ABS(AE3)+ABS(AF3)+ABS(AG3)+ABS(AH3)+ABS(AI3)+ABS(AJ3),6) -> 2.622788
D4: OCI公允 | E4: 0 | F4: 0 | G4: 0 | H4: 0 | I4: 0 | J4: -0.181052 | K4: -0.04591 | L4: 0.021777 | M4: -0.035832 | N4: 0.148425 | O4: 0 | P4: 0 | Q4: -0.056336 | R4: 0.007413 | S4: -0.151997 | T4: -0.070256 | U4: 0.116186 | V4: 0 | W4: 0 | X4: -0.111042 | Y4: 0.187432 | Z4: 0.015084 | AA4: -0.12726 | AB4: 0.077768 | AC4: 0 | AD4: 0 | AE4: -0.05227 | AF4: 0.142638 | AG4: 0.041984 | AH4: 0.299031 | AI4: 0.40917 | AJ4: 0 | AK4: =ROUND(ABS(E4)+ABS(F4)+ABS(G4)+ABS(H4)+ABS(I4)+ABS(J4)+ABS(K4)+ABS(L4)+ABS(M4)+ABS(N4)+ABS(O4)+ABS(P4)+ABS(Q4)+ABS(R4)+ABS(S4)+ABS(T4)+ABS(U4)+ABS(V4)+ABS(W4)+ABS(X4)+ABS(Y4)+ABS(Z4)+ABS(AA4)+ABS(AB4)+ABS(AC4)+ABS(AD4)+ABS(AE4)+ABS(AF4)+ABS(AG4)+ABS(AH4)+ABS(AI4)+ABS(AJ4),6) -> 2.298863
C5: 安踏体育 | D5: 持仓成本 | E5: 758.75399 | F5: 0 | G5: 0 | H5: 0 | I5: 0 | J5: 0 | K5: 0 | L5: 0 | M5: 0 | N5: 0 | O5: 0 | P5: 0 | Q5: 0 | R5: 0 | S5: 0 | T5: 0 | U5: 0 | V5: 0 | W5: 0 | X5: 0 | Y5: 0 | Z5: 0 | AA5: 0 | AB5: 0 | AC5: 0 | AD5: 0 | AE5: 0 | AF5: 0 | AG5: 0 | AH5: 0 | AI5: 0 | AJ5: 0 | AK5: =ROUND(ABS(E5)+ABS(F5)+ABS(G5)+ABS(H5)+ABS(I5)+ABS(J5)+ABS(K5)+ABS(L5)+ABS(M5)+ABS(N5)+ABS(O5)+ABS(P5)+ABS(Q5)+ABS(R5)+ABS(S5)+ABS(T5)+ABS(U5)+ABS(V5)+ABS(W5)+ABS(X5)+ABS(Y5)+ABS(Z5)+ABS(AA5)+ABS(AB5)+ABS(AC5)+ABS(AD5)+ABS(AE5)+ABS(AF5)+ABS(AG5)+ABS(AH5)+ABS(AI5)+ABS(AJ5),6) -> 758.75399
D6: 持仓公允 | E6: -35.898292 | F6: 0 | G6: 0 | H6: 0 | I6: 0 | J6: -4.12495 | K6: 21.64795 | L6: -10.0572 | M6: 1.141 | N6: -12.1351 | O6: 0 | P6: 0 | Q6: -8.221 | R6: 5.9618 | S6: 8.49395 | T6: 5.44635 | U6: 2.10825 | V6: 0 | W6: 0 | X6: -2.47915 | Y6: 6.12115 | Z6: -31.50315 | AA6: -13.3356 | AB6: -4.1717 | AC6: 0 | AD6: 0 | AE6: -6.17185 | AF6: 13.29155 | AG6: -8.182 | AH6: 31.1405 | AI6: -21.79275 | AJ6: 0 | AK6: =ROUND(ABS(E6)+ABS(F6)+ABS(G6)+ABS(H6)+ABS(I6)+ABS(J6)+ABS(K6)+ABS(L6)+ABS(M6)+ABS(N6)+ABS(O6)+ABS(P6)+ABS(Q6)+ABS(R6)+ABS(S6)+ABS(T6)+ABS(U6)+ABS(V6)+ABS(W6)+ABS(X6)+ABS(Y6)+ABS(Z6)+ABS(AA6)+ABS(AB6)+ABS(AC6)+ABS(AD6)+ABS(AE6)+ABS(AF6)+ABS(AG6)+ABS(AH6)+ABS(AI6)+ABS(AJ6),6) -> 253.42524
D7: OCI公允 | E7: 0 | F7: 0 | G7: 0 | H7: 0 | I7: 0 | J7: -4.12495 | K7: 21.64795 | L7: -10.0572 | M7: 1.141 | N7: -12.1351 | O7: 0 | P7: 0 | Q7: -8.221 | R7: 5.9618 | S7: 8.49395 | T7: 5.44635 | U7: 2.10825 | V7: 0 | W7: 0 | X7: -2.47915 | Y7: 6.12115 | Z7: -31.50315 | AA7: -13.3356 | AB7: -4.1717 | AC7: 0 | AD7: 0 | AE7: -6.17185 | AF7: 13.29155 | AG7: -8.182 | AH7: 31.1405 | AI7: -21.79275 | AJ7: 0 | AK7: =ROUND(ABS(E7)+ABS(F7)+ABS(G7)+ABS(H7)+ABS(I7)+ABS(J7)+ABS(K7)+ABS(L7)+ABS(M7)+ABS(N7)+ABS(O7)+ABS(P7)+ABS(Q7)+ABS(R7)+ABS(S7)+ABS(T7)+ABS(U7)+ABS(V7)+ABS(W7)+ABS(X7)+ABS(Y7)+ABS(Z7)+ABS(AA7)+ABS(AB7)+ABS(AC7)+ABS(AD7)+ABS(AE7)+ABS(AF7)+ABS(AG7)+ABS(AH7)+ABS(AI7)+ABS(AJ7),6) -> 217.52695
C8: 北京银行 | D8: 持仓成本 | E8: 879.18426 | F8: 0 | G8: 0 | H8: 0 | I8: 0 | J8: 0 | K8: 0 | L8: 0 | M8: 0 | N8: 0 | O8: 0 | P8: 0 | Q8: 0 | R8: 0 | S8: 0 | T8: 0 | U8: 0 | V8: 0 | W8: 0 | X8: 0 | Y8: 0 | Z8: 0 | AA8: 0 | AB8: 0 | AC8: 0 | AD8: 0 | AE8: 0 | AF8: 0 | AG8: 0 | AH8: 0 | AI8: 0 | AJ8: 0 | AK8: =ROUND(ABS(E8)+ABS(F8)+ABS(G8)+ABS(H8)+ABS(I8)+ABS(J8)+ABS(K8)+ABS(L8)+ABS(M8)+ABS(N8)+ABS(O8)+ABS(P8)+ABS(Q8)+ABS(R8)+ABS(S8)+ABS(T8)+ABS(U8)+ABS(V8)+ABS(W8)+ABS(X8)+ABS(Y8)+ABS(Z8)+ABS(AA8)+ABS(AB8)+ABS(AC8)+ABS(AD8)+ABS(AE8)+ABS(AF8)+ABS(AG8)+ABS(AH8)+ABS(AI8)+ABS(AJ8),6) -> 879.18426
D9: 持仓公允 | E9: -57.184259 | F9: 0 | G9: 0 | H9: 0 | I9: 0 | J9: 6 | K9: 10.5 | L9: -6 | M9: -3 | N9: -3 | O9: 0 | P9: 0 | Q9: 1.5 | R9: 1.5 | S9: -22.5 | T9: -7.5 | U9: -13.5 | V9: 0 | W9: 0 | X9: -3 | Y9: 15 | Z9: -9 | AA9: 6 | AB9: -6 | AC9: 0 | AD9: 0 | AE9: 1.5 | AF9: -4.5 | AG9: 4.5 | AH9: 13.5 | AI9: -9 | AJ9: 0 | AK9: =ROUND(ABS(E9)+ABS(F9)+ABS(G9)+ABS(H9)+ABS(I9)+ABS(J9)+ABS(K9)+ABS(L9)+ABS(M9)+ABS(N9)+ABS(O9)+ABS(P9)+ABS(Q9)+ABS(R9)+ABS(S9)+ABS(T9)+ABS(U9)+ABS(V9)+ABS(W9)+ABS(X9)+ABS(Y9)+ABS(Z9)+ABS(AA9)+ABS(AB9)+ABS(AC9)+ABS(AD9)+ABS(AE9)+ABS(AF9)+ABS(AG9)+ABS(AH9)+ABS(AI9)+ABS(AJ9),6) -> 204.18426
D10: OCI公允 | E10: 0 | F10: 0 | G10: 0 | H10: 0 | I10: 0 | J10: 6 | K10: 10.5 | L10: -6 | M10: -3 | N10: -3 | O10: 0 | P10: 0 | Q10: 1.5 | R10: 1.5 | S10: -22.5 | T10: -7.5 | U10: -13.5 | V10: 0 | W10: 0 | X10: -3 | Y10: 15 | Z10: -9 | AA10: 6 | AB10: -6 | AC10: 0 | AD10: 0 | AE10: 1.5 | AF10: -4.5 | AG10: 4.5 | AH10: 13.5 | AI10: -9 | AJ10: 0 | AK10: =ROUND(ABS(E10)+ABS(F10)+ABS(G10)+ABS(H10)+ABS(I10)+ABS(J10)+ABS(K10)+ABS(L10)+ABS(M10)+ABS(N10)+ABS(O10)+ABS(P10)+ABS(Q10)+ABS(R10)+ABS(S10)+ABS(T10)+ABS(U10)+ABS(V10)+ABS(W10)+ABS(X10)+ABS(Y10)+ABS(Z10)+ABS(AA10)+ABS(AB10)+ABS(AC10)+ABS(AD10)+ABS(AE10)+ABS(AF10)+ABS(AG10)+ABS(AH10)+ABS(AI10)+ABS(AJ10),6) -> 147
C11: 北控水务集团 | D11: 持仓成本 | E11: 452.26321 | F11: 0 | G11: 0 | H11: 0 | I11: 0 | J11: 0 | K11: 0 | L11: 0 | M11: 0 | N11: 0 | O11: 0 | P11: 0 | Q11: 0 | R11: 0 | S11: 0 | T11: 0 | U11: 0 | V11: 0 | W11: 0 | X11: 0 | Y11: 0 | Z11: 0 | AA11: 0 | AB11: 0 | AC11: 0 | AD11: 0 | AE11: 0 | AF11: 0 | AG11: 0 | AH11: 0 | AI11: 0 | AJ11: 0 | AK11: =ROUND(ABS(E11)+ABS(F11)+ABS(G11)+ABS(H11)+ABS(I11)+ABS(J11)+ABS(K11)+ABS(L11)+ABS(M11)+ABS(N11)+ABS(O11)+ABS(P11)+ABS(Q11)+ABS(R11)+ABS(S11)+ABS(T11)+ABS(U11)+ABS(V11)+ABS(W11)+ABS(X11)+ABS(Y11)+ABS(Z11)+ABS(AA11)+ABS(AB11)+ABS(AC11)+ABS(AD11)+ABS(AE11)+ABS(AF11)+ABS(AG11)+ABS(AH11)+ABS(AI11)+ABS(AJ11),6) -> 452.26321
D12: 持仓公允 | E12: -10.742409 | F12: 0 | G12: 0 | H12: 0 | I12: 0 | J12: 0.3622 | K12: 6.017 | L12: 1.9422 | M12: 0.7028 | N12: 0.9382 | O12: 0 | P12: 0 | Q12: -0.1008 | R12: 1.0322 | S12: 5.3646 | T12: 0.0512 | U12: -7.5064 | V12: 0 | W12: 0 | X12: -0.1512 | Y12: 8.5722 | Z12: 1.3206 | AA12: 11.3328 | AB12: -0.1056 | AC12: 0 | AD12: 0 | AE12: -1.7326 | AF12: -5.7202 | AG12: 7.0304 | AH12: 4.1226 | AI12: 3.558 | AJ12: 0 | AK12: =ROUND(ABS(E12)+ABS(F12)+ABS(G12)+ABS(H12)+ABS(I12)+ABS(J12)+ABS(K12)+ABS(L12)+ABS(M12)+ABS(N12)+ABS(O12)+ABS(P12)+ABS(Q12)+ABS(R12)+ABS(S12)+ABS(T12)+ABS(U12)+ABS(V12)+ABS(W12)+ABS(X12)+ABS(Y12)+ABS(Z12)+ABS(AA12)+ABS(AB12)+ABS(AC12)+ABS(AD12)+ABS(AE12)+ABS(AF12)+ABS(AG12)+ABS(AH12)+ABS(AI12)+ABS(AJ12),6) -> 78.406209
D13: OCI公允 | E13: 0 | F13: 0 | G13: 0 | H13: 0 | I13: 0 | J13: 0.3622 | K13: 6.017 | L13: 1.9422 | M13: 0.7028 | N13: 0.9382 | O13: 0 | P13: 0 | Q13: -0.1008 | R13: 1.0322 | S13: 5.3646 | T13: 0.0512 | U13: -7.5064 | V13: 0 | W13: 0 | X13: -0.1512 | Y13: 8.5722 | Z13: 1.3206 | AA13: 11.3328 | AB13: -0.1056 | AC13: 0 | AD13: 0 | AE13: -1.7326 | AF13: -5.7202 | AG13: 7.0304 | AH13: 4.1226 | AI13: 3.558 | AJ13: 0 | AK13: =ROUND(ABS(E13)+ABS(F13)+ABS(G13)+ABS(H13)+ABS(I13)+ABS(J13)+ABS(K13)+ABS(L13)+ABS(M13)+ABS(N13)+ABS(O13)+ABS(P13)+ABS(Q13)+ABS(R13)+ABS(S13)+ABS(T13)+ABS(U13)+ABS(V13)+ABS(W13)+ABS(X13)+ABS(Y13)+ABS(Z13)+ABS(AA13)+ABS(AB13)+ABS(AC13)+ABS(AD13)+ABS(AE13)+ABS(AF13)+ABS(AG13)+ABS(AH13)+ABS(AI13)+ABS(AJ13),6) -> 67.6638
C14: 工商银行 | D14: 持仓成本 | E14: 814.29188 | F14: 0 | G14: 0 | H14: 0 | I14: 0 | J14: 0 | K14: 0 | L14: 0 | M14: 0 | N14: 0 | O14: 0 | P14: 0 | Q14: 0 | R14: 0 | S14: 0 | T14: 0 | U14: 0 | V14: 0 | W14: 0 | X14: 0 | Y14: 0 | Z14: 0 | AA14: 0 | AB14: 0 | AC14: 0 | AD14: 0 | AE14: 0 | AF14: 0 | AG14: 0 | AH14: 0 | AI14: 0 | AJ14: 0 | AK14: =ROUND(ABS(E14)+ABS(F14)+ABS(G14)+ABS(H14)+ABS(I14)+ABS(J14)+ABS(K14)+ABS(L14)+ABS(M14)+ABS(N14)+ABS(O14)+ABS(P14)+ABS(Q14)+ABS(R14)+ABS(S14)+ABS(T14)+ABS(U14)+ABS(V14)+ABS(W14)+ABS(X14)+ABS(Y14)+ABS(Z14)+ABS(AA14)+ABS(AB14)+ABS(AC14)+ABS(AD14)+ABS(AE14)+ABS(AF14)+ABS(AG14)+ABS(AH14)+ABS(AI14)+ABS(AJ14),6) -> 814.29188
D15: 持仓公允 | E15: 145.29794 | F15: 0 | G15: 0 | H15: 0 | I15: 0 | J15: -15.26617 | K15: 1.37241 | L15: -10.34688 | M15: -4.64168 | N15: 2.80568 | O15: 0 | P15: 0 | Q15: 16.5393 | R15: 7.52862 | S15: -9.11982 | T15: 15.30748 | U15: 0.76449 | V15: 0 | W15: 0 | X15: -1.84229 | Y15: -5.30621 | Z15: -16.12263 | AA15: -4.8042 | AB15: -3.24462 | AC15: 0 | AD15: 0 | AE15: 13.76286 | AF15: 17.45424 | AG15: 34.65314 | AH15: 4.98406 | AI15: -22.68225 | AJ15: 0 | AK15: =ROUND(ABS(E15)+ABS(F15)+ABS(G15)+ABS(H15)+ABS(I15)+ABS(J15)+ABS(K15)+ABS(L15)+ABS(M15)+ABS(N15)+ABS(O15)+ABS(P15)+ABS(Q15)+ABS(R15)+ABS(S15)+ABS(T15)+ABS(U15)+ABS(V15)+ABS(W15)+ABS(X15)+ABS(Y15)+ABS(Z15)+ABS(AA15)+ABS(AB15)+ABS(AC15)+ABS(AD15)+ABS(AE15)+ABS(AF15)+ABS(AG15)+ABS(AH15)+ABS(AI15)+ABS(AJ15),6) -> 353.84697
D16: OCI公允 | E16: 0 | F16: 0 | G16: 0 | H16: 0 | I16: 0 | J16: -15.26617 | K16: 1.37241 | L16: -10.34688 | M16: -4.64168 | N16: 2.80568 | O16: 0 | P16: 0 | Q16: 16.5393 | R16: 7.52862 | S16: -9.11982 | T16: 15.30748 | U16: 0.76449 | V16: 0 | W16: 0 | X16: -1.84229 | Y16: -5.30621 | Z16: -16.12263 | AA16: -4.8042 | AB16: -3.24462 | AC16: 0 | AD16: 0 | AE16: 13.76286 | AF16: 17.45424 | AG16: 34.65314 | AH16: 4.98406 | AI16: -22.68225 | AJ16: 0 | AK16: =ROUND(ABS(E16)+ABS(F16)+ABS(G16)+ABS(H16)+ABS(I16)+ABS(J16)+ABS(K16)+ABS(L16)+ABS(M16)+ABS(N16)+ABS(O16)+ABS(P16)+ABS(Q16)+ABS(R16)+ABS(S16)+ABS(T16)+ABS(U16)+ABS(V16)+ABS(W16)+ABS(X16)+ABS(Y16)+ABS(Z16)+ABS(AA16)+ABS(AB16)+ABS(AC16)+ABS(AD16)+ABS(AE16)+ABS(AF16)+ABS(AG16)+ABS(AH16)+ABS(AI16)+ABS(AJ16),6) -> 208.54903
D17: 应收应付 | E17: 24.038 | F17: 0 | G17: 0 | H17: 0 | I17: 0 | J17: 0 | K17: 0 | L17: 0 | M17: 0 | N17: 0 | O17: 0 | P17: 0 | Q17: 0 | R17: 0 | S17: 0 | T17: 0 | U17: 0 | V17: 0 | W17: 0 | X17: 0 | Y17: 0 | Z17: 0 | AA17: 0 | AB17: 0 | AC17: 0 | AD17: 0 | AE17: 0 | AF17: 0 | AG17: -24.038 | AH17: 0 | AI17: 0 | AJ17: 0 | AK17: =ROUND(ABS(E17)+ABS(F17)+ABS(G17)+ABS(H17)+ABS(I17)+ABS(J17)+ABS(K17)+ABS(L17)+ABS(M17)+ABS(N17)+ABS(O17)+ABS(P17)+ABS(Q17)+ABS(R17)+ABS(S17)+ABS(T17)+ABS(U17)+ABS(V17)+ABS(W17)+ABS(X17)+ABS(Y17)+ABS(Z17)+ABS(AA17)+ABS(AB17)+ABS(AC17)+ABS(AD17)+ABS(AE17)+ABS(AF17)+ABS(AG17)+ABS(AH17)+ABS(AI17)+ABS(AJ17),6) -> 48.076
C18: 光大银行 | D18: 持仓成本 | E18: 976.68199 | F18: 0 | G18: 0 | H18: 0 | I18: 0 | J18: 0 | K18: 0 | L18: 0 | M18: 0 | N18: 0 | O18: 0 | P18: 0 | Q18: 0 | R18: 0 | S18: 0 | T18: 0 | U18: 0 | V18: 0 | W18: 0 | X18: 0 | Y18: 0 | Z18: 0 | AA18: 0 | AB18: 0 | AC18: 0 | AD18: 0 | AE18: 0 | AF18: 0 | AG18: 0 | AH18: 0 | AI18: 0 | AJ18: 0 | AK18: =ROUND(ABS(E18)+ABS(F18)+ABS(G18)+ABS(H18)+ABS(I18)+ABS(J18)+ABS(K18)+ABS(L18)+ABS(M18)+ABS(N18)+ABS(O18)+ABS(P18)+ABS(Q18)+ABS(R18)+ABS(S18)+ABS(T18)+ABS(U18)+ABS(V18)+ABS(W18)+ABS(X18)+ABS(Y18)+ABS(Z18)+ABS(AA18)+ABS(AB18)+ABS(AC18)+ABS(AD18)+ABS(AE18)+ABS(AF18)+ABS(AG18)+ABS(AH18)+ABS(AI18)+ABS(AJ18),6) -> 976.68199
D19: 持仓公允 | E19: -34.381994 | F19: 0 | G19: 0 | H19: 0 | I19: 0 | J19: -2.7 | K19: 5.4 | L19: -2.7 | M19: -5.4 | N19: -5.4 | O19: 0 | P19: 0 | Q19: 2.7 | R19: 0 | S19: -8.1 | T19: -13.5 | U19: -8.1 | V19: 0 | W19: 0 | X19: -2.7 | Y19: 13.5 | Z19: -8.1 | AA19: 5.4 | AB19: -2.7 | AC19: 0 | AD19: 0 | AE19: 2.7 | AF19: -5.4 | AG19: -10.8 | AH19: 5.4 | AI19: -5.4 | AJ19: 0 | AK19: =ROUND(ABS(E19)+ABS(F19)+ABS(G19)+ABS(H19)+ABS(I19)+ABS(J19)+ABS(K19)+ABS(L19)+ABS(M19)+ABS(N19)+ABS(O19)+ABS(P19)+ABS(Q19)+ABS(R19)+ABS(S19)+ABS(T19)+ABS(U19)+ABS(V19)+ABS(W19)+ABS(X19)+ABS(Y19)+ABS(Z19)+ABS(AA19)+ABS(AB19)+ABS(AC19)+ABS(AD19)+ABS(AE19)+ABS(AF19)+ABS(AG19)+ABS(AH19)+ABS(AI19)+ABS(AJ19),6) -> 150.48199
D20: OCI公允 | E20: 0 | F20: 0 | G20: 0 | H20: 0 | I20: 0 | J20: -2.7 | K20: 5.4 | L20: -2.7 | M20: -5.4 | N20: -5.4 | O20: 0 | P20: 0 | Q20: 2.7 | R20: 0 | S20: -8.1 | T20: -13.5 | U20: -8.1 | V20: 0 | W20: 0 | X20: -2.7 | Y20: 13.5 | Z20: -8.1 | AA20: 5.4 | AB20: -2.7 | AC20: 0 | AD20: 0 | AE20: 2.7 | AF20: -5.4 | AG20: -10.8 | AH20: 5.4 | AI20: -5.4 | AJ20: 0 | AK20: =ROUND(ABS(E20)+ABS(F20)+ABS(G20)+ABS(H20)+ABS(I20)+ABS(J20)+ABS(K20)+ABS(L20)+ABS(M20)+ABS(N20)+ABS(O20)+ABS(P20)+ABS(Q20)+ABS(R20)+ABS(S20)+ABS(T20)+ABS(U20)+ABS(V20)+ABS(W20)+ABS(X20)+ABS(Y20)+ABS(Z20)+ABS(AA20)+ABS(AB20)+ABS(AC20)+ABS(AD20)+ABS(AE20)+ABS(AF20)+ABS(AG20)+ABS(AH20)+ABS(AI20)+ABS(AJ20),6) -> 116.1
C21: 贵州茅台 | D21: 持仓成本 | E21: 14.83109 | F21: 0 | G21: 0 | H21: 0 | I21: 0 | J21: 0 | K21: 0 | L21: 0 | M21: 0 | N21: 0 | O21: 0 | P21: 0 | Q21: 0 | R21: 0 | S21: 0 | T21: 0 | U21: 0 | V21: 0 | W21: 0 | X21: 0 | Y21: 0 | Z21: 0 | AA21: 0 | AB21: 0 | AC21: 0 | AD21: 0 | AE21: -14.83109 | AF21: 0 | AG21: 0 | AH21: 0 | AI21: 0 | AJ21: 0 | AK21: =ROUND(ABS(E21)+ABS(F21)+ABS(G21)+ABS(H21)+ABS(I21)+ABS(J21)+ABS(K21)+ABS(L21)+ABS(M21)+ABS(N21)+ABS(O21)+ABS(P21)+ABS(Q21)+ABS(R21)+ABS(S21)+ABS(T21)+ABS(U21)+ABS(V21)+ABS(W21)+ABS(X21)+ABS(Y21)+ABS(Z21)+ABS(AA21)+ABS(AB21)+ABS(AC21)+ABS(AD21)+ABS(AE21)+ABS(AF21)+ABS(AG21)+ABS(AH21)+ABS(AI21)+ABS(AJ21),6) -> 29.66218
D22: 持仓公允 | E22: -1.05929 | F22: 0 | G22: 0 | H22: 0 | I22: 0 | J22: 0.4882 | K22: 0.0201 | L22: -0.0465 | M22: -0.1106 | N22: 0.068 | O22: 0 | P22: 0 | Q22: 0.0413 | R22: -0.1223 | S22: -0.1299 | T22: -0.0912 | U22: -0.0689 | V22: 0 | W22: 0 | X22: -0.06 | Y22: -0.0245 | Z22: -0.2249 | AA22: -0.11 | AB22: -0.0306 | AC22: 0 | AD22: 0 | AE22: 1.46109 | AF22: 0 | AG22: 0 | AH22: 0 | AI22: 0 | AJ22: 0 | AK22: =ROUND(ABS(E22)+ABS(F22)+ABS(G22)+ABS(H22)+ABS(I22)+ABS(J22)+ABS(K22)+ABS(L22)+ABS(M22)+ABS(N22)+ABS(O22)+ABS(P22)+ABS(Q22)+ABS(R22)+ABS(S22)+ABS(T22)+ABS(U22)+ABS(V22)+ABS(W22)+ABS(X22)+ABS(Y22)+ABS(Z22)+ABS(AA22)+ABS(AB22)+ABS(AC22)+ABS(AD22)+ABS(AE22)+ABS(AF22)+ABS(AG22)+ABS(AH22)+ABS(AI22)+ABS(AJ22),6) -> 4.15738
D23: OCI公允 | E23: 0 | F23: 0 | G23: 0 | H23: 0 | I23: 0 | J23: 0.4882 | K23: 0.0201 | L23: -0.0465 | M23: -0.1106 | N23: 0.068 | O23: 0 | P23: 0 | Q23: 0.0413 | R23: -0.1223 | S23: -0.1299 | T23: -0.0912 | U23: -0.0689 | V23: 0 | W23: 0 | X23: -0.06 | Y23: -0.0245 | Z23: -0.2249 | AA23: -0.11 | AB23: -0.0306 | AC23: 0 | AD23: 0 | AE23: 1.46109 | AF23: 0 | AG23: 0 | AH23: 0 | AI23: 0 | AJ23: 0 | AK23: =ROUND(ABS(E23)+ABS(F23)+ABS(G23)+ABS(H23)+ABS(I23)+ABS(J23)+ABS(K23)+ABS(L23)+ABS(M23)+ABS(N23)+ABS(O23)+ABS(P23)+ABS(Q23)+ABS(R23)+ABS(S23)+ABS(T23)+ABS(U23)+ABS(V23)+ABS(W23)+ABS(X23)+ABS(Y23)+ABS(Z23)+ABS(AA23)+ABS(AB23)+ABS(AC23)+ABS(AD23)+ABS(AE23)+ABS(AF23)+ABS(AG23)+ABS(AH23)+ABS(AI23)+ABS(AJ23),6) -> 3.09809
D24: OCI价差 | E24: 0 | F24: 0 | G24: 0 | H24: 0 | I24: 0 | J24: 0 | K24: 0 | L24: 0 | M24: 0 | N24: 0 | O24: 0 | P24: 0 | Q24: 0 | R24: 0 | S24: 0 | T24: 0 | U24: 0 | V24: 0 | W24: 0 | X24: 0 | Y24: 0 | Z24: 0 | AA24: 0 | AB24: 0 | AC24: 0 | AD24: 0 | AE24: -1.363692 | AF24: 0 | AG24: 0 | AH24: 0 | AI24: 0 | AJ24: 0 | AK24: =ROUND(ABS(E24)+ABS(F24)+ABS(G24)+ABS(H24)+ABS(I24)+ABS(J24)+ABS(K24)+ABS(L24)+ABS(M24)+ABS(N24)+ABS(O24)+ABS(P24)+ABS(Q24)+ABS(R24)+ABS(S24)+ABS(T24)+ABS(U24)+ABS(V24)+ABS(W24)+ABS(X24)+ABS(Y24)+ABS(Z24)+ABS(AA24)+ABS(AB24)+ABS(AC24)+ABS(AD24)+ABS(AE24)+ABS(AF24)+ABS(AG24)+ABS(AH24)+ABS(AI24)+ABS(AJ24),6) -> 1.363692
C25: 海底捞 | D25: 持仓成本 | E25: 536.57688 | F25: 0 | G25: 0 | H25: 0 | I25: 0 | J25: 0 | K25: 0 | L25: 0 | M25: 0 | N25: 0 | O25: 0 | P25: 0 | Q25: 0 | R25: 0 | S25: 0 | T25: 0 | U25: 0 | V25: 0 | W25: 0 | X25: 0 | Y25: 0 | Z25: 0 | AA25: 0 | AB25: 0 | AC25: 0 | AD25: 0 | AE25: 0 | AF25: 0 | AG25: 0 | AH25: 0 | AI25: 0 | AJ25: 0 | AK25: =ROUND(ABS(E25)+ABS(F25)+ABS(G25)+ABS(H25)+ABS(I25)+ABS(J25)+ABS(K25)+ABS(L25)+ABS(M25)+ABS(N25)+ABS(O25)+ABS(P25)+ABS(Q25)+ABS(R25)+ABS(S25)+ABS(T25)+ABS(U25)+ABS(V25)+ABS(W25)+ABS(X25)+ABS(Y25)+ABS(Z25)+ABS(AA25)+ABS(AB25)+ABS(AC25)+ABS(AD25)+ABS(AE25)+ABS(AF25)+ABS(AG25)+ABS(AH25)+ABS(AI25)+ABS(AJ25),6) -> 536.57688
D26: 持仓公允 | E26: -25.05888 | F26: 0 | G26: 0 | H26: 0 | I26: 0 | J26: -2.0108 | K26: -3.20104 | L26: 5.18772 | M26: -9.25288 | N26: -0.95132 | O26: 0 | P26: 0 | Q26: 27.8308 | R26: -13.4036 | S26: 47.20848 | T26: -3.51384 | U26: -6.15632 | V26: 0 | W26: 0 | X26: 0.5288 | Y26: 4.921 | Z26: -0.5634 | AA26: 6.108 | AB26: 5.2292 | AC26: 0 | AD26: 0 | AE26: -2.79284 | AF26: 1.69644 | AG26: -14.75296 | AH26: 18.85276 | AI26: -3.9138 | AJ26: 0 | AK26: =ROUND(ABS(E26)+ABS(F26)+ABS(G26)+ABS(H26)+ABS(I26)+ABS(J26)+ABS(K26)+ABS(L26)+ABS(M26)+ABS(N26)+ABS(O26)+ABS(P26)+ABS(Q26)+ABS(R26)+ABS(S26)+ABS(T26)+ABS(U26)+ABS(V26)+ABS(W26)+ABS(X26)+ABS(Y26)+ABS(Z26)+ABS(AA26)+ABS(AB26)+ABS(AC26)+ABS(AD26)+ABS(AE26)+ABS(AF26)+ABS(AG26)+ABS(AH26)+ABS(AI26)+ABS(AJ26),6) -> 203.13488
D27: OCI公允 | E27: 0 | F27: 0 | G27: 0 | H27: 0 | I27: 0 | J27: -2.0108 | K27: -3.20104 | L27: 5.18772 | M27: -9.25288 | N27: -0.95132 | O27: 0 | P27: 0 | Q27: 27.8308 | R27: -13.4036 | S27: 47.20848 | T27: -3.51384 | U27: -6.15632 | V27: 0 | W27: 0 | X27: 0.5288 | Y27: 4.921 | Z27: -0.5634 | AA27: 6.108 | AB27: 5.2292 | AC27: 0 | AD27: 0 | AE27: -2.79284 | AF27: 1.69644 | AG27: -14.75296 | AH27: 18.85276 | AI27: -3.9138 | AJ27: 0 | AK27: =ROUND(ABS(E27)+ABS(F27)+ABS(G27)+ABS(H27)+ABS(I27)+ABS(J27)+ABS(K27)+ABS(L27)+ABS(M27)+ABS(N27)+ABS(O27)+ABS(P27)+ABS(Q27)+ABS(R27)+ABS(S27)+ABS(T27)+ABS(U27)+ABS(V27)+ABS(W27)+ABS(X27)+ABS(Y27)+ABS(Z27)+ABS(AA27)+ABS(AB27)+ABS(AC27)+ABS(AD27)+ABS(AE27)+ABS(AF27)+ABS(AG27)+ABS(AH27)+ABS(AI27)+ABS(AJ27),6) -> 178.076
C28: 海尔智家 | D28: 持仓成本 | E28: 453.40333 | F28: 0 | G28: 0 | H28: 0 | I28: 0 | J28: 0 | K28: 0 | L28: 0 | M28: 0 | N28: 0 | O28: 0 | P28: 0 | Q28: 0 | R28: 0 | S28: 0 | T28: 0 | U28: 0 | V28: 0 | W28: 0 | X28: 0 | Y28: 0 | Z28: 0 | AA28: 0 | AB28: 0 | AC28: 0 | AD28: 0 | AE28: 0 | AF28: 0 | AG28: 0 | AH28: 0 | AI28: 0 | AJ28: 0 | AK28: =ROUND(ABS(E28)+ABS(F28)+ABS(G28)+ABS(H28)+ABS(I28)+ABS(J28)+ABS(K28)+ABS(L28)+ABS(M28)+ABS(N28)+ABS(O28)+ABS(P28)+ABS(Q28)+ABS(R28)+ABS(S28)+ABS(T28)+ABS(U28)+ABS(V28)+ABS(W28)+ABS(X28)+ABS(Y28)+ABS(Z28)+ABS(AA28)+ABS(AB28)+ABS(AC28)+ABS(AD28)+ABS(AE28)+ABS(AF28)+ABS(AG28)+ABS(AH28)+ABS(AI28)+ABS(AJ28),6) -> 453.40333
D29: 持仓公允 | E29: -17.625888 | F29: 0 | G29: 0 | H29: 0 | I29: 0 | J29: 15.76616 | K29: 4.59776 | L29: 5.17092 | M29: 0.36172 | N29: 4.142 | O29: 0 | P29: 0 | Q29: 3.83664 | R29: 3.50508 | S29: -1.43056 | T29: -0.30492 | U29: 1.77536 | V29: 0 | W29: 0 | X29: 0.1984 | Y29: 4.627 | Z29: -0.1254 | AA29: -7.92768 | AB29: -7.60312 | AC29: 0 | AD29: 0 | AE29: -4.59024 | AF29: 4.27944 | AG29: -4.38424 | AH29: 8.42624 | AI29: -7.116 | AJ29: 0 | AK29: =ROUND(ABS(E29)+ABS(F29)+ABS(G29)+ABS(H29)+ABS(I29)+ABS(J29)+ABS(K29)+ABS(L29)+ABS(M29)+ABS(N29)+ABS(O29)+ABS(P29)+ABS(Q29)+ABS(R29)+ABS(S29)+ABS(T29)+ABS(U29)+ABS(V29)+ABS(W29)+ABS(X29)+ABS(Y29)+ABS(Z29)+ABS(AA29)+ABS(AB29)+ABS(AC29)+ABS(AD29)+ABS(AE29)+ABS(AF29)+ABS(AG29)+ABS(AH29)+ABS(AI29)+ABS(AJ29),6) -> 107.79477
D30: OCI公允 | E30: 0 | F30: 0 | G30: 0 | H30: 0 | I30: 0 | J30: 15.76616 | K30: 4.59776 | L30: 5.17092 | M30: 0.36172 | N30: 4.142 | O30: 0 | P30: 0 | Q30: 3.83664 | R30: 3.50508 | S30: -1.43056 | T30: -0.30492 | U30: 1.77536 | V30: 0 | W30: 0 | X30: 0.1984 | Y30: 4.627 | Z30: -0.1254 | AA30: -7.92768 | AB30: -7.60312 | AC30: 0 | AD30: 0 | AE30: -4.59024 | AF30: 4.27944 | AG30: -4.38424 | AH30: 8.42624 | AI30: -7.116 | AJ30: 0 | AK30: =ROUND(ABS(E30)+ABS(F30)+ABS(G30)+ABS(H30)+ABS(I30)+ABS(J30)+ABS(K30)+ABS(L30)+ABS(M30)+ABS(N30)+ABS(O30)+ABS(P30)+ABS(Q30)+ABS(R30)+ABS(S30)+ABS(T30)+ABS(U30)+ABS(V30)+ABS(W30)+ABS(X30)+ABS(Y30)+ABS(Z30)+ABS(AA30)+ABS(AB30)+ABS(AC30)+ABS(AD30)+ABS(AE30)+ABS(AF30)+ABS(AG30)+ABS(AH30)+ABS(AI30)+ABS(AJ30),6) -> 90.16888
C31: 华电国际电力股份 | D31: 持仓成本 | E31: 607.74285 | F31: 0 | G31: 0 | H31: 0 | I31: 0 | J31: 0 | K31: 0 | L31: 0 | M31: 0 | N31: 0 | O31: 0 | P31: 0 | Q31: 0 | R31: 0 | S31: 0 | T31: 0 | U31: 0 | V31: 0 | W31: 0 | X31: 0 | Y31: 0 | Z31: 0 | AA31: 0 | AB31: 0 | AC31: 0 | AD31: 0 | AE31: 0 | AF31: 0 | AG31: 0 | AH31: 0 | AI31: 0 | AJ31: 0 | AK31: =ROUND(ABS(E31)+ABS(F31)+ABS(G31)+ABS(H31)+ABS(I31)+ABS(J31)+ABS(K31)+ABS(L31)+ABS(M31)+ABS(N31)+ABS(O31)+ABS(P31)+ABS(Q31)+ABS(R31)+ABS(S31)+ABS(T31)+ABS(U31)+ABS(V31)+ABS(W31)+ABS(X31)+ABS(Y31)+ABS(Z31)+ABS(AA31)+ABS(AB31)+ABS(AC31)+ABS(AD31)+ABS(AE31)+ABS(AF31)+ABS(AG31)+ABS(AH31)+ABS(AI31)+ABS(AJ31),6) -> 607.74285
D32: 持仓公允 | E32: -59.880148 | F32: 0 | G32: 0 | H32: 0 | I32: 0 | J32: 7.6218 | K32: 0.8073 | L32: -9.22275 | M32: 17.0097 | N32: -9.13065 | O32: 0 | P32: 0 | Q32: -0.1239 | R32: 8.4588 | S32: -5.3646 | T32: -2.6202 | U32: -4.45545 | V32: 0 | W32: 0 | X32: 2.49465 | Y32: 3.5826 | Z32: -3.2364 | AA32: -0.594 | AB32: -2.8017 | AC32: 0 | AD32: 0 | AE32: 0.06165 | AF32: 0.90645 | AG32: 5.2272 | AH32: -1.4352 | AI32: -4.00275 | AJ32: 0 | AK32: =ROUND(ABS(E32)+ABS(F32)+ABS(G32)+ABS(H32)+ABS(I32)+ABS(J32)+ABS(K32)+ABS(L32)+ABS(M32)+ABS(N32)+ABS(O32)+ABS(P32)+ABS(Q32)+ABS(R32)+ABS(S32)+ABS(T32)+ABS(U32)+ABS(V32)+ABS(W32)+ABS(X32)+ABS(Y32)+ABS(Z32)+ABS(AA32)+ABS(AB32)+ABS(AC32)+ABS(AD32)+ABS(AE32)+ABS(AF32)+ABS(AG32)+ABS(AH32)+ABS(AI32)+ABS(AJ32),6) -> 149.0379
D33: OCI公允 | E33: 0 | F33: 0 | G33: 0 | H33: 0 | I33: 0 | J33: 7.6218 | K33: 0.8073 | L33: -9.22275 | M33: 17.0097 | N33: -9.13065 | O33: 0 | P33: 0 | Q33: -0.1239 | R33: 8.4588 | S33: -5.3646 | T33: -2.6202 | U33: -4.45545 | V33: 0 | W33: 0 | X33: 2.49465 | Y33: 3.5826 | Z33: -3.2364 | AA33: -0.594 | AB33: -2.8017 | AC33: 0 | AD33: 0 | AE33: 0.06165 | AF33: 0.90645 | AG33: 5.2272 | AH33: -1.4352 | AI33: -4.00275 | AJ33: 0 | AK33: =ROUND(ABS(E33)+ABS(F33)+ABS(G33)+ABS(H33)+ABS(I33)+ABS(J33)+ABS(K33)+ABS(L33)+ABS(M33)+ABS(N33)+ABS(O33)+ABS(P33)+ABS(Q33)+ABS(R33)+ABS(S33)+ABS(T33)+ABS(U33)+ABS(V33)+ABS(W33)+ABS(X33)+ABS(Y33)+ABS(Z33)+ABS(AA33)+ABS(AB33)+ABS(AC33)+ABS(AD33)+ABS(AE33)+ABS(AF33)+ABS(AG33)+ABS(AH33)+ABS(AI33)+ABS(AJ33),6) -> 89.15775
C34: 华润电力 | D34: 持仓成本 | E34: 333.94923 | F34: 0 | G34: 0 | H34: 0 | I34: 0 | J34: 0 | K34: 0 | L34: 0 | M34: 0 | N34: 0 | O34: 0 | P34: 0 | Q34: 0 | R34: 0 | S34: 0 | T34: 0 | U34: 0 | V34: 0 | W34: 0 | X34: 0 | Y34: 0 | Z34: 0 | AA34: 0 | AB34: 0 | AC34: 0 | AD34: 0 | AE34: 0 | AF34: 0 | AG34: 0 | AH34: 0 | AI34: 0 | AJ34: 0 | AK34: =ROUND(ABS(E34)+ABS(F34)+ABS(G34)+ABS(H34)+ABS(I34)+ABS(J34)+ABS(K34)+ABS(L34)+ABS(M34)+ABS(N34)+ABS(O34)+ABS(P34)+ABS(Q34)+ABS(R34)+ABS(S34)+ABS(T34)+ABS(U34)+ABS(V34)+ABS(W34)+ABS(X34)+ABS(Y34)+ABS(Z34)+ABS(AA34)+ABS(AB34)+ABS(AC34)+ABS(AD34)+ABS(AE34)+ABS(AF34)+ABS(AG34)+ABS(AH34)+ABS(AI34)+ABS(AJ34),6) -> 333.94923
D35: 持仓公允 | E35: -23.269354 | F35: 0 | G35: 0 | H35: 0 | I35: 0 | J35: 8.83552 | K35: 0.64352 | L35: 1.18254 | M35: 2.83554 | N35: -2.5848 | O35: 0 | P35: 0 | Q35: 0.64468 | R35: 2.1426 | S35: 0 | T35: 1.28816 | U35: -3.82894 | V35: 0 | W35: 0 | X35: 1.14242 | Y35: -1.68112 | Z35: 0.38928 | AA35: 2.9328 | AB35: -4.00016 | AC35: 0 | AD35: 0 | AE35: 0.57154 | AF35: 0.10494 | AG35: 1.71156 | AH35: -0.83306 | AI35: -5.5149 | AJ35: 0 | AK35: =ROUND(ABS(E35)+ABS(F35)+ABS(G35)+ABS(H35)+ABS(I35)+ABS(J35)+ABS(K35)+ABS(L35)+ABS(M35)+ABS(N35)+ABS(O35)+ABS(P35)+ABS(Q35)+ABS(R35)+ABS(S35)+ABS(T35)+ABS(U35)+ABS(V35)+ABS(W35)+ABS(X35)+ABS(Y35)+ABS(Z35)+ABS(AA35)+ABS(AB35)+ABS(AC35)+ABS(AD35)+ABS(AE35)+ABS(AF35)+ABS(AG35)+ABS(AH35)+ABS(AI35)+ABS(AJ35),6) -> 66.137434
D36: OCI公允 | E36: 0 | F36: 0 | G36: 0 | H36: 0 | I36: 0 | J36: 8.83552 | K36: 0.64352 | L36: 1.18254 | M36: 2.83554 | N36: -2.5848 | O36: 0 | P36: 0 | Q36: 0.64468 | R36: 2.1426 | S36: 0 | T36: 1.28816 | U36: -3.82894 | V36: 0 | W36: 0 | X36: 1.14242 | Y36: -1.68112 | Z36: 0.38928 | AA36: 2.9328 | AB36: -4.00016 | AC36: 0 | AD36: 0 | AE36: 0.57154 | AF36: 0.10494 | AG36: 1.71156 | AH36: -0.83306 | AI36: -5.5149 | AJ36: 0 | AK36: =ROUND(ABS(E36)+ABS(F36)+ABS(G36)+ABS(H36)+ABS(I36)+ABS(J36)+ABS(K36)+ABS(L36)+ABS(M36)+ABS(N36)+ABS(O36)+ABS(P36)+ABS(Q36)+ABS(R36)+ABS(S36)+ABS(T36)+ABS(U36)+ABS(V36)+ABS(W36)+ABS(X36)+ABS(Y36)+ABS(Z36)+ABS(AA36)+ABS(AB36)+ABS(AC36)+ABS(AD36)+ABS(AE36)+ABS(AF36)+ABS(AG36)+ABS(AH36)+ABS(AI36)+ABS(AJ36),6) -> 42.86808
C37: 建设银行 | D37: 持仓成本 | E37: 766.76257 | F37: 0 | G37: 0 | H37: 0 | I37: 0 | J37: 0 | K37: 0 | L37: 0 | M37: 0 | N37: 0 | O37: 0 | P37: 0 | Q37: 0 | R37: 0 | S37: 0 | T37: 0 | U37: 0 | V37: 0 | W37: 0 | X37: 0 | Y37: 0 | Z37: 0 | AA37: 0 | AB37: 0 | AC37: 0 | AD37: 0 | AE37: 0 | AF37: 0 | AG37: 0 | AH37: 0 | AI37: 0 | AJ37: 0 | AK37: =ROUND(ABS(E37)+ABS(F37)+ABS(G37)+ABS(H37)+ABS(I37)+ABS(J37)+ABS(K37)+ABS(L37)+ABS(M37)+ABS(N37)+ABS(O37)+ABS(P37)+ABS(Q37)+ABS(R37)+ABS(S37)+ABS(T37)+ABS(U37)+ABS(V37)+ABS(W37)+ABS(X37)+ABS(Y37)+ABS(Z37)+ABS(AA37)+ABS(AB37)+ABS(AC37)+ABS(AD37)+ABS(AE37)+ABS(AF37)+ABS(AG37)+ABS(AH37)+ABS(AI37)+ABS(AJ37),6) -> 766.76257
D38: 持仓公允 | E38: -7.65191 | F38: 0 | G38: 0 | H38: 0 | I38: 0 | J38: -4.42101 | K38: 7.00909 | L38: -10.58772 | M38: 0.18623 | N38: -3.39383 | O38: 0 | P38: 0 | Q38: 12.6401 | R38: 7.57779 | S38: -3.93404 | T38: 7.95443 | U38: -2.57015 | V38: 0 | W38: 0 | X38: -3.20595 | Y38: -4.5276 | Z38: -9.59508 | AA38: -4.88004 | AB38: -0.16742 | AC38: 0 | AD38: 0 | AE38: 4.99356 | AF38: 10.20338 | AG38: 25.33454 | AH38: 10.68826 | AI38: -24.46125 | AJ38: 0 | AK38: =ROUND(ABS(E38)+ABS(F38)+ABS(G38)+ABS(H38)+ABS(I38)+ABS(J38)+ABS(K38)+ABS(L38)+ABS(M38)+ABS(N38)+ABS(O38)+ABS(P38)+ABS(Q38)+ABS(R38)+ABS(S38)+ABS(T38)+ABS(U38)+ABS(V38)+ABS(W38)+ABS(X38)+ABS(Y38)+ABS(Z38)+ABS(AA38)+ABS(AB38)+ABS(AC38)+ABS(AD38)+ABS(AE38)+ABS(AF38)+ABS(AG38)+ABS(AH38)+ABS(AI38)+ABS(AJ38),6) -> 165.98338
D39: OCI公允 | E39: 0 | F39: 0 | G39: 0 | H39: 0 | I39: 0 | J39: -4.42101 | K39: 7.00909 | L39: -10.58772 | M39: 0.18623 | N39: -3.39383 | O39: 0 | P39: 0 | Q39: 12.6401 | R39: 7.57779 | S39: -3.93404 | T39: 7.95443 | U39: -2.57015 | V39: 0 | W39: 0 | X39: -3.20595 | Y39: -4.5276 | Z39: -9.59508 | AA39: -4.88004 | AB39: -0.16742 | AC39: 0 | AD39: 0 | AE39: 4.99356 | AF39: 10.20338 | AG39: 25.33454 | AH39: 10.68826 | AI39: -24.46125 | AJ39: 0 | AK39: =ROUND(ABS(E39)+ABS(F39)+ABS(G39)+ABS(H39)+ABS(I39)+ABS(J39)+ABS(K39)+ABS(L39)+ABS(M39)+ABS(N39)+ABS(O39)+ABS(P39)+ABS(Q39)+ABS(R39)+ABS(S39)+ABS(T39)+ABS(U39)+ABS(V39)+ABS(W39)+ABS(X39)+ABS(Y39)+ABS(Z39)+ABS(AA39)+ABS(AB39)+ABS(AC39)+ABS(AD39)+ABS(AE39)+ABS(AF39)+ABS(AG39)+ABS(AH39)+ABS(AI39)+ABS(AJ39),6) -> 158.33147
D40: 应收应付 | E40: 13.006 | F40: 0 | G40: 0 | H40: 0 | I40: 0 | J40: 0 | K40: 0 | L40: 0 | M40: 0 | N40: 0 | O40: 0 | P40: 0 | Q40: 0 | R40: 0 | S40: 0 | T40: 0 | U40: 0 | V40: 0 | W40: 0 | X40: 0 | Y40: 0 | Z40: 0 | AA40: 0 | AB40: 0 | AC40: 0 | AD40: 0 | AE40: 0 | AF40: 0 | AG40: -13.006 | AH40: 0 | AI40: 0 | AJ40: 0 | AK40: =ROUND(ABS(E40)+ABS(F40)+ABS(G40)+ABS(H40)+ABS(I40)+ABS(J40)+ABS(K40)+ABS(L40)+ABS(M40)+ABS(N40)+ABS(O40)+ABS(P40)+ABS(Q40)+ABS(R40)+ABS(S40)+ABS(T40)+ABS(U40)+ABS(V40)+ABS(W40)+ABS(X40)+ABS(Y40)+ABS(Z40)+ABS(AA40)+ABS(AB40)+ABS(AC40)+ABS(AD40)+ABS(AE40)+ABS(AF40)+ABS(AG40)+ABS(AH40)+ABS(AI40)+ABS(AJ40),6) -> 26.012
...

Sheet 本年累计
A1: 绩效归因产品口径一级分类 | B1: 绩效归因产品口径二级分类 | C1: 六级科目名称 | D1: 绩效归因科目口径 | E1: 2026年初 | F1: 2026-01-01 | G1: 2026-01-02 | H1: 2026-01-03 | I1: 2026-01-04 | J1: 2026-01-05 | K1: 2026-01-06 | L1: 2026-01-07 | M1: 2026-01-08 | N1: 2026-01-09 | O1: 2026-01-10 | P1: 2026-01-11 | Q1: 2026-01-12 | R1: 2026-01-13 | S1: 2026-01-14 | T1: 2026-01-15 | U1: 2026-01-16 | V1: 2026-01-17 | W1: 2026-01-18 | X1: 2026-01-19 | Y1: 2026-01-20 | Z1: 2026-01-21 | AA1: 2026-01-22 | AB1: 2026-01-23 | AC1: 2026-01-24 | AD1: 2026-01-25 | AE1: 2026-01-26 | AF1: 2026-01-27 | AG1: 2026-01-28 | AH1: 2026-01-29 | AI1: 2026-01-30 | AJ1: 2026-01-31
A2: 权益类产品 | B2: 股票 | C2: 安徽皖通高速公路 | D2: 持仓成本 | E2: 12.061917 | F2: =E2+Sheet54!F2 -> 12.061917 | G2: =F2+Sheet54!G2 -> 12.061917 | H2: =G2+Sheet54!H2 -> 12.061917 | I2: =H2+Sheet54!I2 -> 12.061917 | J2: =I2+Sheet54!J2 -> 12.061917 | K2: =J2+Sheet54!K2 -> 12.061917 | L2: =K2+Sheet54!L2 -> 12.061917 | M2: =L2+Sheet54!M2 -> 12.061917 | ... AJ2: =AI2+Sheet54!AJ2 -> 12.061917
D3: 持仓公允 | E3: -0.323925 | F3: =E3+Sheet54!F3 -> -0.323925 | G3: =F3+Sheet54!G3 -> -0.323925 | H3: =G3+Sheet54!H3 -> -0.323925 | I3: =H3+Sheet54!I3 -> -0.323925 | J3: =I3+Sheet54!J3 -> -0.504977 | K3: =J3+Sheet54!K3 -> -0.550887 | L3: =K3+Sheet54!L3 -> -0.52911 | M3: =L3+Sheet54!M3 -> -0.564942 | ... AJ3: =AI3+Sheet54!AJ3 -> 0.311028
D4: OCI公允 | E4: 0 | F4: =Sheet54!F4 -> 0 | G4: =Sheet54!G4 -> 0 | H4: =Sheet54!H4 -> 0 | I4: =Sheet54!I4 -> 0 | J4: =Sheet54!J4 -> -0.181052 | K4: =Sheet54!K4 -> -0.04591 | L4: =Sheet54!L4 -> 0.021777 | M4: =Sheet54!M4 -> -0.035832 | ... AJ4: =Sheet54!AJ4 -> 0
C5: 安踏体育 | D5: 持仓成本 | E5: 758.75399 | F5: =E5+Sheet54!F5 -> 758.75399 | G5: =F5+Sheet54!G5 -> 758.75399 | H5: =G5+Sheet54!H5 -> 758.75399 | I5: =H5+Sheet54!I5 -> 758.75399 | J5: =I5+Sheet54!J5 -> 758.75399 | K5: =J5+Sheet54!K5 -> 758.75399 | L5: =K5+Sheet54!L5 -> 758.75399 | M5: =L5+Sheet54!M5 -> 758.75399 | ... AJ5: =AI5+Sheet54!AJ5 -> 758.75399
D6: 持仓公允 | E6: -35.898292 | F6: =E6+Sheet54!F6 -> -35.898292 | G6: =F6+Sheet54!G6 -> -35.898292 | H6: =G6+Sheet54!H6 -> -35.898292 | I6: =H6+Sheet54!I6 -> -35.898292 | J6: =I6+Sheet54!J6 -> -40.023242 | K6: =J6+Sheet54!K6 -> -18.375292 | L6: =K6+Sheet54!L6 -> -28.432492 | M6: =L6+Sheet54!M6 -> -27.291492 | ... AJ6: =AI6+Sheet54!AJ6 -> -62.720242
D7: OCI公允 | E7: 0 | F7: =Sheet54!F7 -> 0 | G7: =Sheet54!G7 -> 0 | H7: =Sheet54!H7 -> 0 | I7: =Sheet54!I7 -> 0 | J7: =Sheet54!J7 -> -4.12495 | K7: =Sheet54!K7 -> 21.64795 | L7: =Sheet54!L7 -> -10.0572 | M7: =Sheet54!M7 -> 1.141 | ... AJ7: =Sheet54!AJ7 -> 0
C8: 北京银行 | D8: 持仓成本 | E8: 879.18426 | F8: =E8+Sheet54!F8 -> 879.18426 | G8: =F8+Sheet54!G8 -> 879.18426 | H8: =G8+Sheet54!H8 -> 879.18426 | I8: =H8+Sheet54!I8 -> 879.18426 | J8: =I8+Sheet54!J8 -> 879.18426 | K8: =J8+Sheet54!K8 -> 879.18426 | L8: =K8+Sheet54!L8 -> 879.18426 | M8: =L8+Sheet54!M8 -> 879.18426 | ... AJ8: =AI8+Sheet54!AJ8 -> 879.18426
D9: 持仓公允 | E9: -57.184259 | F9: =E9+Sheet54!F9 -> -57.184259 | G9: =F9+Sheet54!G9 -> -57.184259 | H9: =G9+Sheet54!H9 -> -57.184259 | I9: =H9+Sheet54!I9 -> -57.184259 | J9: =I9+Sheet54!J9 -> -51.184259 | K9: =J9+Sheet54!K9 -> -40.684259 | L9: =K9+Sheet54!L9 -> -46.684259 | M9: =L9+Sheet54!M9 -> -49.684259 | ... AJ9: =AI9+Sheet54!AJ9 -> -84.184259
D10: OCI公允 | E10: 0 | F10: =Sheet54!F10 -> 0 | G10: =Sheet54!G10 -> 0 | H10: =Sheet54!H10 -> 0 | I10: =Sheet54!I10 -> 0 | J10: =Sheet54!J10 -> 6 | K10: =Sheet54!K10 -> 10.5 | L10: =Sheet54!L10 -> -6 | M10: =Sheet54!M10 -> -3 | ... AJ10: =Sheet54!AJ10 -> 0
C11: 北控水务集团 | D11: 持仓成本 | E11: 452.26321 | F11: =E11+Sheet54!F11 -> 452.26321 | G11: =F11+Sheet54!G11 -> 452.26321 | H11: =G11+Sheet54!H11 -> 452.26321 | I11: =H11+Sheet54!I11 -> 452.26321 | J11: =I11+Sheet54!J11 -> 452.26321 | K11: =J11+Sheet54!K11 -> 452.26321 | L11: =K11+Sheet54!L11 -> 452.26321 | M11: =L11+Sheet54!M11 -> 452.26321 | ... AJ11: =AI11+Sheet54!AJ11 -> 452.26321
D12: 持仓公允 | E12: -10.742409 | F12: =E12+Sheet54!F12 -> -10.742409 | G12: =F12+Sheet54!G12 -> -10.742409 | H12: =G12+Sheet54!H12 -> -10.742409 | I12: =H12+Sheet54!I12 -> -10.742409 | J12: =I12+Sheet54!J12 -> -10.380209 | K12: =J12+Sheet54!K12 -> -4.363209 | L12: =K12+Sheet54!L12 -> -2.421009 | M12: =L12+Sheet54!M12 -> -1.718209 | ... AJ12: =AI12+Sheet54!AJ12 -> 26.287791
D13: OCI公允 | E13: 0 | F13: =Sheet54!F13 -> 0 | G13: =Sheet54!G13 -> 0 | H13: =Sheet54!H13 -> 0 | I13: =Sheet54!I13 -> 0 | J13: =Sheet54!J13 -> 0.3622 | K13: =Sheet54!K13 -> 6.017 | L13: =Sheet54!L13 -> 1.9422 | M13: =Sheet54!M13 -> 0.7028 | ... AJ13: =Sheet54!AJ13 -> 0
C14: 工商银行 | D14: 持仓成本 | E14: 814.29188 | F14: =E14+Sheet54!F14 -> 814.29188 | G14: =F14+Sheet54!G14 -> 814.29188 | H14: =G14+Sheet54!H14 -> 814.29188 | I14: =H14+Sheet54!I14 -> 814.29188 | J14: =I14+Sheet54!J14 -> 814.29188 | K14: =J14+Sheet54!K14 -> 814.29188 | L14: =K14+Sheet54!L14 -> 814.29188 | M14: =L14+Sheet54!M14 -> 814.29188 | ... AJ14: =AI14+Sheet54!AJ14 -> 814.29188
D15: 持仓公允 | E15: 145.29794 | F15: =E15+Sheet54!F15 -> 145.29794 | G15: =F15+Sheet54!G15 -> 145.29794 | H15: =G15+Sheet54!H15 -> 145.29794 | I15: =H15+Sheet54!I15 -> 145.29794 | J15: =I15+Sheet54!J15 -> 130.03177 | K15: =J15+Sheet54!K15 -> 131.40418 | L15: =K15+Sheet54!L15 -> 121.0573 | M15: =L15+Sheet54!M15 -> 116.41562 | ... AJ15: =AI15+Sheet54!AJ15 -> 167.09347
D16: OCI公允 | E16: 0 | F16: =Sheet54!F16 -> 0 | G16: =Sheet54!G16 -> 0 | H16: =Sheet54!H16 -> 0 | I16: =Sheet54!I16 -> 0 | J16: =Sheet54!J16 -> -15.26617 | K16: =Sheet54!K16 -> 1.37241 | L16: =Sheet54!L16 -> -10.34688 | M16: =Sheet54!M16 -> -4.64168 | ... AJ16: =Sheet54!AJ16 -> 0
D17: 应收应付 | E17: 24.038 | F17: =E17+Sheet54!F17 -> 24.038 | G17: =F17+Sheet54!G17 -> 24.038 | H17: =G17+Sheet54!H17 -> 24.038 | I17: =H17+Sheet54!I17 -> 24.038 | J17: =I17+Sheet54!J17 -> 24.038 | K17: =J17+Sheet54!K17 -> 24.038 | L17: =K17+Sheet54!L17 -> 24.038 | M17: =L17+Sheet54!M17 -> 24.038 | ... AJ17: =AI17+Sheet54!AJ17 -> 0
C18: 光大银行 | D18: 持仓成本 | E18: 976.68199 | F18: =E18+Sheet54!F18 -> 976.68199 | G18: =F18+Sheet54!G18 -> 976.68199 | H18: =G18+Sheet54!H18 -> 976.68199 | I18: =H18+Sheet54!I18 -> 976.68199 | J18: =I18+Sheet54!J18 -> 976.68199 | K18: =J18+Sheet54!K18 -> 976.68199 | L18: =K18+Sheet54!L18 -> 976.68199 | M18: =L18+Sheet54!M18 -> 976.68199 | ... AJ18: =AI18+Sheet54!AJ18 -> 976.68199
D19: 持仓公允 | E19: -34.381994 | F19: =E19+Sheet54!F19 -> -34.381994 | G19: =F19+Sheet54!G19 -> -34.381994 | H19: =G19+Sheet54!H19 -> -34.381994 | I19: =H19+Sheet54!I19 -> -34.381994 | J19: =I19+Sheet54!J19 -> -37.081994 | K19: =J19+Sheet54!K19 -> -31.681994 | L19: =K19+Sheet54!L19 -> -34.381994 | M19: =L19+Sheet54!M19 -> -39.781994 | ... AJ19: =AI19+Sheet54!AJ19 -> -80.281994
D20: OCI公允 | E20: 0 | F20: =Sheet54!F20 -> 0 | G20: =Sheet54!G20 -> 0 | H20: =Sheet54!H20 -> 0 | I20: =Sheet54!I20 -> 0 | J20: =Sheet54!J20 -> -2.7 | K20: =Sheet54!K20 -> 5.4 | L20: =Sheet54!L20 -> -2.7 | M20: =Sheet54!M20 -> -5.4 | ... AJ20: =Sheet54!AJ20 -> 0
C21: 贵州茅台 | D21: 持仓成本 | E21: 14.83109 | F21: =E21+Sheet54!F21 -> 14.83109 | G21: =F21+Sheet54!G21 -> 14.83109 | H21: =G21+Sheet54!H21 -> 14.83109 | I21: =H21+Sheet54!I21 -> 14.83109 | J21: =I21+Sheet54!J21 -> 14.83109 | K21: =J21+Sheet54!K21 -> 14.83109 | L21: =K21+Sheet54!L21 -> 14.83109 | M21: =L21+Sheet54!M21 -> 14.83109 | ... AJ21: =AI21+Sheet54!AJ21 -> 9.9475983e-14
D22: 持仓公允 | E22: -1.05929 | F22: =E22+Sheet54!F22 -> -1.05929 | G22: =F22+Sheet54!G22 -> -1.05929 | H22: =G22+Sheet54!H22 -> -1.05929 | I22: =H22+Sheet54!I22 -> -1.05929 | J22: =I22+Sheet54!J22 -> -0.57109 | K22: =J22+Sheet54!K22 -> -0.55099 | L22: =K22+Sheet54!L22 -> -0.59749 | M22: =L22+Sheet54!M22 -> -0.70809 | ... AJ22: =AI22+Sheet54!AJ22 -> -3.9968029e-14
D23: OCI公允 | E23: 0 | F23: =Sheet54!F23 -> 0 | G23: =Sheet54!G23 -> 0 | H23: =Sheet54!H23 -> 0 | I23: =Sheet54!I23 -> 0 | J23: =Sheet54!J23 -> 0.4882 | K23: =Sheet54!K23 -> 0.0201 | L23: =Sheet54!L23 -> -0.0465 | M23: =Sheet54!M23 -> -0.1106 | ... AJ23: =Sheet54!AJ23 -> 0
D24: OCI价差 | E24: 0 | F24: =Sheet54!F24 -> 0 | G24: =Sheet54!G24 -> 0 | H24: =Sheet54!H24 -> 0 | I24: =Sheet54!I24 -> 0 | J24: =Sheet54!J24 -> 0 | K24: =Sheet54!K24 -> 0 | L24: =Sheet54!L24 -> 0 | M24: =Sheet54!M24 -> 0 | ... AJ24: =Sheet54!AJ24 -> 0
C25: 海底捞 | D25: 持仓成本 | E25: 536.57688 | F25: =E25+Sheet54!F25 -> 536.57688 | G25: =F25+Sheet54!G25 -> 536.57688 | H25: =G25+Sheet54!H25 -> 536.57688 | I25: =H25+Sheet54!I25 -> 536.57688 | J25: =I25+Sheet54!J25 -> 536.57688 | K25: =J25+Sheet54!K25 -> 536.57688 | L25: =K25+Sheet54!L25 -> 536.57688 | M25: =L25+Sheet54!M25 -> 536.57688 | ... AJ25: =AI25+Sheet54!AJ25 -> 536.57688
D26: 持仓公允 | E26: -25.05888 | F26: =E26+Sheet54!F26 -> -25.05888 | G26: =F26+Sheet54!G26 -> -25.05888 | H26: =G26+Sheet54!H26 -> -25.05888 | I26: =H26+Sheet54!I26 -> -25.05888 | J26: =I26+Sheet54!J26 -> -27.06968 | K26: =J26+Sheet54!K26 -> -30.27072 | L26: =K26+Sheet54!L26 -> -25.083 | M26: =L26+Sheet54!M26 -> -34.33588 | ... AJ26: =AI26+Sheet54!AJ26 -> 31.99152
D27: OCI公允 | E27: 0 | F27: =Sheet54!F27 -> 0 | G27: =Sheet54!G27 -> 0 | H27: =Sheet54!H27 -> 0 | I27: =Sheet54!I27 -> 0 | J27: =Sheet54!J27 -> -2.0108 | K27: =Sheet54!K27 -> -3.20104 | L27: =Sheet54!L27 -> 5.18772 | M27: =Sheet54!M27 -> -9.25288 | ... AJ27: =Sheet54!AJ27 -> 0
C28: 海尔智家 | D28: 持仓成本 | E28: 453.40333 | F28: =E28+Sheet54!F28 -> 453.40333 | G28: =F28+Sheet54!G28 -> 453.40333 | H28: =G28+Sheet54!H28 -> 453.40333 | I28: =H28+Sheet54!I28 -> 453.40333 | J28: =I28+Sheet54!J28 -> 453.40333 | K28: =J28+Sheet54!K28 -> 453.40333 | L28: =K28+Sheet54!L28 -> 453.40333 | M28: =L28+Sheet54!M28 -> 453.40333 | ... AJ28: =AI28+Sheet54!AJ28 -> 453.40333
D29: 持仓公允 | E29: -17.625888 | F29: =E29+Sheet54!F29 -> -17.625888 | G29: =F29+Sheet54!G29 -> -17.625888 | H29: =G29+Sheet54!H29 -> -17.625888 | I29: =H29+Sheet54!I29 -> -17.625888 | J29: =I29+Sheet54!J29 -> -1.859728 | K29: =J29+Sheet54!K29 -> 2.738032 | L29: =K29+Sheet54!L29 -> 7.908952 | M29: =L29+Sheet54!M29 -> 8.270672 | ... AJ29: =AI29+Sheet54!AJ29 -> 5.578672
D30: OCI公允 | E30: 0 | F30: =Sheet54!F30 -> 0 | G30: =Sheet54!G30 -> 0 | H30: =Sheet54!H30 -> 0 | I30: =Sheet54!I30 -> 0 | J30: =Sheet54!J30 -> 15.76616 | K30: =Sheet54!K30 -> 4.59776 | L30: =Sheet54!L30 -> 5.17092 | M30: =Sheet54!M30 -> 0.36172 | ... AJ30: =Sheet54!AJ30 -> 0
C31: 华电国际电力股份 | D31: 持仓成本 | E31: 607.74285 | F31: =E31+Sheet54!F31 -> 607.74285 | G31: =F31+Sheet54!G31 -> 607.74285 | H31: =G31+Sheet54!H31 -> 607.74285 | I31: =H31+Sheet54!I31 -> 607.74285 | J31: =I31+Sheet54!J31 -> 607.74285 | K31: =J31+Sheet54!K31 -> 607.74285 | L31: =K31+Sheet54!L31 -> 607.74285 | M31: =L31+Sheet54!M31 -> 607.74285 | ... AJ31: =AI31+Sheet54!AJ31 -> 607.74285
D32: 持仓公允 | E32: -59.880148 | F32: =E32+Sheet54!F32 -> -59.880148 | G32: =F32+Sheet54!G32 -> -59.880148 | H32: =G32+Sheet54!H32 -> -59.880148 | I32: =H32+Sheet54!I32 -> -59.880148 | J32: =I32+Sheet54!J32 -> -52.258348 | K32: =J32+Sheet54!K32 -> -51.451048 | L32: =K32+Sheet54!L32 -> -60.673798 | M32: =L32+Sheet54!M32 -> -43.664098 | ... AJ32: =AI32+Sheet54!AJ32 -> -56.697598
D33: OCI公允 | E33: 0 | F33: =Sheet54!F33 -> 0 | G33: =Sheet54!G33 -> 0 | H33: =Sheet54!H33 -> 0 | I33: =Sheet54!I33 -> 0 | J33: =Sheet54!J33 -> 7.6218 | K33: =Sheet54!K33 -> 0.8073 | L33: =Sheet54!L33 -> -9.22275 | M33: =Sheet54!M33 -> 17.0097 | ... AJ33: =Sheet54!AJ33 -> 0
C34: 华润电力 | D34: 持仓成本 | E34: 333.94923 | F34: =E34+Sheet54!F34 -> 333.94923 | G34: =F34+Sheet54!G34 -> 333.94923 | H34: =G34+Sheet54!H34 -> 333.94923 | I34: =H34+Sheet54!I34 -> 333.94923 | J34: =I34+Sheet54!J34 -> 333.94923 | K34: =J34+Sheet54!K34 -> 333.94923 | L34: =K34+Sheet54!L34 -> 333.94923 | M34: =L34+Sheet54!M34 -> 333.94923 | ... AJ34: =AI34+Sheet54!AJ34 -> 333.94923
D35: 持仓公允 | E35: -23.269354 | F35: =E35+Sheet54!F35 -> -23.269354 | G35: =F35+Sheet54!G35 -> -23.269354 | H35: =G35+Sheet54!H35 -> -23.269354 | I35: =H35+Sheet54!I35 -> -23.269354 | J35: =I35+Sheet54!J35 -> -14.433834 | K35: =J35+Sheet54!K35 -> -13.790314 | L35: =K35+Sheet54!L35 -> -12.607774 | M35: =L35+Sheet54!M35 -> -9.772234 | ... AJ35: =AI35+Sheet54!AJ35 -> -17.287234
D36: OCI公允 | E36: 0 | F36: =Sheet54!F36 -> 0 | G36: =Sheet54!G36 -> 0 | H36: =Sheet54!H36 -> 0 | I36: =Sheet54!I36 -> 0 | J36: =Sheet54!J36 -> 8.83552 | K36: =Sheet54!K36 -> 0.64352 | L36: =Sheet54!L36 -> 1.18254 | M36: =Sheet54!M36 -> 2.83554 | ... AJ36: =Sheet54!AJ36 -> 0
C37: 建设银行 | D37: 持仓成本 | E37: 766.76257 | F37: =E37+Sheet54!F37 -> 766.76257 | G37: =F37+Sheet54!G37 -> 766.76257 | H37: =G37+Sheet54!H37 -> 766.76257 | I37: =H37+Sheet54!I37 -> 766.76257 | J37: =I37+Sheet54!J37 -> 766.76257 | K37: =J37+Sheet54!K37 -> 766.76257 | L37: =K37+Sheet54!L37 -> 766.76257 | M37: =L37+Sheet54!M37 -> 766.76257 | ... AJ37: =AI37+Sheet54!AJ37 -> 766.76257
D38: 持仓公允 | E38: -7.65191 | F38: =E38+Sheet54!F38 -> -7.65191 | G38: =F38+Sheet54!G38 -> -7.65191 | H38: =G38+Sheet54!H38 -> -7.65191 | I38: =H38+Sheet54!I38 -> -7.65191 | J38: =I38+Sheet54!J38 -> -12.07292 | K38: =J38+Sheet54!K38 -> -5.06383 | L38: =K38+Sheet54!L38 -> -15.65155 | M38: =L38+Sheet54!M38 -> -15.46532 | ... AJ38: =AI38+Sheet54!AJ38 -> 7.19138
D39: OCI公允 | E39: 0 | F39: =Sheet54!F39 -> 0 | G39: =Sheet54!G39 -> 0 | H39: =Sheet54!H39 -> 0 | I39: =Sheet54!I39 -> 0 | J39: =Sheet54!J39 -> -4.42101 | K39: =Sheet54!K39 -> 7.00909 | L39: =Sheet54!L39 -> -10.58772 | M39: =Sheet54!M39 -> 0.18623 | ... AJ39: =Sheet54!AJ39 -> 0
D40: 应收应付 | E40: 13.006 | F40: =E40+Sheet54!F40 -> 13.006 | G40: =F40+Sheet54!G40 -> 13.006 | H40: =G40+Sheet54!H40 -> 13.006 | I40: =H40+Sheet54!I40 -> 13.006 | J40: =I40+Sheet54!J40 -> 13.006 | K40: =J40+Sheet54!K40 -> 13.006 | L40: =K40+Sheet54!L40 -> 13.006 | M40: =L40+Sheet54!M40 -> 13.006 | ... AJ40: =AI40+Sheet54!AJ40 -> 0
...

Sheet 口径说明
B2: 资产类/负债类科目，口径为截止当日的累计余额
B3: 权益类/损益类科目，口径为当日的发生额
