Workbook

Sheet Part_II_a_领导考核
A1: Part II 投组 / 交易员考核
A2: II-a.1 领导考核 · 全账 + FIFO + 估值日盯市。估值日 2026-06-01（行情见「估值日行情」B1）；RPNL=SUMIFS(逐笔辅助!U)；MTM=SUMIFS(期末持仓!S)=市值(CNY)−FIFO剩余成本(期末持仓!T·本币透传)；汇率见 FX_RATES_TO_CNY_HIST；与引擎 position_end MTM 同口径。
A4: 指标 | B4: 口径 | C4: 权益现货（场内） | D4: 权益现货（深港） | E4: 权益现货 | F4: 股指期货 | G4: 权益类基金 | H4: 合计
A5: 成交笔数 | B5: 成交回报 | C5: =COUNTIFS('交易流水'!$X$2:$X$151,"*场内*") | D5: =COUNTIFS('交易流水'!$X$2:$X$151,"*深港*") | E5: =C5+D5 | F5: 0 | G5: 0 | H5: =C5+D5+F5+G5
A6: 买入笔数 | B6: 成交回报 | C6: =COUNTIFS('交易流水'!$X$2:$X$151,"*场内*",'交易流水'!$H$2:$H$151,"买入") | D6: =COUNTIFS('交易流水'!$X$2:$X$151,"*深港*",'交易流水'!$H$2:$H$151,"买入") | E6: =C6+D6 | F6: 0 | G6: 0 | H6: =C6+D6+F6+G6
A7: 卖出笔数 | B7: 成交回报 | C7: =COUNTIFS('交易流水'!$X$2:$X$151,"*场内*",'交易流水'!$H$2:$H$151,"卖出") | D7: =COUNTIFS('交易流水'!$X$2:$X$151,"*深港*",'交易流水'!$H$2:$H$151,"卖出") | E7: =C7+D7 | F7: 0 | G7: 0 | H7: =C7+D7+F7+G7
A8: 买入数量合计 | B8: 成交回报 | C8: =SUMIFS('交易流水'!$K$2:$K$151,'交易流水'!$X$2:$X$151,"*场内*",'交易流水'!$H$2:$H$151,"买入")/10000 | D8: =SUMIFS('交易流水'!$K$2:$K$151,'交易流水'!$X$2:$X$151,"*深港*",'交易流水'!$H$2:$H$151,"买入")/10000 | E8: =C8+D8 | F8: 0 | G8: 0 | H8: =C8+D8+F8+G8
A9: 卖出数量合计 | B9: 成交回报 | C9: =SUMIFS('交易流水'!$K$2:$K$151,'交易流水'!$X$2:$X$151,"*场内*",'交易流水'!$H$2:$H$151,"卖出")/10000 | D9: =SUMIFS('交易流水'!$K$2:$K$151,'交易流水'!$X$2:$X$151,"*深港*",'交易流水'!$H$2:$H$151,"卖出")/10000 | E9: =C9+D9 | F9: 0 | G9: 0 | H9: =C9+D9+F9+G9
A10: 买入金额合计(本币) | B10: 成交回报 | C10: =SUMIFS('交易流水'!$AR$2:$AR$151,'交易流水'!$X$2:$X$151,"*场内*",'交易流水'!$H$2:$H$151,"买入")/10000 | D10: =SUMIFS('交易流水'!$AR$2:$AR$151,'交易流水'!$X$2:$X$151,"*深港*",'交易流水'!$H$2:$H$151,"买入")/10000 | E10: =C10+D10 | F10: 0 | G10: 0 | H10: =C10+D10+F10+G10
A11: 卖出金额合计(本币) | B11: 成交回报 | C11: =SUMIFS('交易流水'!$AR$2:$AR$151,'交易流水'!$X$2:$X$151,"*场内*",'交易流水'!$H$2:$H$151,"卖出")/10000 | D11: =SUMIFS('交易流水'!$AR$2:$AR$151,'交易流水'!$X$2:$X$151,"*深港*",'交易流水'!$H$2:$H$151,"卖出")/10000 | E11: =C11+D11 | F11: 0 | G11: 0 | H11: =C11+D11+F11+G11
A12: 已实现损益（先买先卖 · 开平匹配） | B12: 全账考核 | C12: =SUMIFS('逐笔辅助'!$U$2:$U$191,'逐笔辅助'!$A$2:$A$191,"流水",'逐笔辅助'!$D$2:$D$191,"场内") | D12: =SUMIFS('逐笔辅助'!$U$2:$U$191,'逐笔辅助'!$A$2:$A$191,"流水",'逐笔辅助'!$D$2:$D$191,"深港") | E12: =C12+D12 | F12: 0 | G12: 0 | H12: =C12+D12+F12+G12
A13: 浮动盈亏（估值日盯市） | B13: 全账考核 | C13: =SUMIFS('期末持仓'!$S$2:$S$56,'期末持仓'!$A$2:$A$56,"场内") | D13: =SUMIFS('期末持仓'!$S$2:$S$56,'期末持仓'!$A$2:$A$56,"深港") | E13: =C13+D13 | F13: 0 | G13: 0 | H13: =C13+D13+F13+G13
A14: 股息收入（引擎日计提） | B14: 引擎 | C14: 274119.67 | D14: 284981.16 | E14: 559100.83 | H14: 559100.83
A15: 总损益（已实现 + 浮动 + 股息） | B15: 全账考核 | C15: =C12+C13+C14 | D15: =D12+D13+D14 | E15: =E12+E13+E14 | F15: =F12+F13+F14 | G15: =G12+G13+G14 | H15: =C15+D15+F15+G15
A16: 择时损益（相对931357.SH） | B16: 引擎/公式 | E16: 29901670 | H16: 29901670
A18: 期初投资（initial_capital）
A19: 自营权益4 | B19: 期初资金.xls | C19: 202510600
A20: 期初持仓成本合计 | C20: =SUM('期初批次'!$E$2:$E$41)
A21: 期初持仓市值合计 | C21: =SUM('期初批次'!$H$2:$H$41)

Sheet Part_II_a_运营财务
A1: Part II 投组 / 交易员考核
A2: II-a.2 运营 / 测试 / 财务 · 流水 + 加权均价。损益三行均为 Excel 公式：RPNL=SUMIFS(逐笔辅助!T 加权·CNY)；MTM=SUMIFS(期末持仓!W 流水净持仓盯市·CNY)；TOTAL=已实现+浮动；供运营手算对账，不与领导考核奖罚直接对比。
A4: 指标 | B4: 口径 | C4: 权益现货（场内） | D4: 权益现货（深港） | E4: 权益现货 | F4: 股指期货 | G4: 权益类基金 | H4: 合计
A5: 成交笔数 | B5: 成交回报 | C5: =COUNTIFS('交易流水'!$X$2:$X$151,"*场内*") | D5: =COUNTIFS('交易流水'!$X$2:$X$151,"*深港*") | E5: =C5+D5 | F5: 0 | G5: 0 | H5: =C5+D5+F5+G5
A6: 买入笔数 | B6: 成交回报 | C6: =COUNTIFS('交易流水'!$X$2:$X$151,"*场内*",'交易流水'!$H$2:$H$151,"买入") | D6: =COUNTIFS('交易流水'!$X$2:$X$151,"*深港*",'交易流水'!$H$2:$H$151,"买入") | E6: =C6+D6 | F6: 0 | G6: 0 | H6: =C6+D6+F6+G6
A7: 卖出笔数 | B7: 成交回报 | C7: =COUNTIFS('交易流水'!$X$2:$X$151,"*场内*",'交易流水'!$H$2:$H$151,"卖出") | D7: =COUNTIFS('交易流水'!$X$2:$X$151,"*深港*",'交易流水'!$H$2:$H$151,"卖出") | E7: =C7+D7 | F7: 0 | G7: 0 | H7: =C7+D7+F7+G7
A8: 买入数量合计 | B8: 成交回报 | C8: =SUMIFS('交易流水'!$K$2:$K$151,'交易流水'!$X$2:$X$151,"*场内*",'交易流水'!$H$2:$H$151,"买入")/10000 | D8: =SUMIFS('交易流水'!$K$2:$K$151,'交易流水'!$X$2:$X$151,"*深港*",'交易流水'!$H$2:$H$151,"买入")/10000 | E8: =C8+D8 | F8: 0 | G8: 0 | H8: =C8+D8+F8+G8
A9: 卖出数量合计 | B9: 成交回报 | C9: =SUMIFS('交易流水'!$K$2:$K$151,'交易流水'!$X$2:$X$151,"*场内*",'交易流水'!$H$2:$H$151,"卖出")/10000 | D9: =SUMIFS('交易流水'!$K$2:$K$151,'交易流水'!$X$2:$X$151,"*深港*",'交易流水'!$H$2:$H$151,"卖出")/10000 | E9: =C9+D9 | F9: 0 | G9: 0 | H9: =C9+D9+F9+G9
A10: 买入金额合计(本币) | B10: 成交回报 | C10: =SUMIFS('交易流水'!$AR$2:$AR$151,'交易流水'!$X$2:$X$151,"*场内*",'交易流水'!$H$2:$H$151,"买入")/10000 | D10: =SUMIFS('交易流水'!$AR$2:$AR$151,'交易流水'!$X$2:$X$151,"*深港*",'交易流水'!$H$2:$H$151,"买入")/10000 | E10: =C10+D10 | F10: 0 | G10: 0 | H10: =C10+D10+F10+G10
A11: 卖出金额合计(本币) | B11: 成交回报 | C11: =SUMIFS('交易流水'!$AR$2:$AR$151,'交易流水'!$X$2:$X$151,"*场内*",'交易流水'!$H$2:$H$151,"卖出")/10000 | D11: =SUMIFS('交易流水'!$AR$2:$AR$151,'交易流水'!$X$2:$X$151,"*深港*",'交易流水'!$H$2:$H$151,"卖出")/10000 | E11: =C11+D11 | F11: 0 | G11: 0 | H11: =C11+D11+F11+G11
A12: 已实现损益（加权均价） | B12: 流水对账 | C12: =SUMIFS('逐笔辅助'!$T$2:$T$191,'逐笔辅助'!$A$2:$A$191,"流水",'逐笔辅助'!$D$2:$D$191,"场内") | D12: =SUMIFS('逐笔辅助'!$T$2:$T$191,'逐笔辅助'!$A$2:$A$191,"流水",'逐笔辅助'!$D$2:$D$191,"深港") | E12: =C12+D12 | F12: 0 | G12: 0 | H12: =C12+D12+F12+G12
A13: 浮动盈亏（流水净持仓盯市） | B13: 流水对账 | C13: =SUMIFS('期末持仓'!$W$2:$W$56,'期末持仓'!$A$2:$A$56,"场内") | D13: =SUMIFS('期末持仓'!$W$2:$W$56,'期末持仓'!$A$2:$A$56,"深港") | E13: =C13+D13 | F13: 0 | G13: 0 | H13: =C13+D13+F13+G13
A14: 总损益（加权 + 流水浮动） | B14: 流水对账 | C14: =C12+C13 | D14: =D12+D13 | E14: =E12+E13 | F14: =F12+F13 | G14: =G12+G13 | H14: =C14+D14+F14+G14
A16: 期初投资（initial_capital）
A17: 自营权益4 | B17: 期初资金.xls | C17: 202510600
A18: 期初持仓成本合计 | C18: =SUM('期初批次'!$E$2:$E$41)
A19: 期初持仓市值合计 | C19: =SUM('期初批次'!$H$2:$H$41)

Sheet Part_II_a_第三轨
A1: Part II 投组 / 交易员考核
A2: II-a.3 第三轨试算 · 全账加权均价（期初纳入成本池）。RPNL=SUMIFS(逐笔辅助!AJ)；MTM=SUMIFS(期末持仓!Q−O)（全账净持仓×估值日市价−全账加权成本）；与运营轨(仅流水加权) / 考核轨(FIFO) 对比见下方。逐笔明细见逐笔辅助 AG–AL 列。
A4: 指标 | B4: 口径 | C4: 权益现货（场内） | D4: 权益现货（深港） | E4: 权益现货 | F4: 股指期货 | G4: 权益类基金 | H4: 合计
A5: 成交笔数 | B5: 成交回报 | C5: =COUNTIFS('交易流水'!$X$2:$X$151,"*场内*") | D5: =COUNTIFS('交易流水'!$X$2:$X$151,"*深港*") | E5: =C5+D5 | F5: 0 | G5: 0 | H5: =C5+D5+F5+G5
A6: 买入笔数 | B6: 成交回报 | C6: =COUNTIFS('交易流水'!$X$2:$X$151,"*场内*",'交易流水'!$H$2:$H$151,"买入") | D6: =COUNTIFS('交易流水'!$X$2:$X$151,"*深港*",'交易流水'!$H$2:$H$151,"买入") | E6: =C6+D6 | F6: 0 | G6: 0 | H6: =C6+D6+F6+G6
A7: 卖出笔数 | B7: 成交回报 | C7: =COUNTIFS('交易流水'!$X$2:$X$151,"*场内*",'交易流水'!$H$2:$H$151,"卖出") | D7: =COUNTIFS('交易流水'!$X$2:$X$151,"*深港*",'交易流水'!$H$2:$H$151,"卖出") | E7: =C7+D7 | F7: 0 | G7: 0 | H7: =C7+D7+F7+G7
A8: 买入数量合计 | B8: 成交回报 | C8: =SUMIFS('交易流水'!$K$2:$K$151,'交易流水'!$X$2:$X$151,"*场内*",'交易流水'!$H$2:$H$151,"买入")/10000 | D8: =SUMIFS('交易流水'!$K$2:$K$151,'交易流水'!$X$2:$X$151,"*深港*",'交易流水'!$H$2:$H$151,"买入")/10000 | E8: =C8+D8 | F8: 0 | G8: 0 | H8: =C8+D8+F8+G8
A9: 卖出数量合计 | B9: 成交回报 | C9: =SUMIFS('交易流水'!$K$2:$K$151,'交易流水'!$X$2:$X$151,"*场内*",'交易流水'!$H$2:$H$151,"卖出")/10000 | D9: =SUMIFS('交易流水'!$K$2:$K$151,'交易流水'!$X$2:$X$151,"*深港*",'交易流水'!$H$2:$H$151,"卖出")/10000 | E9: =C9+D9 | F9: 0 | G9: 0 | H9: =C9+D9+F9+G9
A10: 买入金额合计(本币) | B10: 成交回报 | C10: =SUMIFS('交易流水'!$AR$2:$AR$151,'交易流水'!$X$2:$X$151,"*场内*",'交易流水'!$H$2:$H$151,"买入")/10000 | D10: =SUMIFS('交易流水'!$AR$2:$AR$151,'交易流水'!$X$2:$X$151,"*深港*",'交易流水'!$H$2:$H$151,"买入")/10000 | E10: =C10+D10 | F10: 0 | G10: 0 | H10: =C10+D10+F10+G10
A11: 卖出金额合计(本币) | B11: 成交回报 | C11: =SUMIFS('交易流水'!$AR$2:$AR$151,'交易流水'!$X$2:$X$151,"*场内*",'交易流水'!$H$2:$H$151,"卖出")/10000 | D11: =SUMIFS('交易流水'!$AR$2:$AR$151,'交易流水'!$X$2:$X$151,"*深港*",'交易流水'!$H$2:$H$151,"卖出")/10000 | E11: =C11+D11 | F11: 0 | G11: 0 | H11: =C11+D11+F11+G11
A12: 已实现损益（全账加权均价·含期初） | B12: 第三轨 | C12: =SUMIFS('逐笔辅助'!$AJ$2:$AJ$191,'逐笔辅助'!$A$2:$A$191,"流水",'逐笔辅助'!$D$2:$D$191,"场内") | D12: =SUMIFS('逐笔辅助'!$AJ$2:$AJ$191,'逐笔辅助'!$A$2:$A$191,"流水",'逐笔辅助'!$D$2:$D$191,"深港") | E12: =C12+D12 | F12: 0 | G12: 0 | H12: =C12+D12+F12+G12
A13: 浮动盈亏（全账净持仓·加权成本盯市） | B13: 第三轨 | C13: =SUMIFS('期末持仓'!$Q$2:$Q$56,'期末持仓'!$A$2:$A$56,"场内")-SUMIFS('期末持仓'!$O$2:$O$56,'期末持仓'!$A$2:$A$56,"场内") | D13: =SUMIFS('期末持仓'!$Q$2:$Q$56,'期末持仓'!$A$2:$A$56,"深港")-SUMIFS('期末持仓'!$O$2:$O$56,'期末持仓'!$A$2:$A$56,"深港") | E13: =C13+D13 | F13: 0 | G13: 0 | H13: =C13+D13+F13+G13
A14: 总损益（全账加权 + 浮动） | B14: 第三轨 | C14: =C12+C13 | D14: =D12+D13 | E14: =E12+E13 | F14: =F12+F13 | G14: =G12+G13 | H14: =C14+D14+F14+G14
A16: ▼ 三轨 RPNL 对比（仅已实现）
A17: 已实现损益（流水加权均价·运营轨） | B17: 运营轨对比 | C17: =SUMIFS('逐笔辅助'!$T$2:$T$191,'逐笔辅助'!$A$2:$A$191,"流水",'逐笔辅助'!$D$2:$D$191,"场内") | D17: =SUMIFS('逐笔辅助'!$T$2:$T$191,'逐笔辅助'!$A$2:$A$191,"流水",'逐笔辅助'!$D$2:$D$191,"深港") | E17: =C17+D17 | F17: 0 | G17: 0 | H17: =C17+D17+F17+G17
A18: 第三轨 − 运营轨（RPNL） | B18: 差额 | C18: =C12-C17 | D18: =D12-D17 | E18: =C12-C17+D12-D17 | F18: 0 | G18: 0 | H18: =C12-C17+D12-D17
A19: 已实现损益（FIFO·考核轨） | B19: 考核轨对比 | C19: =SUMIFS('逐笔辅助'!$U$2:$U$191,'逐笔辅助'!$A$2:$A$191,"流水",'逐笔辅助'!$D$2:$D$191,"场内") | D19: =SUMIFS('逐笔辅助'!$U$2:$U$191,'逐笔辅助'!$A$2:$A$191,"流水",'逐笔辅助'!$D$2:$D$191,"深港") | E19: =C19+D19 | F19: 0 | G19: 0 | H19: =C19+D19+F19+G19
A21: 期初投资（initial_capital）
A22: 自营权益4 | B22: 期初资金.xls | C22: 202510600
A23: 期初持仓成本合计 | C23: =SUM('期初批次'!$E$2:$E$41)
A24: 期初持仓市值合计 | C24: =SUM('期初批次'!$H$2:$H$41)

Sheet 交易流水
A1: 序号 | B1: 发生日期 | C1: 账户编号 | D1: 账户名称 | E1: 账户代码 | F1: 证券代码 | G1: 证券名称 | H1: 委托方向 | I1: 最新价 | J1: 市场成交均价 | K1: 成交数量 | L1: 成交金额 | M1: 成交次数 | N1: 成交最低价 | O1: 成交最高价 | P1: 成交均价 | Q1: 成交均价(全价) | R1: 成交均价(净价) | S1: 交易市场 | T1: 市场成交数量 | U1: 数量成交比例(%) | V1: 市场成交金额 | W1: 组合编号 | X1: 组合名称 | Y1: 委托数量 | Z1: 市场最高价 | AA1: 市场最低价 | AB1: 委托次数 | AC1: 操作员 | AD1: 资产类别 | AE1: 涨跌幅(%) | AF1: 金额成交比例(%) | AG1: 价格差额比例(%) | AH1: 指令数量 | AI1: 资产单元序号 | AJ1: 资产单元名称 | AK1: 交易币种 | AL1: 交易席位 | AM1: 投资类型 | AN1: 资产单元编号 | AO1: 股东代码 | AP1: 指令下达人 | AQ1: 本币币种 | AR1: 本币成交金额 | AS1: RIC | AT1: Bloomberg | AU1: CUSIP | AV1: SEDOL | AW1: ISIN | AX1: 指令操作级别 | AY1: 账户组类型 | AZ1: 账户组 | BA1: 成交金额占净值(%) | BB1: 券商编号 | BC1: 券商名称 | BD1: 业务分类 | BE1: 是否ETF补券 | BF1: 发生金额(全价) | BG1: 今开盘价 | BH1: 是否强平委托 | BI1: 代下达人 | BJ1: 是否强平 | BK1: 价格类型 | BL1: 杂项分类 | BM1: 平仓盈亏 | BN1: 成交时间(分) | BO1: 证券类别 | BP1: 交易对手 | BQ1: 对方席位号 | BR1: 交易实例序号 | BS1: 成交状态
A2: 1 | B2: 2026-01-13 | C2: 3008 | D2: 自营权益4 | E2: 3008 | F2: 601098 | G2: 中南传媒 | H2: 买入 | I2: 11.56 | J2: 11.68 | K2: 200000 | L2: 2330000 | M2: 73 | N2: 11.65 | O2: 11.65 | P2: 11.65 | Q2: 11.65 | R2: 11.65 | S2: 上交所A | T2: 25567700 | U2: 0.7822 | V2: 298680747 | W2: 300821 | X2: 自营权益4（场内） | Y2: 200000 | Z2: 11.93 | AA2: 11.52 | AB2: 1 | AC2: 叶盛 | AD2: 股票资产 | AE2: -1.1121 | AF2: 0.7801 | AG2: 0.2739 | AH2: 200000 | AI2: 46 | AJ2: 自营权益4（场内） | AK2: 人民币 | AL2: 40878 | AN2: 30082 | AP2: 顾吟湫 | AQ2: 人民币 | AR2: 2330000 | AS2: 601098 | AT2: 601098 | AU2: 601098 | AV2: 601098 | AW2: 601098 | AX2: 无 | BA2: 1.1409 | BB2: 0 | BC2: 缺省券商 | BD2: 交易所业务 | BE2: 不是ETF补券指令 | BF2: -2,330,000.00 | BG2: 11.81 | BH2: 非强平 | BI2: 顾吟湫 | BJ2: 否 | BK2: 限价 | BM2: 0 | BN2: 31.266667 | BO2: 股票 | BR2: 0 | BS2: 已成交
A3: 2 | B3: 2026-01-13 | C3: 3008 | D3: 自营权益4 | E3: 3008 | F3: 601900 | G3: 南方传媒 | H3: 卖出 | I3: 15.31 | J3: 16.03 | K3: 200000 | L3: 3267529 | M3: 64 | N3: 16.05 | O3: 16.58 | P3: 16.337645 | Q3: 16.337645 | R3: 16.337645 | S3: 上交所A | T3: 86139472 | U3: 0.2322 | V3: 1380565150 | W3: 300821 | X3: 自营权益4（场内） | Y3: 200000 | Z3: 16.58 | AA3: 15.3 | AB3: 4 | AC3: 叶盛 | AD3: 股票资产 | AE3: 1.5926 | AF3: 0.2367 | AG3: 1.9373 | AH3: 200000 | AI3: 46 | AJ3: 自营权益4（场内） | AK3: 人民币 | AL3: 40878 | AN3: 30082 | AP3: 顾吟湫 | AQ3: 人民币 | AR3: 3267529 | AX3: 无 | BA3: 1.5999 | BB3: 0 | BC3: 缺省券商 | BD3: 交易所业务 | BE3: 不是ETF补券指令 | BF3: 3,267,529.00 | BG3: 16.58 | BH3: 非强平 | BI3: 顾吟湫 | BJ3: 否 | BK3: 限价 | BM3: 0 | BN3: 2.7 | BO3: 股票 | BR3: 0 | BS3: 已成交
A4: 3 | B4: 2026-01-20 | C4: 3008 | D4: 自营权益4 | E4: 3008 | F4: 2318 | G4: 中国平安 | H4: 卖出 | I4: 69 | J4: 68.85 | K4: 10000 | L4: 690500 | M4: 6 | N4: 69.05 | O4: 69.05 | P4: 69.05 | Q4: 69.05 | R4: 69.05 | S4: 港股通（深） | T4: 30771432 | U4: 0.0325 | V4: 2.1187495e+09 | W4: 300841 | X4: 自营权益4（深港） | Y4: 60000 | Z4: 69.65 | AA4: 68.1 | AB4: 6 | AC4: 叶盛 | AD4: 股票资产 | AE4: 0.8772 | AF4: 0.0326 | AG4: 0.2841 | AH4: 20000 | AI4: 53 | AJ4: 自营权益4（深港） | AK4: 人民币 | AL4: 6111 | AN4: 30084 | AP4: 顾吟湫 | AQ4: 人民币 | AR4: 616271.25 | AW4: CNE1000003X6 | AX4: 无 | BA4: 0.3063 | BB4: 0 | BC4: 缺省券商 | BD4: 交易所业务 | BE4: 不是ETF补券指令 | BF4: 690,500.00 | BG4: 0 | BH4: 非强平 | BI4: 顾吟湫 | BJ4: 否 | BK4: 增强限价盘 | BM4: 0 | BN4: 7.8333333 | BO4: 股票 | BR4: 0 | BS4: 已成交
A5: 4 | B5: 2026-01-21 | C5: 3008 | D5: 自营权益4 | E5: 3008 | F5: 858 | G5: 五 粮 液 | H5: 卖出 | I5: 103.05 | J5: 103.4 | K5: 20000 | L5: 2060319 | M5: 20 | N5: 103 | O5: 103.02 | P5: 103.01595 | Q5: 103.01595 | R5: 103.01595 | S5: 深交所A | T5: 26228280 | U5: 0.0763 | V5: 2.7118849e+09 | W5: 300821 | X5: 自营权益4（场内） | Y5: 20000 | Z5: 104.7 | AA5: 103 | AB5: 1 | AC5: 叶盛 | AD5: 股票资产 | AE5: -1.7729 | AF5: 0.076 | AG5: -0.367 | AH5: 20000 | AI5: 46 | AJ5: 自营权益4（场内） | AK5: 人民币 | AL5: 6111 | AN5: 30082 | AP5: 顾吟湫 | AQ5: 人民币 | AR5: 2060319 | AS5: 858 | AT5: 858 | AU5: 858 | AV5: 858 | AW5: 000858 | AX5: 无 | BA5: 1.0334 | BB5: 0 | BC5: 缺省券商 | BD5: 交易所业务 | BE5: 不是ETF补券指令 | BF5: 2,060,319.00 | BG5: 104.62 | BH5: 非强平 | BI5: 顾吟湫 | BJ5: 否 | BK5: 限价 | BM5: 0 | BN5: 0 | BO5: 股票 | BR5: 0 | BS5: 已成交
A6: 5 | B6: 2026-01-22 | C6: 3008 | D6: 自营权益4 | E6: 3008 | F6: 603198 | G6: 迎驾贡酒 | H6: 卖出 | I6: 38.84 | J6: 38.85 | K6: 60000 | L6: 2329000 | M6: 93 | N6: 38.79 | O6: 38.95 | P6: 38.816667 | Q6: 38.816667 | R6: 38.816667 | S6: 上交所A | T6: 3329948 | U6: 1.8018 | V6: 129356872 | W6: 300821 | X6: 自营权益4（场内） | Y6: 60000 | Z6: 39.05 | AA6: 38.7 | AB6: 18 | AC6: 叶盛 | AD6: 股票资产 | AE6: -0.308 | AF6: 1.8004 | AG6: -0.0767 | AH6: 60000 | AI6: 46 | AJ6: 自营权益4（场内） | AK6: 人民币 | AL6: 40878 | AN6: 30082 | AP6: 顾吟湫 | AQ6: 人民币 | AR6: 2329000 | AS6: 603198 | AT6: 603198 | AU6: 603198 | AV6: 603198 | AW6: 603198 | AX6: 无 | BA6: 1.1648 | BB6: 0 | BC6: 缺省券商 | BD6: 交易所业务 | BE6: 不是ETF补券指令 | BF6: 2,329,000.00 | BG6: 38.94 | BH6: 非强平 | BI6: 顾吟湫 | BJ6: 否 | BK6: 限价 | BM6: 0 | BN6: 46.25 | BO6: 股票 | BR6: 0 | BS6: 已成交
A7: 6 | B7: 2026-01-22 | C7: 3008 | D7: 自营权益4 | E7: 3008 | F7: 603369 | G7: 今世缘 | H7: 卖出 | I7: 33.91 | J7: 34.06 | K7: 60000 | L7: 2042778 | M7: 110 | N7: 34.04 | O7: 34.06 | P7: 34.0463 | Q7: 34.0463 | R7: 34.0463 | S7: 上交所A | T7: 7359607 | U7: 0.8153 | V7: 250690671 | W7: 300821 | X7: 自营权益4（场内） | Y7: 60000 | Z7: 34.31 | AA7: 33.88 | AB7: 7 | AC7: 叶盛 | AD7: 股票资产 | AE7: -0.9059 | AF7: 0.8149 | AG7: -0.0493 | AH7: 60000 | AI7: 46 | AJ7: 自营权益4（场内） | AK7: 人民币 | AL7: 40878 | AN7: 30082 | AP7: 顾吟湫 | AQ7: 人民币 | AR7: 2042778 | AS7: 603369 | AT7: 603369 | AU7: 603369 | AV7: 603369 | AW7: 603369 | AX7: 无 | BA7: 1.0217 | BB7: 0 | BC7: 缺省券商 | BD7: 交易所业务 | BE7: 不是ETF补券指令 | BF7: 2,042,778.00 | BG7: 34.2 | BH7: 非强平 | BI7: 顾吟湫 | BJ7: 否 | BK7: 限价 | BM7: 0 | BN7: 26.616667 | BO7: 股票 | BR7: 0 | BS7: 已成交
A8: 7 | B8: 2026-01-22 | C8: 3008 | D8: 自营权益4 | E8: 3008 | F8: 788 | G8: 中国铁塔 | H8: 买入 | I8: 11.46 | J8: 11.42 | K8: 300000 | L8: 3426200 | M8: 65 | N8: 11.4 | O8: 11.44 | P8: 11.420667 | Q8: 11.420667 | R8: 11.420667 | S8: 港股通（深） | T8: 11116072 | U8: 2.6988 | V8: 1.2690714e+08 | W8: 300841 | X8: 自营权益4（深港） | Y8: 300000 | Z8: 11.46 | AA8: 11.35 | AB8: 9 | AC8: 叶盛 | AD8: 股票资产 | AE8: 0.5263 | AF8: 2.6998 | AG8: -0.0368 | AH8: 300000 | AI8: 53 | AJ8: 自营权益4（深港） | AK8: 人民币 | AL8: 6111 | AN8: 30084 | AP8: 顾吟湫 | AQ8: 人民币 | AR8: 3058945.6 | AW8: CNE100006V65 | AX8: 无 | BA8: 1.5299 | BB8: 0 | BC8: 缺省券商 | BD8: 交易所业务 | BE8: 不是ETF补券指令 | BF8: -3,426,200.00 | BG8: 0 | BH8: 非强平 | BI8: 顾吟湫 | BJ8: 否 | BK8: 增强限价盘 | BM8: 0 | BN8: 61.383333 | BO8: 股票 | BR8: 0 | BS8: 已成交
A9: 8 | B9: 2026-01-23 | C9: 3008 | D9: 自营权益4 | E9: 3008 | F9: 788 | G9: 中国铁塔 | H9: 买入 | I9: 11.38 | J9: 11.38 | K9: 100000 | L9: 1137000 | M9: 26 | N9: 11.37 | O9: 11.37 | P9: 11.37 | Q9: 11.37 | R9: 11.37 | S9: 港股通（深） | T9: 9203678 | U9: 1.0865 | V9: 1.0476768e+08 | W9: 300841 | X9: 自营权益4（深港） | Y9: 100000 | Z9: 11.46 | AA9: 11.35 | AB9: 1 | AC9: 叶盛 | AD9: 股票资产 | AE9: -0.6981 | AF9: 1.0853 | AG9: 0.116 | AH9: 100000 | AI9: 53 | AJ9: 自营权益4（深港） | AK9: 人民币 | AL9: 6111 | AN9: 30084 | AP9: 顾吟湫 | AQ9: 人民币 | AR9: 1014897.6 | AW9: CNE100006V65 | AX9: 无 | BA9: 0.5178 | BB9: 0 | BC9: 缺省券商 | BD9: 交易所业务 | BE9: 不是ETF补券指令 | BF9: -1,137,000.00 | BG9: 0 | BH9: 非强平 | BI9: 顾吟湫 | BJ9: 否 | BK9: 增强限价盘 | BM9: 0 | BN9: 0 | BO9: 股票 | BR9: 0 | BS9: 已成交
A10: 9 | B10: 2026-01-26 | C10: 3008 | D10: 自营权益4 | E10: 3008 | F10: 600519 | G10: 贵州茅台 | H10: 卖出 | I10: 1342 | J10: 1341.12 | K10: 100 | L10: 134750 | M10: 1 | N10: 1347.5 | O10: 1347.5 | P10: 1347.5 | Q10: 1347.5 | R10: 1347.5 | S10: 上交所A | T10: 8016606 | U10: 0.0012 | V10: 10751225525 | W10: 300821 | X10: 自营权益4（场内） | Y10: 100 | Z10: 1355 | AA10: 1325.12 | AB10: 1 | AC10: 叶盛 | AD10: 股票资产 | AE10: 0.374 | AF10: 0.0013 | AG10: 0.4758 | AH10: 100 | AI10: 46 | AJ10: 自营权益4（场内） | AK10: 人民币 | AL10: 40878 | AN10: 30082 | AP10: 顾吟湫 | AQ10: 人民币 | AR10: 134750 | AS10: 600519 | AT10: 600519 | AU10: 600519 | AV10: 600519 | AW10: 600519 | AX10: 无 | BA10: 0.0688 | BB10: 0 | BC10: 缺省券商 | BD10: 交易所业务 | BE10: 不是ETF补券指令 | BF10: 134,750.00 | BG10: 1340.51 | BH10: 非强平 | BI10: 顾吟湫 | BJ10: 否 | BK10: 限价 | BM10: 0 | BN10: 0.016666667 | BO10: 股票 | BR10: 0 | BS10: 已成交
A11: 10 | B11: 2026-01-26 | C11: 3008 | D11: 自营权益4 | E11: 3008 | F11: 322 | G11: 康师傅控股 | H11: 买入 | I11: 11.64 | J11: 11.7 | K11: 50000 | L11: 577500 | M11: 19 | N11: 11.55 | O11: 11.55 | P11: 11.55 | Q11: 11.55 | R11: 11.55 | S11: 港股通（深） | T11: 18004148 | U11: 0.2777 | V11: 2.1064094e+08 | W11: 300841 | X11: 自营权益4（深港） | Y11: 50000 | Z11: 12.4 | AA11: 11.5 | AB11: 1 | AC11: 叶盛 | AD11: 股票资产 | AE11: -4.5902 | AF11: 0.2742 | AG11: 1.2787 | AH11: 50000 | AI11: 53 | AJ11: 自营权益4（深港） | AK11: 人民币 | AL11: 6111 | AN11: 30084 | AP11: 顾吟湫 | AQ11: 人民币 | AR11: 515545.76 | AW11: KYG8878S1030 | AX11: 无 | BA11: 0.263 | BB11: 0 | BC11: 缺省券商 | BD11: 交易所业务 | BE11: 不是ETF补券指令 | BF11: -577,500.00 | BG11: 0 | BH11: 非强平 | BI11: 顾吟湫 | BJ11: 否 | BK11: 增强限价盘 | BM11: 0 | BN11: 4.4166667 | BO11: 股票 | BR11: 0 | BS11: 已成交
A12: 11 | B12: 2026-01-26 | C12: 3008 | D12: 自营权益4 | E12: 3008 | F12: 2607 | G12: 上海医药 | H12: 卖出 | I12: 12.12 | J12: 12.06 | K12: 100000 | L12: 1206000 | M12: 13 | N12: 12.05 | O12: 12.07 | P12: 12.06 | Q12: 12.06 | R12: 12.06 | S12: 港股通（深） | T12: 2259945 | U12: 4.4249 | V12: 27259166 | W12: 300841 | X12: 自营权益4（深港） | Y12: 100000 | Z12: 12.12 | AA12: 11.94 | AB12: 3 | AC12: 叶盛 | AD12: 股票资产 | AE12: 1.1686 | AF12: 4.4242 | AG12: -0.0158 | AH12: 100000 | AI12: 53 | AJ12: 自营权益4（深港） | AK12: 人民币 | AL12: 6111 | AN12: 30084 | AP12: 顾吟湫 | AQ12: 人民币 | AR12: 1076572.1 | AW12: CNE1000012B3 | AX12: 无 | BA12: 0.5493 | BB12: 0 | BC12: 缺省券商 | BD12: 交易所业务 | BE12: 不是ETF补券指令 | BF12: 1,206,000.00 | BG12: 0 | BH12: 非强平 | BI12: 顾吟湫 | BJ12: 否 | BK12: 增强限价盘 | BM12: 0 | BN12: 2.0833333 | BO12: 股票 | BR12: 0 | BS12: 已成交
A13: 12 | B13: 2026-01-27 | C13: 3008 | D13: 自营权益4 | E13: 3008 | F13: 2318 | G13: 中国平安 | H13: 卖出 | I13: 69.7 | J13: 69.48 | K13: 10000 | L13: 689500 | M13: 4 | N13: 68.95 | O13: 68.95 | P13: 68.95 | Q13: 68.95 | R13: 68.95 | S13: 港股通（深） | T13: 47392544 | U13: 0.0211 | V13: 3.2928292e+09 | W13: 300841 | X13: 自营权益4（深港） | Y13: 10000 | Z13: 70.05 | AA13: 67.9 | AB13: 2 | AC13: 叶盛 | AD13: 股票资产 | AE13: 2.3495 | AF13: 0.0209 | AG13: -0.7627 | AH13: 10000 | AI13: 53 | AJ13: 自营权益4（深港） | AK13: 人民币 | AL13: 6111 | AN13: 30084 | AP13: 顾吟湫 | AQ13: 人民币 | AR13: 615034 | AW13: CNE1000003X6 | AX13: 无 | BA13: 0.3138 | BB13: 0 | BC13: 缺省券商 | BD13: 交易所业务 | BE13: 不是ETF补券指令 | BF13: 689,500.00 | BG13: 0 | BH13: 非强平 | BI13: 顾吟湫 | BJ13: 否 | BK13: 增强限价盘 | BM13: 0 | BN13: 0.066666667 | BO13: 股票 | BR13: 0 | BS13: 已成交
A14: 13 | B14: 2026-01-28 | C14: 3008 | D14: 自营权益4 | E14: 3008 | F14: 600036 | G14: 招商银行 | H14: 买入 | I14: 37.8 | J14: 38 | K14: 28100 | L14: 1070084 | M14: 8 | N14: 38.03 | O14: 38.14 | P14: 38.081281 | Q14: 38.081281 | R14: 38.081281 | S14: 上交所A | T14: 204166688 | U14: 0.0138 | V14: 7757392685 | W14: 300821 | X14: 自营权益4（场内） | Y14: 28100 | Z14: 38.44 | AA14: 37.7 | AB14: 2 | AC14: 叶盛 | AD14: 股票资产 | AE14: -0.7874 | AF14: 0.0138 | AG14: -0.2261 | AH14: 28100 | AI14: 46 | AJ14: 自营权益4（场内） | AK14: 人民币 | AL14: 40878 | AN14: 30082 | AP14: 顾吟湫 | AQ14: 人民币 | AR14: 1070084 | AS14: 600036 | AT14: 600036 | AU14: 600036 | AV14: 600036 | AW14: 600036 | AX14: 无 | BA14: 0.5342 | BB14: 0 | BC14: 缺省券商 | BD14: 交易所业务 | BE14: 不是ETF补券指令 | BF14: -1,070,084.00 | BG14: 38.12 | BH14: 非强平 | BI14: 顾吟湫 | BJ14: 否 | BK14: 限价 | BM14: 0 | BN14: 0.083333333 | BO14: 股票 | BR14: 0 | BS14: 已成交
A15: 14 | B15: 2026-01-28 | C15: 3008 | D15: 自营权益4 | E15: 3008 | F15: 601166 | G15: 兴业银行 | H15: 买入 | I15: 18.55 | J15: 18.67 | K15: 50100 | L15: 934330 | M15: 33 | N15: 18.64 | O15: 18.66 | P15: 18.649301 | Q15: 18.649301 | R15: 18.649301 | S15: 上交所A | T15: 204522726 | U15: 0.0245 | V15: 3817641687 | W15: 300821 | X15: 自营权益4（场内） | Y15: 50100 | Z15: 18.89 | AA15: 18.51 | AB15: 3 | AC15: 叶盛 | AD15: 股票资产 | AE15: -1.4346 | AF15: 0.0245 | AG15: 0.09 | AH15: 50100 | AI15: 46 | AJ15: 自营权益4（场内） | AK15: 人民币 | AL15: 40878 | AN15: 30082 | AP15: 顾吟湫 | AQ15: 人民币 | AR15: 934330 | AS15: 601166 | AT15: 601166 | AU15: 601166 | AV15: 601166 | AW15: 601166 | AX15: 无 | BA15: 0.4665 | BB15: 0 | BC15: 缺省券商 | BD15: 交易所业务 | BE15: 不是ETF补券指令 | BF15: -934,330.00 | BG15: 18.81 | BH15: 非强平 | BI15: 顾吟湫 | BJ15: 否 | BK15: 限价 | BM15: 0 | BN15: 2.0333333 | BO15: 股票 | BR15: 0 | BS15: 已成交
A16: 15 | B16: 2026-02-05 | C16: 3008 | D16: 自营权益4 | E16: 3008 | F16: 600036 | G16: 招商银行 | H16: 买入 | I16: 39.71 | J16: 39.46 | K16: 21900 | L16: 860633 | M16: 34 | N16: 38.97 | O16: 39.33 | P16: 39.298311 | Q16: 39.298311 | R16: 39.298311 | S16: 上交所A | T16: 121889452 | U16: 0.018 | V16: 4810048757 | W16: 300821 | X16: 自营权益4（场内） | Y16: 21900 | Z16: 39.92 | AA16: 38.91 | AB16: 3 | AC16: 叶盛 | AD16: 股票资产 | AE16: 1.7944 | AF16: 0.0179 | AG16: 0.4158 | AH16: 21900 | AI16: 46 | AJ16: 自营权益4（场内） | AK16: 人民币 | AL16: 40878 | AN16: 30082 | AP16: 顾吟湫 | AQ16: 人民币 | AR16: 860633 | AS16: 600036 | AT16: 600036 | AU16: 600036 | AV16: 600036 | AW16: 600036 | AX16: 无 | BA16: 0.4241 | BB16: 0 | BC16: 缺省券商 | BD16: 交易所业务 | BE16: 不是ETF补券指令 | BF16: -860,633.00 | BG16: 38.94 | BH16: 非强平 | BI16: 顾吟湫 | BJ16: 否 | BK16: 限价 | BM16: 0 | BN16: 11.766667 | BO16: 股票 | BR16: 0 | BS16: 已成交
A17: 16 | B17: 2026-02-05 | C17: 3008 | D17: 自营权益4 | E17: 3008 | F17: 601166 | G17: 兴业银行 | H17: 买入 | I17: 19.38 | J17: 19.34 | K17: 49900 | L17: 961478 | M17: 46 | N17: 19.22 | O17: 19.28 | P17: 19.268096 | Q17: 19.268096 | R17: 19.268096 | S17: 上交所A | T17: 119848229 | U17: 0.0416 | V17: 2318435836 | W17: 300821 | X17: 自营权益4（场内） | Y17: 49900 | Z17: 19.49 | AA17: 19.2 | AB17: 2 | AC17: 叶盛 | AD17: 股票资产 | AE17: 1.0428 | AF17: 0.0415 | AG17: 0.3965 | AH17: 49900 | AI17: 46 | AJ17: 自营权益4（场内） | AK17: 人民币 | AL17: 40878 | AN17: 30082 | AP17: 顾吟湫 | AQ17: 人民币 | AR17: 961478 | AS17: 601166 | AT17: 601166 | AU17: 601166 | AV17: 601166 | AW17: 601166 | AX17: 无 | BA17: 0.4738 | BB17: 0 | BC17: 缺省券商 | BD17: 交易所业务 | BE17: 不是ETF补券指令 | BF17: -961,478.00 | BG17: 19.2 | BH17: 非强平 | BI17: 顾吟湫 | BJ17: 否 | BK17: 限价 | BM17: 0 | BN17: 2.1 | BO17: 股票 | BR17: 0 | BS17: 已成交
A18: 17 | B18: 2026-02-09 | C18: 3008 | D18: 自营权益4 | E18: 3008 | F18: 600036 | G18: 招商银行 | H18: 买入 | I18: 39.48 | J18: 39.48 | K18: 40000 | L18: 1576800 | M18: 41 | N18: 39.42 | O18: 39.42 | P18: 39.42 | Q18: 39.42 | R18: 39.42 | S18: 上交所A | T18: 65894891 | U18: 0.0607 | V18: 2601539089 | W18: 300821 | X18: 自营权益4（场内） | Y18: 40000 | Z18: 39.74 | AA18: 39.33 | AB18: 1 | AC18: 叶盛 | AD18: 股票资产 | AE18: -0.303 | AF18: 0.0606 | AG18: 0.1522 | AH18: 40000 | AI18: 46 | AJ18: 自营权益4（场内） | AK18: 人民币 | AL18: 40878 | AN18: 30082 | AP18: 顾吟湫 | AQ18: 人民币 | AR18: 1576800 | AS18: 600036 | AT18: 600036 | AU18: 600036 | AV18: 600036 | AW18: 600036 | AX18: 无 | BA18: 0.7781 | BB18: 0 | BC18: 缺省券商 | BD18: 交易所业务 | BE18: 不是ETF补券指令 | BF18: -1,576,800.00 | BG18: 39.6 | BH18: 非强平 | BI18: 顾吟湫 | BJ18: 否 | BK18: 限价 | BM18: 0 | BN18: 42.533333 | BO18: 股票 | BR18: 0 | BS18: 已成交
A19: 18 | B19: 2026-02-09 | C19: 3008 | D19: 自营权益4 | E19: 3008 | F19: 601009 | G19: 南京银行 | H19: 卖出 | I19: 11.26 | J19: 11.2 | K19: 300000 | L19: 3372000 | M19: 23 | N19: 11.24 | O19: 11.24 | P19: 11.24 | Q19: 11.24 | R19: 11.24 | S19: 上交所A | T19: 52474996 | U19: 0.5717 | V19: 587653443 | W19: 300821 | X19: 自营权益4（场内） | Y19: 300000 | Z19: 11.29 | AA19: 11.05 | AB19: 1 | AC19: 叶盛 | AD19: 股票资产 | AE19: 0.9865 | AF19: 0.5738 | AG19: 0.3688 | AH19: 300000 | AI19: 46 | AJ19: 自营权益4（场内） | AK19: 人民币 | AL19: 40878 | AN19: 30082 | AP19: 顾吟湫 | AQ19: 人民币 | AR19: 3372000 | AS19: 601009 | AT19: 601009 | AU19: 601009 | AV19: 601009 | AW19: 601009 | AX19: 无 | BA19: 1.6639 | BB19: 0 | BC19: 缺省券商 | BD19: 交易所业务 | BE19: 不是ETF补券指令 | BF19: 3,372,000.00 | BG19: 11.1 | BH19: 非强平 | BI19: 顾吟湫 | BJ19: 否 | BK19: 限价 | BM19: 0 | BN19: 0.38333333 | BO19: 股票 | BR19: 0 | BS19: 已成交
A20: 19 | B20: 2026-02-09 | C20: 3008 | D20: 自营权益4 | E20: 3008 | F20: 601166 | G20: 兴业银行 | H20: 买入 | I20: 18.88 | J20: 18.86 | K20: 90000 | L20: 1699200 | M20: 149 | N20: 18.88 | O20: 18.88 | P20: 18.88 | Q20: 18.88 | R20: 18.88 | S20: 上交所A | T20: 64439529 | U20: 0.1397 | V20: 1215569554 | W20: 300821 | X20: 自营权益4（场内） | Y20: 90000 | Z20: 18.97 | AA20: 18.76 | AB20: 1 | AC20: 叶盛 | AD20: 股票资产 | AE20: 0.1592 | AF20: 0.1398 | AG20: -0.0864 | AH20: 90000 | AI20: 46 | AJ20: 自营权益4（场内） | AK20: 人民币 | AL20: 40878 | AN20: 30082 | AP20: 顾吟湫 | AQ20: 人民币 | AR20: 1699200 | AS20: 601166 | AT20: 601166 | AU20: 601166 | AV20: 601166 | AW20: 601166 | AX20: 无 | BA20: 0.8385 | BB20: 0 | BC20: 缺省券商 | BD20: 交易所业务 | BE20: 不是ETF补券指令 | BF20: -1,699,200.00 | BG20: 18.85 | BH20: 非强平 | BI20: 顾吟湫 | BJ20: 否 | BK20: 限价 | BM20: 0 | BN20: 2.0833333 | BO20: 股票 | BR20: 0 | BS20: 已成交
A21: 20 | B21: 2026-02-09 | C21: 3008 | D21: 自营权益4 | E21: 3008 | F21: 2319 | G21: 蒙牛乳业 | H21: 卖出 | I21: 17.47 | J21: 17.62 | K21: 10000 | L21: 175400 | M21: 1 | N21: 17.54 | O21: 17.54 | P21: 17.54 | Q21: 17.54 | R21: 17.54 | S21: 港股通（深） | T21: 36756086 | U21: 0.0272 | V21: 6.4764329e+08 | W21: 300841 | X21: 自营权益4（深港） | Y21: 10000 | Z21: 17.88 | AA21: 17.45 | AB21: 1 | AC21: 叶盛 | AD21: 股票资产 | AE21: -1.1319 | AF21: 0.0271 | AG21: -0.454 | AH21: 10000 | AI21: 53 | AJ21: 自营权益4（深港） | AK21: 人民币 | AL21: 6111 | AN21: 30084 | AP21: 顾吟湫 | AQ21: 人民币 | AR21: 155786.77 | AW21: KYG210961051 | AX21: 无 | BA21: 0.0769 | BB21: 0 | BC21: 缺省券商 | BD21: 交易所业务 | BE21: 不是ETF补券指令 | BF21: 175,400.00 | BG21: 0 | BH21: 非强平 | BI21: 顾吟湫 | BJ21: 否 | BK21: 增强限价盘 | BM21: 0 | BN21: 0.76666667 | BO21: 股票 | BR21: 0 | BS21: 已成交
A22: 21 | B22: 2026-02-09 | C22: 3008 | D22: 自营权益4 | E22: 3008 | F22: 3988 | G22: 中国银行 | H22: 卖出 | I22: 4.7 | J22: 4.69 | K22: 100000 | L22: 469000 | M22: 2 | N22: 4.69 | O22: 4.69 | P22: 4.69 | Q22: 4.69 | R22: 4.69 | S22: 港股通（深） | T22: 125338863 | U22: 0.0798 | V22: 5.8794872e+08 | W22: 300841 | X22: 自营权益4（深港） | Y22: 100000 | Z22: 4.73 | AA22: 4.66 | AB22: 1 | AC22: 叶盛 | AD22: 股票资产 | AE22: 0.8584 | AF22: 0.0798 | AG22: -0.0192 | AH22: 100000 | AI22: 53 | AJ22: 自营权益4（深港） | AK22: 人民币 | AL22: 6111 | AN22: 30084 | AP22: 顾吟湫 | AQ22: 人民币 | AR22: 416556.42 | AW22: CNE1000001Z5 | AX22: 无 | BA22: 0.2056 | BB22: 0 | BC22: 缺省券商 | BD22: 交易所业务 | BE22: 不是ETF补券指令 | BF22: 469,000.00 | BG22: 0 | BH22: 非强平 | BI22: 顾吟湫 | BJ22: 否 | BK22: 增强限价盘 | BM22: 0 | BN22: 20.133333 | BO22: 股票 | BR22: 0 | BS22: 已成交
A23: 22 | B23: 2026-02-10 | C23: 3008 | D23: 自营权益4 | E23: 3008 | F23: 600809 | G23: 山西汾酒 | H23: 卖出 | I23: 170.28 | J23: 170.77 | K23: 9000 | L23: 1532820 | M23: 41 | N23: 170.3 | O23: 170.34 | P23: 170.31333 | Q23: 170.31333 | R23: 170.31333 | S23: 上交所A | T23: 6789052 | U23: 0.1326 | V23: 1159371222 | W23: 300821 | X23: 自营权益4（场内） | Y23: 9000 | Z23: 174.12 | AA23: 169.61 | AB23: 2 | AC23: 叶盛 | AD23: 股票资产 | AE23: -2.5301 | AF23: 0.1322 | AG23: -0.2678 | AH23: 9000 | AI23: 46 | AJ23: 自营权益4（场内） | AK23: 人民币 | AL23: 40878 | AN23: 30082 | AP23: 顾吟湫 | AQ23: 人民币 | AR23: 1532820 | AS23: 600809 | AT23: 600809 | AU23: 600809 | AV23: 600809 | AW23: 600809 | AX23: 无 | BA23: 0.7542 | BB23: 0 | BC23: 缺省券商 | BD23: 交易所业务 | BE23: 不是ETF补券指令 | BF23: 1,532,820.00 | BG23: 174 | BH23: 非强平 | BI23: 顾吟湫 | BJ23: 否 | BK23: 限价 | BM23: 0 | BN23: 8.6333333 | BO23: 股票 | BR23: 0 | BS23: 已成交
A24: 23 | B24: 2026-02-10 | C24: 3008 | D24: 自营权益4 | E24: 3008 | F24: 600887 | G24: 伊利股份 | H24: 买入 | I24: 26.75 | J24: 26.75 | K24: 20000 | L24: 535200 | M24: 5 | N24: 26.76 | O24: 26.76 | P24: 26.76 | Q24: 26.76 | R24: 26.76 | S24: 上交所A | T24: 56476485 | U24: 0.0354 | V24: 1510541822 | W24: 300821 | X24: 自营权益4（场内） | Y24: 20000 | Z24: 27.03 | AA24: 26.64 | AB24: 1 | AC24: 叶盛 | AD24: 股票资产 | AE24: -1.2186 | AF24: 0.0354 | AG24: -0.0508 | AH24: 20000 | AI24: 46 | AJ24: 自营权益4（场内） | AK24: 人民币 | AL24: 40878 | AN24: 30082 | AP24: 顾吟湫 | AQ24: 人民币 | AR24: 535200 | AS24: 600887 | AT24: 600887 | AU24: 600887 | AV24: 600887 | AW24: 600887 | AX24: 无 | BA24: 0.2633 | BB24: 0 | BC24: 缺省券商 | BD24: 交易所业务 | BE24: 不是ETF补券指令 | BF24: -535,200.00 | BG24: 27.03 | BH24: 非强平 | BI24: 顾吟湫 | BJ24: 否 | BK24: 限价 | BM24: 0 | BN24: 0 | BO24: 股票 | BR24: 0 | BS24: 已成交
A25: 24 | B25: 2026-02-10 | C25: 3008 | D25: 自营权益4 | E25: 3008 | F25: 600919 | G25: 江苏银行 | H25: 买入 | I25: 10.48 | J25: 10.48 | K25: 150000 | L25: 1572000 | M25: 108 | N25: 10.48 | O25: 10.48 | P25: 10.48 | Q25: 10.48 | R25: 10.48 | S25: 上交所A | T25: 66595470 | U25: 0.2252 | V25: 698017694 | W25: 300821 | X25: 自营权益4（场内） | Y25: 150000 | Z25: 10.54 | AA25: 10.43 | AB25: 2 | AC25: 叶盛 | AD25: 股票资产 | AE25: 0.4794 | AF25: 0.2252 | AG25: 0.0143 | AH25: 150000 | AI25: 46 | AJ25: 自营权益4（场内） | AK25: 人民币 | AL25: 40878 | AN25: 30082 | AP25: 顾吟湫 | AQ25: 人民币 | AR25: 1572000 | AX25: 无 | BA25: 0.7734 | BB25: 0 | BC25: 缺省券商 | BD25: 交易所业务 | BE25: 不是ETF补券指令 | BF25: -1,572,000.00 | BG25: 10.43 | BH25: 非强平 | BI25: 顾吟湫 | BJ25: 否 | BK25: 限价 | BM25: 0 | BN25: 0 | BO25: 股票 | BR25: 0 | BS25: 已成交
A26: 25 | B26: 2026-02-10 | C26: 3008 | D26: 自营权益4 | E26: 3008 | F26: 601166 | G26: 兴业银行 | H26: 买入 | I26: 18.82 | J26: 18.86 | K26: 10000 | L26: 188250 | M26: 2 | N26: 18.82 | O26: 18.83 | P26: 18.825 | Q26: 18.825 | R26: 18.825 | S26: 上交所A | T26: 51870605 | U26: 0.0193 | V26: 978050860 | W26: 300821 | X26: 自营权益4（场内） | Y26: 10000 | Z26: 18.96 | AA26: 18.8 | AB26: 2 | AC26: 叶盛 | AD26: 股票资产 | AE26: -0.3178 | AF26: 0.0192 | AG26: 0.1623 | AH26: 10000 | AI26: 46 | AJ26: 自营权益4（场内） | AK26: 人民币 | AL26: 40878 | AN26: 30082 | AP26: 顾吟湫 | AQ26: 人民币 | AR26: 188250 | AS26: 601166 | AT26: 601166 | AU26: 601166 | AV26: 601166 | AW26: 601166 | AX26: 无 | BA26: 0.0926 | BB26: 0 | BC26: 缺省券商 | BD26: 交易所业务 | BE26: 不是ETF补券指令 | BF26: -188,250.00 | BG26: 18.88 | BH26: 非强平 | BI26: 顾吟湫 | BJ26: 否 | BK26: 限价 | BM26: 0 | BN26: 1.7833333 | BO26: 股票 | BR26: 0 | BS26: 已成交
A27: 26 | B27: 2026-02-10 | C27: 3008 | D27: 自营权益4 | E27: 3008 | F27: 601825 | G27: 沪农商行 | H27: 买入 | I27: 8.64 | J27: 8.62 | K27: 120000 | L27: 1035600 | M27: 76 | N27: 8.63 | O27: 8.63 | P27: 8.63 | Q27: 8.63 | R27: 8.63 | S27: 上交所A | T27: 15048230 | U27: 0.7974 | V27: 129756751 | W27: 300821 | X27: 自营权益4（场内） | Y27: 120000 | Z27: 8.66 | AA27: 8.56 | AB27: 2 | AC27: 叶盛 | AD27: 股票资产 | AE27: 0.6993 | AF27: 0.7981 | AG27: -0.0847 | AH27: 120000 | AI27: 46 | AJ27: 自营权益4（场内） | AK27: 人民币 | AL27: 40878 | AN27: 30082 | AP27: 顾吟湫 | AQ27: 人民币 | AR27: 1035600 | AX27: 无 | BA27: 0.5095 | BB27: 0 | BC27: 缺省券商 | BD27: 交易所业务 | BE27: 不是ETF补券指令 | BF27: -1,035,600.00 | BG27: 8.6 | BH27: 非强平 | BI27: 顾吟湫 | BJ27: 否 | BK27: 限价 | BM27: 0 | BN27: 180.08333 | BO27: 股票 | BR27: 0 | BS27: 已成交
A28: 27 | B28: 2026-02-10 | C28: 3008 | D28: 自营权益4 | E28: 3008 | F28: 568 | G28: 泸州老窖 | H28: 卖出 | I28: 118.19 | J28: 118.35 | K28: 15000 | L28: 1769314 | M28: 38 | N28: 117.95 | O28: 118.03 | P28: 117.95427 | Q28: 117.95427 | R28: 117.95427 | S28: 深交所A | T28: 12866212 | U28: 0.1166 | V28: 1.5226833e+09 | W28: 300821 | X28: 自营权益4（场内） | Y28: 15000 | Z28: 121 | AA28: 117.6 | AB28: 2 | AC28: 叶盛 | AD28: 股票资产 | AE28: -2.5559 | AF28: 0.1162 | AG28: -0.3322 | AH28: 15000 | AI28: 46 | AJ28: 自营权益4（场内） | AK28: 人民币 | AL28: 6111 | AN28: 30082 | AP28: 顾吟湫 | AQ28: 人民币 | AR28: 1769314 | AS28: 568 | AT28: 568 | AU28: 568 | AV28: 568 | AW28: 000568 | AX28: 无 | BA28: 0.8705 | BB28: 0 | BC28: 缺省券商 | BD28: 交易所业务 | BE28: 不是ETF补券指令 | BF28: 1,769,314.00 | BG28: 121 | BH28: 非强平 | BI28: 顾吟湫 | BJ28: 否 | BK28: 限价 | BM28: 0 | BN28: 30.483333 | BO28: 股票 | BR28: 0 | BS28: 已成交
A29: 28 | B29: 2026-02-11 | C29: 3008 | D29: 自营权益4 | E29: 3008 | F29: 600036 | G29: 招商银行 | H29: 买入 | I29: 39.4 | J29: 39.34 | K29: 10000 | L29: 393353 | M29: 5 | N29: 39.33 | O29: 39.34 | P29: 39.3353 | Q29: 39.3353 | R29: 39.3353 | S29: 上交所A | T29: 52881696 | U29: 0.0189 | V29: 2080370293 | W29: 300821 | X29: 自营权益4（场内） | Y29: 10000 | Z29: 39.45 | AA29: 39.2 | AB29: 1 | AC29: 叶盛 | AD29: 股票资产 | AE29: 0.1525 | AF29: 0.0189 | AG29: 0.0122 | AH29: 10000 | AI29: 46 | AJ29: 自营权益4（场内） | AK29: 人民币 | AL29: 40878 | AN29: 30082 | AP29: 顾吟湫 | AQ29: 人民币 | AR29: 393353 | AS29: 600036 | AT29: 600036 | AU29: 600036 | AV29: 600036 | AW29: 600036 | AX29: 无 | BA29: 0.1927 | BB29: 0 | BC29: 缺省券商 | BD29: 交易所业务 | BE29: 不是ETF补券指令 | BF29: -393,353.00 | BG29: 39.36 | BH29: 非强平 | BI29: 顾吟湫 | BJ29: 否 | BK29: 限价 | BM29: 0 | BN29: 0 | BO29: 股票 | BR29: 0 | BS29: 已成交
A30: 29 | B30: 2026-02-12 | C30: 3008 | D30: 自营权益4 | E30: 3008 | F30: 600809 | G30: 山西汾酒 | H30: 卖出 | I30: 166.31 | J30: 166.8 | K30: 7000 | L30: 1177820 | M30: 3 | N30: 168.26 | O30: 168.26 | P30: 168.26 | Q30: 168.26 | R30: 168.26 | S30: 上交所A | T30: 5856835 | U30: 0.1195 | V30: 976918471 | W30: 300821 | X30: 自营权益4（场内） | Y30: 7000 | Z30: 169.18 | AA30: 165.82 | AB30: 2 | AC30: 叶盛 | AD30: 股票资产 | AE30: -1.9745 | AF30: 0.1206 | AG30: 0.8755 | AH30: 7000 | AI30: 46 | AJ30: 自营权益4（场内） | AK30: 人民币 | AL30: 40878 | AN30: 30082 | AP30: 顾吟湫 | AQ30: 人民币 | AR30: 1177820 | AS30: 600809 | AT30: 600809 | AU30: 600809 | AV30: 600809 | AW30: 600809 | AX30: 无 | BA30: 0.5844 | BB30: 0 | BC30: 缺省券商 | BD30: 交易所业务 | BE30: 不是ETF补券指令 | BF30: 1,177,820.00 | BG30: 168.5 | BH30: 非强平 | BI30: 顾吟湫 | BJ30: 否 | BK30: 限价 | BM30: 0 | BN30: 0.13333333 | BO30: 股票 | BR30: 0 | BS30: 已成交
A31: 30 | B31: 2026-02-12 | C31: 3008 | D31: 自营权益4 | E31: 3008 | F31: 568 | G31: 泸州老窖 | H31: 卖出 | I31: 115.62 | J31: 116.15 | K31: 10000 | L31: 1171300 | M31: 8 | N31: 117.13 | O31: 117.13 | P31: 117.13 | Q31: 117.13 | R31: 117.13 | S31: 深交所A | T31: 9332215 | U31: 0.1072 | V31: 1.0839812e+09 | W31: 300821 | X31: 自营权益4（场内） | Y31: 10000 | Z31: 117.94 | AA31: 115.57 | AB31: 2 | AC31: 叶盛 | AD31: 股票资产 | AE31: -1.9671 | AF31: 0.1081 | AG31: 0.8396 | AH31: 10000 | AI31: 46 | AJ31: 自营权益4（场内） | AK31: 人民币 | AL31: 6111 | AN31: 30082 | AP31: 顾吟湫 | AQ31: 人民币 | AR31: 1171300 | AS31: 568 | AT31: 568 | AU31: 568 | AV31: 568 | AW31: 000568 | AX31: 无 | BA31: 0.5812 | BB31: 0 | BC31: 缺省券商 | BD31: 交易所业务 | BE31: 不是ETF补券指令 | BF31: 1,171,300.00 | BG31: 117.55 | BH31: 非强平 | BI31: 顾吟湫 | BJ31: 否 | BK31: 限价 | BM31: 0 | BN31: 0.15 | BO31: 股票 | BR31: 0 | BS31: 已成交
A32: 31 | B32: 2026-02-24 | C32: 3008 | D32: 自营权益4 | E32: 3008 | F32: 600919 | G32: 江苏银行 | H32: 买入 | I32: 10.32 | J32: 10.38 | K32: 30000 | L32: 311700 | M32: 26 | N32: 10.39 | O32: 10.39 | P32: 10.39 | Q32: 10.39 | R32: 10.39 | S32: 上交所A | T32: 76468662 | U32: 0.0392 | V32: 793715267 | W32: 300821 | X32: 自营权益4（场内） | Y32: 30000 | Z32: 10.48 | AA32: 10.32 | AB32: 1 | AC32: 叶盛 | AD32: 股票资产 | AE32: -0.6737 | AF32: 0.0393 | AG32: -0.1002 | AH32: 30000 | AI32: 46 | AJ32: 自营权益4（场内） | AK32: 人民币 | AL32: 40878 | AN32: 30082 | AP32: 顾吟湫 | AQ32: 人民币 | AR32: 311700 | AX32: 无 | BA32: 0.1547 | BB32: 0 | BC32: 缺省券商 | BD32: 交易所业务 | BE32: 不是ETF补券指令 | BF32: -311,700.00 | BG32: 10.43 | BH32: 非强平 | BI32: 顾吟湫 | BJ32: 否 | BK32: 限价 | BM32: 0 | BN32: 5.8166667 | BO32: 股票 | BR32: 0 | BS32: 已成交
A33: 32 | B33: 2026-02-24 | C33: 3008 | D33: 自营权益4 | E33: 3008 | F33: 601825 | G33: 沪农商行 | H33: 买入 | I33: 8.44 | J33: 8.47 | K33: 30000 | L33: 253800 | M33: 27 | N33: 8.46 | O33: 8.46 | P33: 8.46 | Q33: 8.46 | R33: 8.46 | S33: 上交所A | T33: 12886600 | U33: 0.2328 | V33: 109120584 | W33: 300821 | X33: 自营权益4（场内） | Y33: 30000 | Z33: 8.55 | AA33: 8.43 | AB33: 1 | AC33: 叶盛 | AD33: 股票资产 | AE33: -0.4717 | AF33: 0.2326 | AG33: 0.0921 | AH33: 30000 | AI33: 46 | AJ33: 自营权益4（场内） | AK33: 人民币 | AL33: 40878 | AN33: 30082 | AP33: 顾吟湫 | AQ33: 人民币 | AR33: 253800 | AX33: 无 | BA33: 0.126 | BB33: 0 | BC33: 缺省券商 | BD33: 交易所业务 | BE33: 不是ETF补券指令 | BF33: -253,800.00 | BG33: 8.47 | BH33: 非强平 | BI33: 顾吟湫 | BJ33: 否 | BK33: 限价 | BM33: 0 | BN33: 41.666667 | BO33: 股票 | BR33: 0 | BS33: 已成交
A34: 33 | B34: 2026-02-24 | C34: 3008 | D34: 自营权益4 | E34: 3008 | F34: 333 | G34: 美的集团 | H34: 买入 | I34: 79.52 | J34: 80 | K34: 30000 | L34: 2404500 | M34: 38 | N34: 80.15 | O34: 80.15 | P34: 80.15 | Q34: 80.15 | R34: 80.15 | S34: 深交所A | T34: 25251393 | U34: 0.1188 | V34: 2.0201032e+09 | W34: 300821 | X34: 自营权益4（场内） | Y34: 30000 | Z34: 80.6 | AA34: 79.52 | AB34: 1 | AC34: 叶盛 | AD34: 股票资产 | AE34: 0.5946 | AF34: 0.119 | AG34: -0.1879 | AH34: 30000 | AI34: 46 | AJ34: 自营权益4（场内） | AK34: 人民币 | AL34: 6111 | AN34: 30082 | AP34: 顾吟湫 | AQ34: 人民币 | AR34: 2404500 | AS34: 333 | AT34: 333 | AU34: 333 | AV34: 333 | AW34: 000333 | AX34: 无 | BA34: 1.1938 | BB34: 0 | BC34: 缺省券商 | BD34: 交易所业务 | BE34: 不是ETF补券指令 | BF34: -2,404,500.00 | BG34: 80.2 | BH34: 非强平 | BI34: 顾吟湫 | BJ34: 否 | BK34: 限价 | BM34: 0 | BN34: 8.1333333 | BO34: 股票 | BR34: 0 | BS34: 已成交
A35: 34 | B35: 2026-02-24 | C35: 3008 | D35: 自营权益4 | E35: 3008 | F35: 300 | G35: 美的集团 | H35: 卖出 | I35: 92.25 | J35: 92.18 | K35: 50000 | L35: 4610000 | M35: 12 | N35: 92.05 | O35: 92.35 | P35: 92.2 | Q35: 92.2 | R35: 92.2 | S35: 港股通（深） | T35: 2980600 | U35: 1.6775 | V35: 2.7474805e+08 | W35: 300841 | X35: 自营权益4（深港） | Y35: 70000 | Z35: 93.5 | AA35: 91.5 | AB35: 5 | AC35: 叶盛 | AD35: 股票资产 | AE35: -1.3369 | AF35: 1.6779 | AG35: 0.023 | AH35: 70000 | AI35: 53 | AJ35: 自营权益4（深港） | AK35: 人民币 | AL35: 6111 | AN35: 30084 | AP35: 顾吟湫 | AQ35: 人民币 | AR35: 4059658.2 | AW35: CNE100006M58 | AX35: 无 | BA35: 2.0155 | BB35: 0 | BC35: 缺省券商 | BD35: 交易所业务 | BE35: 不是ETF补券指令 | BF35: 4,610,000.00 | BG35: 0 | BH35: 非强平 | BI35: 顾吟湫 | BJ35: 否 | BK35: 增强限价盘 | BM35: 0 | BN35: 5.55 | BO35: 股票 | BR35: 0 | BS35: 已成交
A36: 35 | B36: 2026-02-24 | C36: 3008 | D36: 自营权益4 | E36: 3008 | F36: 728 | G36: 中国电信 | H36: 买入 | I36: 4.96 | J36: 4.97 | K36: 200000 | L36: 996000 | M36: 20 | N36: 4.98 | O36: 4.98 | P36: 4.98 | Q36: 4.98 | R36: 4.98 | S36: 港股通（深） | T36: 41625412 | U36: 0.4805 | V36: 2.0668144e+08 | W36: 300841 | X36: 自营权益4（深港） | Y36: 200000 | Z36: 4.98 | AA36: 4.93 | AB36: 3 | AC36: 叶盛 | AD36: 股票资产 | AE36: -0.4016 | AF36: 0.4819 | AG36: -0.2961 | AH36: 200000 | AI36: 53 | AJ36: 自营权益4（深港） | AK36: 人民币 | AL36: 6111 | AN36: 30084 | AP36: 顾吟湫 | AQ36: 人民币 | AR36: 877057.68 | AW36: CNE1000002V2 | AX36: 无 | BA36: 0.4354 | BB36: 0 | BC36: 缺省券商 | BD36: 交易所业务 | BE36: 不是ETF补券指令 | BF36: -996,000.00 | BG36: 0 | BH36: 非强平 | BI36: 顾吟湫 | BJ36: 否 | BK36: 增强限价盘 | BM36: 0 | BN36: 0 | BO36: 股票 | BR36: 0 | BS36: 已成交
A37: 36 | B37: 2026-02-24 | C37: 3008 | D37: 自营权益4 | E37: 3008 | F37: 836 | G37: 华润电力 | H37: 卖出 | I37: 18.25 | J37: 18.15 | K37: 200000 | L37: 3622600 | M37: 11 | N37: 18.1 | O37: 18.14 | P37: 18.113 | Q37: 18.113 | R37: 18.113 | S37: 港股通（深） | T37: 13329354 | U37: 1.5004 | V37: 2.4193548e+08 | W37: 300841 | X37: 自营权益4（深港） | Y37: 200000 | Z37: 18.28 | AA37: 18.06 | AB37: 5 | AC37: 叶盛 | AD37: 股票资产 | AE37: -0.2732 | AF37: 1.4973 | AG37: -0.2072 | AH37: 200000 | AI37: 53 | AJ37: 自营权益4（深港） | AK37: 人民币 | AL37: 6111 | AN37: 30084 | AP37: 顾吟湫 | AQ37: 人民币 | AR37: 3190134 | AW37: HK0836012952 | AX37: 无 | BA37: 1.5838 | BB37: 0 | BC37: 缺省券商 | BD37: 交易所业务 | BE37: 不是ETF补券指令 | BF37: 3,622,600.00 | BG37: 0 | BH37: 非强平 | BI37: 顾吟湫 | BJ37: 否 | BK37: 增强限价盘 | BM37: 0 | BN37: 3.9166667 | BO37: 股票 | BR37: 0 | BS37: 已成交
A38: 37 | B38: 2026-02-24 | C38: 3008 | D38: 自营权益4 | E38: 3008 | F38: 883 | G38: 中国海洋石油 | H38: 买入 | I38: 25.58 | J38: 25.61 | K38: 150000 | L38: 3835000 | M38: 35 | N38: 25.56 | O38: 25.58 | P38: 25.566667 | Q38: 25.566667 | R38: 25.566667 | S38: 港股通（深） | T38: 80946824 | U38: 0.1853 | V38: 2.0732571e+09 | W38: 300841 | X38: 自营权益4（深港） | Y38: 150000 | Z38: 25.94 | AA38: 25.42 | AB38: 3 | AC38: 叶盛 | AD38: 股票资产 | AE38: -1.0062 | AF38: 0.185 | AG38: 0.1792 | AH38: 150000 | AI38: 53 | AJ38: 自营权益4（深港） | AK38: 人民币 | AL38: 6111 | AN38: 30084 | AP38: 顾吟湫 | AQ38: 人民币 | AR38: 3377024.2 | AW38: HK0883013259 | AX38: 无 | BA38: 1.6766 | BB38: 0 | BC38: 缺省券商 | BD38: 交易所业务 | BE38: 不是ETF补券指令 | BF38: -3,835,000.00 | BG38: 0 | BH38: 非强平 | BI38: 顾吟湫 | BJ38: 否 | BK38: 增强限价盘 | BM38: 0 | BN38: 57.05 | BO38: 股票 | BR38: 0 | BS38: 已成交
A39: 38 | B39: 2026-02-24 | C39: 3008 | D39: 自营权益4 | E39: 3008 | F39: 995 | G39: 安徽皖通高速公路 | H39: 买入 | I39: 13.43 | J39: 13.35 | K39: 22000 | L39: 289960 | M39: 2 | N39: 13.18 | O39: 13.18 | P39: 13.18 | Q39: 13.18 | R39: 13.18 | S39: 港股通（深） | T39: 1916227 | U39: 1.1481 | V39: 25589755 | W39: 300841 | X39: 自营权益4（深港） | Y39: 60000 | Z39: 13.68 | AA39: 13.14 | AB39: 2 | AC39: 叶盛 | AD39: 股票资产 | AE39: 1.5117 | AF39: 1.1331 | AG39: 1.3045 | AH39: 60000 | AI39: 53 | AJ39: 自营权益4（深港） | AK39: 人民币 | AL39: 6111 | AN39: 30084 | AP39: 顾吟湫 | AQ39: 人民币 | AR39: 255332.98 | AW39: CNE1000001X0 | AX39: 无 | BA39: 0.1268 | BB39: 0 | BC39: 缺省券商 | BD39: 交易所业务 | BE39: 不是ETF补券指令 | BF39: -289,960.00 | BG39: 0 | BH39: 非强平 | BI39: 顾吟湫 | BJ39: 否 | BK39: 增强限价盘 | BM39: 0 | BN39: 0.9 | BO39: 股票 | BR39: 0 | BS39: 已成交
A40: 39 | B40: 2026-02-24 | C40: 3008 | D40: 自营权益4 | E40: 3008 | F40: 1071 | G40: 华电国际电力股份 | H40: 卖出 | I40: 4.23 | J40: 4.22 | K40: 1500000 | L40: 6319420 | M40: 105 | N40: 4.21 | O40: 4.23 | P40: 4.2129467 | Q40: 4.2129467 | R40: 4.2129467 | S40: 港股通（深） | T40: 9624893 | U40: 15.5846 | V40: 40632077 | W40: 300841 | X40: 自营权益4（深港） | Y40: 1500000 | Z40: 4.26 | AA40: 4.2 | AB40: 8 | AC40: 叶盛 | AD40: 股票资产 | AE40: -1.1682 | AF40: 15.5528 | AG40: -0.2061 | AH40: 1500000 | AI40: 53 | AJ40: 自营权益4（深港） | AK40: 人民币 | AL40: 6111 | AN40: 30084 | AP40: 顾吟湫 | AQ40: 人民币 | AR40: 5565007.6 | AW40: CNE1000003D8 | AX40: 无 | BA40: 2.7628 | BB40: 0 | BC40: 缺省券商 | BD40: 交易所业务 | BE40: 不是ETF补券指令 | BF40: 6,319,420.00 | BG40: 0 | BH40: 非强平 | BI40: 顾吟湫 | BJ40: 否 | BK40: 增强限价盘 | BM40: 0 | BN40: 1527.3167 | BO40: 股票 | BR40: 0 | BS40: 已成交
...

Sheet 初始持仓
A1: 股票代码 | B1: 股票名称 | C1: 数量 | D1: 成本 | E1: 市价 | F1: 市值 | G1: 账户名称
A2: 600036 | B2: 招商银行 | C2: 150000 | D2: 6307325.2 | E2: 42.1 | F2: 6315000 | G2: 自营权益4
A3: 600519 | B3: 贵州茅台 | C3: 100 | D3: 148310.9 | E3: 1377.18 | F3: 137718 | G3: 自营权益4
A4: 600809 | B4: 山西汾酒 | C4: 16000 | D4: 2869126.9 | E4: 171.7 | F4: 2747200 | G4: 自营权益4
A5: 601009 | B5: 南京银行 | C5: 300000 | D5: 3332290.5 | E5: 11.43 | F5: 3429000 | G5: 自营权益4
A6: 601098 | B6: 中南传媒 | C6: 300000 | D6: 3912034 | E6: 11.26 | F6: 3378000 | G6: 自营权益4
A7: 601166 | B7: 兴业银行 | C7: 300000 | D7: 6347906.6 | E7: 21.06 | F7: 6318000 | G7: 自营权益4
A8: 601169 | B8: 北京银行 | C8: 1500000 | D8: 8791842.6 | E8: 5.48 | F8: 8220000 | G8: 自营权益4
A9: 601818 | B9: 光大银行 | C9: 2700000 | D9: 9766819.9 | E9: 3.49 | F9: 9423000 | G9: 自营权益4
A10: 601900 | B10: 南方传媒 | C10: 200000 | D10: 3093896.3 | E10: 13.41 | F10: 2682000 | G10: 自营权益4
A11: 603198 | B11: 迎驾贡酒 | C11: 60000 | D11: 2637959.9 | E11: 39.56 | F11: 2373600 | G11: 自营权益4
A12: 603369 | B12: 今世缘 | C12: 60000 | D12: 2460995.7 | E12: 34.78 | F12: 2086800 | G12: 自营权益4
A13: 1 | B13: 平安银行 | C13: 700000 | D13: 8159372.6 | E13: 11.41 | F13: 7987000 | G13: 自营权益4
... A41: 6862 | B41: 海底捞 | C41: 400000 | D41: 5365768.8 | E41: 12.78795 | F41: 5115180 | G41: 自营权益4

Sheet 初始资金
A1: 账户名称 | B1: 期初资金
A2: 自营权益4 | B2: 202510600

Sheet 映射
A1: 组合名称样例 | B1: II-a 列 | C1: COUNTIFS 通配
A2: 自营权益4（深港） | B2: 深港 | C2: *深港*
A3: 自营权益4（场内） | B3: 场内 | C3: *场内*
A5: 说明 | B5: 场内/深港 由组合名称关键字判定；股指/基金本样例为 0

Sheet 期初批次
A1: 账户名称 | B1: 证券代码 | C1: 证券名称 | D1: 数量 | E1: 成本总额(CNY) | F1: 成本单价(CNY) | G1: 市价(CNY) | H1: 市值(CNY) | I1: 叶子投组 | J1: 标准代码 | K1: 期初折算汇率(HKD/CNY) | L1: 成本单价(原币) | M1: 成本总额(原币)
A2: 自营权益4 | B2: 600036 | C2: 招商银行 | D2: 150000 | E2: 6307325.2 | F2: 42.048835 | G2: 42.1 | H2: 6315000 | I2: 场内 | J2: 600036.SH | K2: ='FX_RATES_TO_CNY_HIST'!$B$5 | L2: =IF(I2="深港",IF(K2>0,F2/K2,""),F2) | M2: =IF(I2="深港",IF(K2>0,E2/K2,""),E2)
A3: 自营权益4 | B3: 600519 | C3: 贵州茅台 | D3: 100 | E3: 148310.9 | F3: 1483.109 | G3: 1377.18 | H3: 137718 | I3: 场内 | J3: 600519.SH | K3: ='FX_RATES_TO_CNY_HIST'!$B$5 | L3: =IF(I3="深港",IF(K3>0,F3/K3,""),F3) | M3: =IF(I3="深港",IF(K3>0,E3/K3,""),E3)
A4: 自营权益4 | B4: 600809 | C4: 山西汾酒 | D4: 16000 | E4: 2869126.9 | F4: 179.32043 | G4: 171.7 | H4: 2747200 | I4: 场内 | J4: 600809.SH | K4: ='FX_RATES_TO_CNY_HIST'!$B$5 | L4: =IF(I4="深港",IF(K4>0,F4/K4,""),F4) | M4: =IF(I4="深港",IF(K4>0,E4/K4,""),E4)
A5: 自营权益4 | B5: 601009 | C5: 南京银行 | D5: 300000 | E5: 3332290.5 | F5: 11.107635 | G5: 11.43 | H5: 3429000 | I5: 场内 | J5: 601009.SH | K5: ='FX_RATES_TO_CNY_HIST'!$B$5 | L5: =IF(I5="深港",IF(K5>0,F5/K5,""),F5) | M5: =IF(I5="深港",IF(K5>0,E5/K5,""),E5)
A6: 自营权益4 | B6: 601098 | C6: 中南传媒 | D6: 300000 | E6: 3912034 | F6: 13.040114 | G6: 11.26 | H6: 3378000 | I6: 场内 | J6: 601098.SH | K6: ='FX_RATES_TO_CNY_HIST'!$B$5 | L6: =IF(I6="深港",IF(K6>0,F6/K6,""),F6) | M6: =IF(I6="深港",IF(K6>0,E6/K6,""),E6)
A7: 自营权益4 | B7: 601166 | C7: 兴业银行 | D7: 300000 | E7: 6347906.6 | F7: 21.159689 | G7: 21.06 | H7: 6318000 | I7: 场内 | J7: 601166.SH | K7: ='FX_RATES_TO_CNY_HIST'!$B$5 | L7: =IF(I7="深港",IF(K7>0,F7/K7,""),F7) | M7: =IF(I7="深港",IF(K7>0,E7/K7,""),E7)
A8: 自营权益4 | B8: 601169 | C8: 北京银行 | D8: 1500000 | E8: 8791842.6 | F8: 5.8612284 | G8: 5.48 | H8: 8220000 | I8: 场内 | J8: 601169.SH | K8: ='FX_RATES_TO_CNY_HIST'!$B$5 | L8: =IF(I8="深港",IF(K8>0,F8/K8,""),F8) | M8: =IF(I8="深港",IF(K8>0,E8/K8,""),E8)
A9: 自营权益4 | B9: 601818 | C9: 光大银行 | D9: 2700000 | E9: 9766819.9 | F9: 3.6173407 | G9: 3.49 | H9: 9423000 | I9: 场内 | J9: 601818.SH | K9: ='FX_RATES_TO_CNY_HIST'!$B$5 | L9: =IF(I9="深港",IF(K9>0,F9/K9,""),F9) | M9: =IF(I9="深港",IF(K9>0,E9/K9,""),E9)
A10: 自营权益4 | B10: 601900 | C10: 南方传媒 | D10: 200000 | E10: 3093896.3 | F10: 15.469481 | G10: 13.41 | H10: 2682000 | I10: 场内 | J10: 601900.SH | K10: ='FX_RATES_TO_CNY_HIST'!$B$5 | L10: =IF(I10="深港",IF(K10>0,F10/K10,""),F10) | M10: =IF(I10="深港",IF(K10>0,E10/K10,""),E10)
A11: 自营权益4 | B11: 603198 | C11: 迎驾贡酒 | D11: 60000 | E11: 2637959.9 | F11: 43.965998 | G11: 39.56 | H11: 2373600 | I11: 场内 | J11: 603198.SH | K11: ='FX_RATES_TO_CNY_HIST'!$B$5 | L11: =IF(I11="深港",IF(K11>0,F11/K11,""),F11) | M11: =IF(I11="深港",IF(K11>0,E11/K11,""),E11)
A12: 自营权益4 | B12: 603369 | C12: 今世缘 | D12: 60000 | E12: 2460995.7 | F12: 41.016594 | G12: 34.78 | H12: 2086800 | I12: 场内 | J12: 603369.SH | K12: ='FX_RATES_TO_CNY_HIST'!$B$5 | L12: =IF(I12="深港",IF(K12>0,F12/K12,""),F12) | M12: =IF(I12="深港",IF(K12>0,E12/K12,""),E12)
A13: 自营权益4 | B13: 1 | C13: 平安银行 | D13: 700000 | E13: 8159372.6 | F13: 11.656247 | G13: 11.41 | H13: 7987000 | I13: 场内 | J13: 000001.SZ | K13: ='FX_RATES_TO_CNY_HIST'!$B$5 | L13: =IF(I13="深港",IF(K13>0,F13/K13,""),F13) | M13: =IF(I13="深港",IF(K13>0,E13/K13,""),E13)
... A41: 自营权益4 | B41: 6862 | C41: 海底捞 | D41: 400000 | E41: 5365768.8 | F41: 13.414422 | G41: 12.78795 | H41: 5115180 | I41: 深港 | J41: 6862.HK | K41: ='FX_RATES_TO_CNY_HIST'!$B$5 | L41: =IF(I41="深港",IF(K41>0,F41/K41,""),F41) | M41: =IF(I41="深港",IF(K41>0,E41/K41,""),E41)

Sheet FX_RATES_TO_CNY
A1: currency | B1: rate_to_cny
A2: CNY | B2: 1
A3: USD | B3: 7.125
A4: EUR | B4: 7.731
A5: GBP | B5: 9.011
A6: JPY | B6: 0.0475
A7: HKD | B7: 0.86315
A8: CNH | B8: 1
A9: THB | B9: 0.2016

Sheet FX_RATES_TO_CNY_HIST
A1: 报表货币 | B1: CNY
A2: 估值日 | B2: 2026-06-01
A3: 估值日 HKD→CNY | B3: 0.86315
A4: 期初折算日(参数) | B4: 2026-01-01
A5: 期初日 HKD→CNY | B5: 0.89834
A6: 说明 | B6: B3/B5：1 HKD = rate CNY；B3 供估值日盯市折合，B5 供期初深港成本 CNY→HKD（÷B5）。历史表已过滤异常汇率并锁定前海锚点日。
A8: valuation_date | B8: currency | C8: rate_to_cny
A9: 2024-06-03 | B9: USD | C9: 7.1257
A10: 2024-06-04 | B10: USD | C10: 7.0647
A11: 2024-06-05 | B11: USD | C11: 7.2688
A12: 2024-07-11 | B12: HKD | C12: 0.92953
A13: 2024-07-12 | B13: HKD | C13: 0.92857
A14: 2024-07-15 | B14: HKD | C14: 0.92989
A15: 2024-07-16 | B15: HKD | C15: 0.93092
A16: 2024-07-17 | B16: HKD | C16: 0.92998
A17: 2024-07-18 | B17: HKD | C17: 0.92955
A18: 2024-07-19 | B18: HKD | C18: 0.93075
A19: 2024-07-22 | B19: HKD | C19: 0.93165
A20: 2024-07-23 | B20: HKD | C20: 0.93152
... A1301: 2026-06-10 | B1301: HKD | C1301: 0.86444

Sheet 估值日行情
A1: 估值日(实际使用) | B1: 2026-06-01 | C1: 行情缺失→期初持仓兜底(深港CNY÷HKD/CNY)
A2: instrument_code | B2: valuation_date | C2: price | D2: volume | E2: 备注
A3: 000001.SZ | B3: 6/1/2026 | C3: 11.41
A4: 0001.HK | B4: 6/1/2026 | C4: 69.3 | D4: 9282578
A5: 000333.SZ | B5: 2026-06-01 | C5: 81.7 | D5: 37671119 | E5: 补充行情
A6: 000568.SZ | B6: 2026-06-01 | C6: 90.4 | D6: 14082175 | E6: 补充行情
A7: 000858.SZ | B7: 2026-06-01 | C7: 83.41 | D7: 27998720 | E7: 补充行情
A8: 002807.SZ | B8: 2026-06-01 | C8: 4.09 | D8: 47812807 | E8: 补充行情
A9: 002839.SZ | B9: 2026-06-01 | C9: 4.34 | D9: 28288760 | E9: 补充行情
A10: 0177.HK | B10: 6/1/2026 | C10: 10.84 | D10: 26550114
A11: 0300.HK | B11: 2026-06-01 | C11: 89.3 | D11: 13612908 | E11: 补充行情
A12: 0322.HK | B12: 2026-06-01 | C12: 12.41 | D12: 22819396 | E12: 补充行情
A13: 0371.HK | B13: 6/1/2026 | C13: 2.7 | D13: 24656000
A14: 0568.HK | B14: 6/1/2026 | C14: 5.46 | D14: 19684200
A15: 0576.HK | B15: 2026-06-01 | C15: 6.9 | D15: 8524743 | E15: 补充行情
A16: 0728.HK | B16: 2026-06-01 | C16: 5.24 | D16: 71673454 | E16: 补充行情
A17: 0762.HK | B17: 2026-06-01 | C17: 7.75 | D17: 18511329 | E17: 补充行情
A18: 0788.HK | B18: 2026-06-01 | C18: 10.02 | D18: 17748131 | E18: 补充行情
A19: 0811.HK | B19: 6/1/2026 | C19: 9.65 | D19: 816600
A20: 0836.HK | B20: 2026-06-01 | C20: 21.64 | D20: 29719349 | E20: 补充行情
A21: 0858.HK | B21: 6/1/2026 | C21: 0.081 | D21: 2880000
A22: 0883.HK | B22: 2026-06-01 | C22: 26.7 | D22: 85992482 | E22: 补充行情
A23: 0939.HK | B23: 2026-06-01 | C23: 8.53 | D23: 350866907 | E23: 补充行情
A24: 0941.HK | B24: 2026-06-01 | C24: 85.15 | D24: 10941368 | E24: 补充行情
A25: 0995.HK | B25: 2026-06-01 | C25: 16.82 | D25: 1808000 | E25: 补充行情
A26: 0998.HK | B26: 2026-06-01 | C26: 7.31 | D26: 33269624 | E26: 补充行情
A27: 1071.HK | B27: 2026-06-01 | C27: 4.75 | D27: 24856000 | E27: 补充行情
A28: 1088.HK | B28: 2026-06-01 | C28: 47.24 | D28: 21515703 | E28: 补充行情
A29: 1368.HK | B29: 2026-06-01 | C29: 4.46 | D29: 19309068 | E29: 补充行情
A30: 1398.HK | B30: 2026-06-01 | C30: 6.65 | D30: 174592527 | E30: 补充行情
A31: 2016.HK | B31: 2026-06-01 | C31: 2.45 | D31: 5700878 | E31: 补充行情
A32: 2020.HK | B32: 2026-06-01 | C32: 76.4 | D32: 7195973 | E32: 补充行情
A33: 2318.HK | B33: 2026-06-01 | C33: 60.2 | D33: 34250928 | E33: 补充行情
... A49: 601166.SH | B49: 2026-06-01 | C49: 18.44 | D49: 117584490 | E49: 补充行情
A50: 601169.SH | B50: 6/1/2026 | C50: 5.17 | D50: 126704143
A51: 601577.SH | B51: 2026-06-01 | C51: 9.69 | D51: 27029767 | E51: 补充行情
A52: 601818.SH | B52: 6/1/2026 | C52: 3.14 | D52: 182501573
A53: 601825.SH | B53: 2026-06-01 | C53: 8.64 | D53: 23074260 | E53: 补充行情
A54: 601900.SH | B54: 2026-06-01 | C54: 12.39 | D54: 12928667 | E54: 补充行情
A55: 603198.SH | B55: 2026-06-01 | C55: 37.55 | D55: 12125509 | E55: 补充行情
...

Sheet 逐笔辅助
A1: 来源 | B1: 日期 | C1: 组合名称 | D1: 叶子投组 | E1: 证券代码 | F1: 证券名称 | G1: 方向 | H1: 数量 | I1: 原币成交单价(深港=HKD/场内=CNY) | J1: 原币成交金额(深港=HKD/场内=CNY) | K1: 本币成交金额(CNY) | L1: 本币成交单价(CNY) | M1: 买入数量 | N1: 买入本币金额(CNY) | O1: 卖出数量 | P1: 卖出本币金额(CNY) | Q1: 累计买入数量(同叶+码) | R1: 累计买入本币金额(CNY) | S1: 加权成本单价(CNY) | T1: 流水已实现损益(加权RPNL)(CNY) | U1: FIFO已实现(RPNL)(CNY) | V1: 折算汇率(本币÷原币) | W1: 加权RPNL算式(引用L/S/H) | X1: FIFO RPNL算式(先买先卖·含期初) | Y1: 标准代码 | Z1: 估值日市价(原币) | AA1: 兑CNY汇率(估值日) | AB1: 估值日市价(CNY) | AC1: 累计净持仓(至本行) | AD1: 成本单价(加权)(原币) | AE1: 盯市损益(MTM)(原币) | AF1: 盯市损益(MTM)(CNY) | AG1: 全账累计买入数量(含期初) | AH1: 全账累计买入本币金额(含期初) | AI1: 全账加权成本单价(CNY) | AJ1: 全账加权RPNL(CNY) | AK1: 第三轨−运营轨(RPNL差额) | AL1: 全账加权RPNL算式
A2: 期初 | D2: 场内 | E2: 600036 | F2: 招商银行 | G2: 买入 | H2: 150000 | I2: 42.048835 | J2: 6307325.2 | K2: 6307325.2 | L2: 42.048835 | M2: 150000 | N2: 6307325.2 | U2: 0 | Y2: 600036.SH | Z2: =IF(Y2="","",IFERROR(INDEX('估值日行情'!$C$3:$C$61,MATCH(Y2,'估值日行情'!$A$3:$A$61,0)),"")) | AA2: =IF(D2="深港",IFERROR('FX_RATES_TO_CNY_HIST'!$B$3,""),1) | AB2: =IF(Z2<>"",Z2*AA2,"") | AC2: =SUMIFS($H$2:H2,$D$2:D2,D2,$E$2:E2,E2,$G$2:G2,"买入")-SUMIFS($H$2:H2,$D$2:D2,D2,$E$2:E2,E2,$G$2:G2,"卖出") | AD2: =L2 | AE2: =IF(AC2>0,AC2*Z2-AC2*AD2,0) | AF2: =IF(AC2>0,IF(D2="深港",AE2*AA2,AE2),0) | AG2: =H2 | AH2: =K2 | AI2: =L2 | AJ2: 0
A3: 期初 | D3: 场内 | E3: 600519 | F3: 贵州茅台 | G3: 买入 | H3: 100 | I3: 1483.109 | J3: 148310.9 | K3: 148310.9 | L3: 1483.109 | M3: 100 | N3: 148310.9 | U3: 0 | Y3: 600519.SH | Z3: =IF(Y3="","",IFERROR(INDEX('估值日行情'!$C$3:$C$61,MATCH(Y3,'估值日行情'!$A$3:$A$61,0)),"")) | AA3: =IF(D3="深港",IFERROR('FX_RATES_TO_CNY_HIST'!$B$3,""),1) | AB3: =IF(Z3<>"",Z3*AA3,"") | AC3: =SUMIFS($H$2:H3,$D$2:D3,D3,$E$2:E3,E3,$G$2:G3,"买入")-SUMIFS($H$2:H3,$D$2:D3,D3,$E$2:E3,E3,$G$2:G3,"卖出") | AD3: =L3 | AE3: =IF(AC3>0,AC3*Z3-AC3*AD3,0) | AF3: =IF(AC3>0,IF(D3="深港",AE3*AA3,AE3),0) | AG3: =H3 | AH3: =K3 | AI3: =L3 | AJ3: 0
A4: 期初 | D4: 场内 | E4: 600809 | F4: 山西汾酒 | G4: 买入 | H4: 16000 | I4: 179.32043 | J4: 2869126.9 | K4: 2869126.9 | L4: 179.32043 | M4: 16000 | N4: 2869126.9 | U4: 0 | Y4: 600809.SH | Z4: =IF(Y4="","",IFERROR(INDEX('估值日行情'!$C$3:$C$61,MATCH(Y4,'估值日行情'!$A$3:$A$61,0)),"")) | AA4: =IF(D4="深港",IFERROR('FX_RATES_TO_CNY_HIST'!$B$3,""),1) | AB4: =IF(Z4<>"",Z4*AA4,"") | AC4: =SUMIFS($H$2:H4,$D$2:D4,D4,$E$2:E4,E4,$G$2:G4,"买入")-SUMIFS($H$2:H4,$D$2:D4,D4,$E$2:E4,E4,$G$2:G4,"卖出") | AD4: =L4 | AE4: =IF(AC4>0,AC4*Z4-AC4*AD4,0) | AF4: =IF(AC4>0,IF(D4="深港",AE4*AA4,AE4),0) | AG4: =H4 | AH4: =K4 | AI4: =L4 | AJ4: 0
A5: 期初 | D5: 场内 | E5: 601009 | F5: 南京银行 | G5: 买入 | H5: 300000 | I5: 11.107635 | J5: 3332290.5 | K5: 3332290.5 | L5: 11.107635 | M5: 300000 | N5: 3332290.5 | U5: 0 | Y5: 601009.SH | Z5: =IF(Y5="","",IFERROR(INDEX('估值日行情'!$C$3:$C$61,MATCH(Y5,'估值日行情'!$A$3:$A$61,0)),"")) | AA5: =IF(D5="深港",IFERROR('FX_RATES_TO_CNY_HIST'!$B$3,""),1) | AB5: =IF(Z5<>"",Z5*AA5,"") | AC5: =SUMIFS($H$2:H5,$D$2:D5,D5,$E$2:E5,E5,$G$2:G5,"买入")-SUMIFS($H$2:H5,$D$2:D5,D5,$E$2:E5,E5,$G$2:G5,"卖出") | AD5: =L5 | AE5: =IF(AC5>0,AC5*Z5-AC5*AD5,0) | AF5: =IF(AC5>0,IF(D5="深港",AE5*AA5,AE5),0) | AG5: =H5 | AH5: =K5 | AI5: =L5 | AJ5: 0
A6: 期初 | D6: 场内 | E6: 601098 | F6: 中南传媒 | G6: 买入 | H6: 300000 | I6: 13.040114 | J6: 3912034 | K6: 3912034 | L6: 13.040114 | M6: 300000 | N6: 3912034 | U6: 0 | Y6: 601098.SH | Z6: =IF(Y6="","",IFERROR(INDEX('估值日行情'!$C$3:$C$61,MATCH(Y6,'估值日行情'!$A$3:$A$61,0)),"")) | AA6: =IF(D6="深港",IFERROR('FX_RATES_TO_CNY_HIST'!$B$3,""),1) | AB6: =IF(Z6<>"",Z6*AA6,"") | AC6: =SUMIFS($H$2:H6,$D$2:D6,D6,$E$2:E6,E6,$G$2:G6,"买入")-SUMIFS($H$2:H6,$D$2:D6,D6,$E$2:E6,E6,$G$2:G6,"卖出") | AD6: =L6 | AE6: =IF(AC6>0,AC6*Z6-AC6*AD6,0) | AF6: =IF(AC6>0,IF(D6="深港",AE6*AA6,AE6),0) | AG6: =H6 | AH6: =K6 | AI6: =L6 | AJ6: 0
A7: 期初 | D7: 场内 | E7: 601166 | F7: 兴业银行 | G7: 买入 | H7: 300000 | I7: 21.159689 | J7: 6347906.6 | K7: 6347906.6 | L7: 21.159689 | M7: 300000 | N7: 6347906.6 | U7: 0 | Y7: 601166.SH | Z7: =IF(Y7="","",IFERROR(INDEX('估值日行情'!$C$3:$C$61,MATCH(Y7,'估值日行情'!$A$3:$A$61,0)),"")) | AA7: =IF(D7="深港",IFERROR('FX_RATES_TO_CNY_HIST'!$B$3,""),1) | AB7: =IF(Z7<>"",Z7*AA7,"") | AC7: =SUMIFS($H$2:H7,$D$2:D7,D7,$E$2:E7,E7,$G$2:G7,"买入")-SUMIFS($H$2:H7,$D$2:D7,D7,$E$2:E7,E7,$G$2:G7,"卖出") | AD7: =L7 | AE7: =IF(AC7>0,AC7*Z7-AC7*AD7,0) | AF7: =IF(AC7>0,IF(D7="深港",AE7*AA7,AE7),0) | AG7: =H7 | AH7: =K7 | AI7: =L7 | AJ7: 0
A8: 期初 | D8: 场内 | E8: 601169 | F8: 北京银行 | G8: 买入 | H8: 1500000 | I8: 5.8612284 | J8: 8791842.6 | K8: 8791842.6 | L8: 5.8612284 | M8: 1500000 | N8: 8791842.6 | U8: 0 | Y8: 601169.SH | Z8: =IF(Y8="","",IFERROR(INDEX('估值日行情'!$C$3:$C$61,MATCH(Y8,'估值日行情'!$A$3:$A$61,0)),"")) | AA8: =IF(D8="深港",IFERROR('FX_RATES_TO_CNY_HIST'!$B$3,""),1) | AB8: =IF(Z8<>"",Z8*AA8,"") | AC8: =SUMIFS($H$2:H8,$D$2:D8,D8,$E$2:E8,E8,$G$2:G8,"买入")-SUMIFS($H$2:H8,$D$2:D8,D8,$E$2:E8,E8,$G$2:G8,"卖出") | AD8: =L8 | AE8: =IF(AC8>0,AC8*Z8-AC8*AD8,0) | AF8: =IF(AC8>0,IF(D8="深港",AE8*AA8,AE8),0) | AG8: =H8 | AH8: =K8 | AI8: =L8 | AJ8: 0
A9: 期初 | D9: 场内 | E9: 601818 | F9: 光大银行 | G9: 买入 | H9: 2700000 | I9: 3.6173407 | J9: 9766819.9 | K9: 9766819.9 | L9: 3.6173407 | M9: 2700000 | N9: 9766819.9 | U9: 0 | Y9: 601818.SH | Z9: =IF(Y9="","",IFERROR(INDEX('估值日行情'!$C$3:$C$61,MATCH(Y9,'估值日行情'!$A$3:$A$61,0)),"")) | AA9: =IF(D9="深港",IFERROR('FX_RATES_TO_CNY_HIST'!$B$3,""),1) | AB9: =IF(Z9<>"",Z9*AA9,"") | AC9: =SUMIFS($H$2:H9,$D$2:D9,D9,$E$2:E9,E9,$G$2:G9,"买入")-SUMIFS($H$2:H9,$D$2:D9,D9,$E$2:E9,E9,$G$2:G9,"卖出") | AD9: =L9 | AE9: =IF(AC9>0,AC9*Z9-AC9*AD9,0) | AF9: =IF(AC9>0,IF(D9="深港",AE9*AA9,AE9),0) | AG9: =H9 | AH9: =K9 | AI9: =L9 | AJ9: 0
A10: 期初 | D10: 场内 | E10: 601900 | F10: 南方传媒 | G10: 买入 | H10: 200000 | I10: 15.469481 | J10: 3093896.3 | K10: 3093896.3 | L10: 15.469481 | M10: 200000 | N10: 3093896.3 | U10: 0 | Y10: 601900.SH | Z10: =IF(Y10="","",IFERROR(INDEX('估值日行情'!$C$3:$C$61,MATCH(Y10,'估值日行情'!$A$3:$A$61,0)),"")) | AA10: =IF(D10="深港",IFERROR('FX_RATES_TO_CNY_HIST'!$B$3,""),1) | AB10: =IF(Z10<>"",Z10*AA10,"") | AC10: =SUMIFS($H$2:H10,$D$2:D10,D10,$E$2:E10,E10,$G$2:G10,"买入")-SUMIFS($H$2:H10,$D$2:D10,D10,$E$2:E10,E10,$G$2:G10,"卖出") | AD10: =L10 | AE10: =IF(AC10>0,AC10*Z10-AC10*AD10,0) | AF10: =IF(AC10>0,IF(D10="深港",AE10*AA10,AE10),0) | AG10: =H10 | AH10: =K10 | AI10: =L10 | AJ10: 0
A11: 期初 | D11: 场内 | E11: 603198 | F11: 迎驾贡酒 | G11: 买入 | H11: 60000 | I11: 43.965998 | J11: 2637959.9 | K11: 2637959.9 | L11: 43.965998 | M11: 60000 | N11: 2637959.9 | U11: 0 | Y11: 603198.SH | Z11: =IF(Y11="","",IFERROR(INDEX('估值日行情'!$C$3:$C$61,MATCH(Y11,'估值日行情'!$A$3:$A$61,0)),"")) | AA11: =IF(D11="深港",IFERROR('FX_RATES_TO_CNY_HIST'!$B$3,""),1) | AB11: =IF(Z11<>"",Z11*AA11,"") | AC11: =SUMIFS($H$2:H11,$D$2:D11,D11,$E$2:E11,E11,$G$2:G11,"买入")-SUMIFS($H$2:H11,$D$2:D11,D11,$E$2:E11,E11,$G$2:G11,"卖出") | AD11: =L11 | AE11: =IF(AC11>0,AC11*Z11-AC11*AD11,0) | AF11: =IF(AC11>0,IF(D11="深港",AE11*AA11,AE11),0) | AG11: =H11 | AH11: =K11 | AI11: =L11 | AJ11: 0
A12: 期初 | D12: 场内 | E12: 603369 | F12: 今世缘 | G12: 买入 | H12: 60000 | I12: 41.016594 | J12: 2460995.7 | K12: 2460995.7 | L12: 41.016594 | M12: 60000 | N12: 2460995.7 | U12: 0 | Y12: 603369.SH | Z12: =IF(Y12="","",IFERROR(INDEX('估值日行情'!$C$3:$C$61,MATCH(Y12,'估值日行情'!$A$3:$A$61,0)),"")) | AA12: =IF(D12="深港",IFERROR('FX_RATES_TO_CNY_HIST'!$B$3,""),1) | AB12: =IF(Z12<>"",Z12*AA12,"") | AC12: =SUMIFS($H$2:H12,$D$2:D12,D12,$E$2:E12,E12,$G$2:G12,"买入")-SUMIFS($H$2:H12,$D$2:D12,D12,$E$2:E12,E12,$G$2:G12,"卖出") | AD12: =L12 | AE12: =IF(AC12>0,AC12*Z12-AC12*AD12,0) | AF12: =IF(AC12>0,IF(D12="深港",AE12*AA12,AE12),0) | AG12: =H12 | AH12: =K12 | AI12: =L12 | AJ12: 0
A13: 期初 | D13: 场内 | E13: 1 | F13: 平安银行 | G13: 买入 | H13: 700000 | I13: 11.656247 | J13: 8159372.6 | K13: 8159372.6 | L13: 11.656247 | M13: 700000 | N13: 8159372.6 | U13: 0 | Y13: 000001.SZ | Z13: =IF(Y13="","",IFERROR(INDEX('估值日行情'!$C$3:$C$61,MATCH(Y13,'估值日行情'!$A$3:$A$61,0)),"")) | AA13: =IF(D13="深港",IFERROR('FX_RATES_TO_CNY_HIST'!$B$3,""),1) | AB13: =IF(Z13<>"",Z13*AA13,"") | AC13: =SUMIFS($H$2:H13,$D$2:D13,D13,$E$2:E13,E13,$G$2:G13,"买入")-SUMIFS($H$2:H13,$D$2:D13,D13,$E$2:E13,E13,$G$2:G13,"卖出") | AD13: =L13 | AE13: =IF(AC13>0,AC13*Z13-AC13*AD13,0) | AF13: =IF(AC13>0,IF(D13="深港",AE13*AA13,AE13),0) | AG13: =H13 | AH13: =K13 | AI13: =L13 | AJ13: 0
... A15: 期初 | D15: 场内 | E15: 858 | F15: 五 粮 液 | G15: 买入 | H15: 20000 | I15: 129.79844 | J15: 2595968.9 | K15: 2595968.9 | L15: 129.79844 | M15: 20000 | N15: 2595968.9 | U15: 0 | Y15: 000858.SZ | Z15: =IF(Y15="","",IFERROR(INDEX('估值日行情'!$C$3:$C$61,MATCH(Y15,'估值日行情'!$A$3:$A$61,0)),"")) | AA15: =IF(D15="深港",IFERROR('FX_RATES_TO_CNY_HIST'!$B$3,""),1) | AB15: =IF(Z15<>"",Z15*AA15,"") | AC15: =SUMIFS($H$2:H15,$D$2:D15,D15,$E$2:E15,E15,$G$2:G15,"买入")-SUMIFS($H$2:H15,$D$2:D15,D15,$E$2:E15,E15,$G$2:G15,"卖出") | AD15: =L15 | AE15: =IF(AC15>0,AC15*Z15-AC15*AD15,0) | AF15: =IF(AC15>0,IF(D15="深港",AE15*AA15,AE15),0) | AG15: =H15 | AH15: =K15 | AI15: =L15 | AJ15: 0
A16: 期初 | D16: 深港 | E16: 177 | F16: 江苏宁沪高速公路 | G16: 买入 | H16: 650000 | I16: =IF('FX_RATES_TO_CNY_HIST'!$B$5>0,L16/'FX_RATES_TO_CNY_HIST'!$B$5,"") | J16: =IF(I16<>"",I16*H16,"") | K16: 5863319.3 | L16: 9.0204912 | M16: 650000 | N16: 5863319.3 | U16: 0 | Y16: 0177.HK | Z16: =IF(Y16="","",IFERROR(INDEX('估值日行情'!$C$3:$C$61,MATCH(Y16,'估值日行情'!$A$3:$A$61,0)),"")) | AA16: =IF(D16="深港",IFERROR('FX_RATES_TO_CNY_HIST'!$B$3,""),1) | AB16: =IF(Z16<>"",Z16*AA16,"") | AC16: =SUMIFS($H$2:H16,$D$2:D16,D16,$E$2:E16,E16,$G$2:G16,"买入")-SUMIFS($H$2:H16,$D$2:D16,D16,$E$2:E16,E16,$G$2:G16,"卖出") | AD16: =I16 | AE16: =IF(AC16>0,AC16*Z16-AC16*AD16,0) | AF16: =IF(AC16>0,IF(D16="深港",AE16*AA16,AE16),0) | AG16: =H16 | AH16: =K16 | AI16: =L16 | AJ16: 0
