Workbook

Sheet 逐月汇总(WAVG)
A1: 逐月汇总 · WAVG（第三轨）· 2026-01-01 → 2026-06-08
D2: 已实现 | E2: 浮动
A3: 口径 | B3: 期初MTM | C3: 期初WAVG-持仓成本 | D3: 2026-01 RPNL | E3: 2026-01 MTM | F3: 2026-02 RPNL | G3: 2026-02 MTM | H3: 2026-03 RPNL | I3: 2026-03 MTM | J3: 2026-04 RPNL | K3: 2026-04 MTM | L3: 2026-05 RPNL | M3: 2026-05 MTM | N3: 2026-06 RPNL | O3: 2026-06 MTM | P3: 累计 WAVG-RPNL | Q3: 累计 WAVG-MTM
A4: 场内 | B4: -3345326.9 | C4: 63466945 | D4: -1102755.7 | E4: -1152243.3 | F4: -221258.25 | G4: -68658.75 | H4: 0 | I4: 633359 | J4: 42820 | K4: -108030 | L4: 61939 | M4: -1247939 | N4: 0 | O4: -77000 | P4: -1219254.9 | Q4: -5365839
A5: 深港 | B5: -3402773.8 | C5: 1.448506e+08 | D5: 306077.82 | E5: 2613866.9 | F5: 526224.45 | G5: -1342543.7 | H5: -747568.3 | I5: -2861178.8 | J5: -437458.17 | K5: 3044790.7 | L5: -723779.31 | M5: -5938666.5 | N5: 0 | O5: 19040.45 | P5: -1076503.5 | Q5: -7867464.7
A6: 现货合计 | B6: -6748100.7 | C6: 2.0831755e+08 | D6: -796677.84 | E6: 1461623.6 | F6: 304966.2 | G6: -1411202.5 | H6: -747568.3 | I6: -2227819.8 | J6: -394638.17 | K6: 2936760.7 | L6: -661840.31 | M6: -7186605.5 | N6: 0 | O6: -57959.55 | P6: -2295758.4 | Q6: -13233304
A7: 累计 | B7: -6748100.7 | C7: 2.0831755e+08 | D7: -796677.84 | E7: -5286477.1 | F7: -491711.64 | G7: -6697679.6 | H7: -1239279.9 | I7: -8925499.4 | J7: -1633918.1 | K7: -5988738.7 | L7: -2295758.4 | M7: -13175344 | N7: -2295758.4 | O7: -13233304 | P7: -2295758.4 | Q7: -13233304
A8: 当月发生 | D8: =D7 -> -796677.84 | E8: =E7-B7 -> 1461623.6 | F8: =F7-D7 -> 304966.2 | G8: =G7-E7 -> -1411202.5 | H8: =H7-F7 -> -747568.3 | I8: =I7-G7 -> -2227819.8 | J8: =J7-H7 -> -394638.17 | K8: =K7-I7 -> 2936760.7 | L8: =L7-J7 -> -661840.31 | M8: =M7-K7 -> -7186605.5 | ... O8: =O7-M7 -> -57959.55
A9: 估值 | D9: =逐月汇总!E9*10000 -> -804837.91 | E9: =逐月汇总!E8*10000 -> 1456121.6 | F9: =逐月汇总!F9*10000 -> 274667.3 | G9: =逐月汇总!F8*10000 -> -1427420.7 | H9: =逐月汇总!G9*10000 -> -757002.75 | I9: =逐月汇总!G8*10000 -> -2234096.3 | J9: =逐月汇总!H9*10000 -> -422718.4 | K9: =逐月汇总!H8*10000 -> 2915643.4 | L9: =逐月汇总!I9*10000 -> -717983.43 | M9: =逐月汇总!I8*10000 -> -7181440.2 | N9: =逐月汇总!J9*10000 -> -250690.36 | O9: =逐月汇总!J8*10000 -> 402887.67
A10: 差异 | D10: =D8-D9 -> 8160.07 | E10: =E8-E9 -> 5502 | F10: =F8-F9 -> 30298.9 | G10: =G8-G9 -> 16218.2 | H10: =H8-H9 -> 9434.45 | I10: =I8-I9 -> 6276.52 | J10: =J8-J9 -> 28080.23 | K10: =K8-K9 -> 21117.36 | ... O10: =O8-O9 -> -460847.22

Sheet 逐月汇总
A1: 绩效归因产品口径一级分类 | B1: 绩效归因产品口径二级分类 | C1: 绩效归因科目口径 | D1: 2026年初 | E1: 2026-01 | F1: 2026-02 | G1: 2026-03 | H1: 2026-04 | I1: 2026-05 | J1: 2026-06
A2: 其他 | B2: 买入返售 | C2: 利息盈亏 | D2: 3.5527137e-15
B3: 资金 | C3: 利息盈亏 | D3: 1.29452e-13 | E3: 0.020805 | F3: 0.020595 | G3: -0.140267 | H3: 0.004383 | I3: 0.632907 | J3: 0.035892
A4: 权益类产品 | B4: 股票 | C4: 浮动盈亏 | D4: 1.6342483e-13
C5: 股利盈亏 | D5: 1.7053026e-13 | E5: 18.59 | F5: 50.95 | I5: 145.94325 | J5: 78.798082
C6: 价差盈亏 | D6: 9.5923269e-14
C7: 交易费用 | D7: 6.1062266e-15 | E7: -0.093644 | F7: -0.08964 | G7: -0.093525 | H7: -0.087553 | I7: -0.082279 | J7: -0.022693
C8: OCI公允 | D8: -674.81007 | E8: 145.61216 | F8: -142.74207 | G8: -223.40963 | H8: 291.56434 | I8: -718.14402 | J8: 40.288767
C9: OCI价差 | D9: 1463.2581 | E9: -80.483791 | F9: 27.46673 | G9: -75.700275 | H9: -42.27184 | I9: -71.798343 | J9: -25.069036 | L9: =SUM(E8:J9) -> -874.68701

Sheet 逐券逐月(WAVG)
A1: 逐券逐月 · WAVG · 2026-01-01 → 2026-06-08
A3: 证券名称 | B3: 证券代码 | C3: 标准代码 | D3: 叶子投组 | E3: 市场 | F3: 期初持仓 | G3: 净持仓 | H3: 期初MTM | I3: 期初WAVG-持仓成本 | J3: WAVG-持仓成本 | K3: 2026-01 RPNL | L3: 2026-01 MTM | M3: 2026-02 RPNL | N3: 2026-02 MTM | O3: 2026-03 RPNL | P3: 2026-03 MTM | Q3: 2026-04 RPNL | R3: 2026-04 MTM | S3: 2026-05 RPNL | T3: 2026-05 MTM | U3: 2026-06 RPNL | V3: 2026-06 MTM | W3: 累计 WAVG-RPNL | X3: 累计 WAVG-MTM | Y3: 累计 WAVG-总浮动(期初→估值日)
A4: 平安银行 | B4: 000001 | C4: 000001.SZ | D4: 场内 | E4: 场内 | F4: 700000 | G4: 700000 | H4: -172372.57 | I4: 8159372.6 | J4: 8159372.6 | K4: 0 | L4: -406000 | M4: 0 | N4: 49000 | O4: 0 | P4: 126000 | Q4: 0 | R4: 287000 | S4: 0 | T4: -392000 | U4: 0 | V4: 70000 | W4: 0 | X4: -438372.57 | Y4: -266000
A5: 美的集团 | B5: 000333 | C5: 000333.SZ | D5: 场内 | E5: 场内 | F5: 0 | G5: 0 | H5: 0 | I5: 0 | J5: 0 | K5: 0 | L5: 0 | M5: 0 | N5: -53400 | O5: 0 | P5: -100561 | Q5: 0 | R5: 420900 | S5: 61939 | T5: -266939 | U5: 0 | V5: 0 | W5: 61939 | X5: 0 | Y5: 0
A6: 泸州老窖 | B6: 000568 | C6: 000568.SZ | D6: 场内 | E6: 场内 | F6: 25000 | G6: 0 | H6: -137594.93 | I6: 3043094.9 | J6: 0 | K6: 0 | L6: 117000 | M6: -102480.93 | N6: 20594.93 | O6: 0 | P6: 0 | Q6: 0 | R6: 0 | S6: 0 | T6: 0 | U6: 0 | V6: 0 | W6: -102480.93 | X6: 0 | Y6: 137594.93
A7: 五 粮 液 | B7: 000858 | C7: 000858.SZ | D7: 场内 | E7: 场内 | F7: 20000 | G7: 0 | H7: -477168.9 | I7: 2595968.9 | J7: 0 | K7: -535649.9 | L7: 477168.9 | M7: 0 | N7: 0 | O7: 0 | P7: 0 | Q7: 0 | R7: 0 | S7: 0 | T7: 0 | U7: 0 | V7: 0 | W7: -535649.9 | X7: 0 | Y7: 477168.9
A8: 江阴银行 | B8: 002807 | C8: 002807.SZ | D8: 场内 | E8: 场内 | F8: 0 | G8: 0 | H8: 0 | I8: 0 | J8: 0 | K8: 0 | L8: 0 | M8: 0 | N8: 0 | O8: 0 | P8: -16800 | Q8: -8800 | R8: 16800 | S8: 0 | T8: 0 | U8: 0 | V8: 0 | W8: -8800 | X8: 0 | Y8: 0
A9: 张家港行 | B9: 002839 | C9: 002839.SZ | D9: 场内 | E9: 场内 | F9: 0 | G9: 0 | H9: 0 | I9: 0 | J9: 0 | K9: 0 | L9: 0 | M9: 0 | N9: 0 | O9: 0 | P9: -20800 | Q9: -18800 | R9: 20800 | S9: 0 | T9: 0 | U9: 0 | V9: 0 | W9: -18800 | X9: 0 | Y9: 0
A10: 招商银行 | B10: 600036 | C10: 600036.SH | D10: 场内 | E10: 场内 | F10: 150000 | G10: 250000 | H10: 7674.77 | I10: 6307325.2 | J10: 10208195 | K10: 0 | L10: -497957 | M10: 0 | N10: -30413 | O10: 0 | P10: 142500 | Q10: 0 | R10: -262500 | S10: 0 | T10: -65000 | U10: 0 | V10: 122500 | W10: 0 | X10: -583195.23 | Y10: -590870
A11: 贵州茅台 | B11: 600519 | C11: 600519.SH | D11: 场内 | E11: 场内 | F11: 100 | G11: 0 | H11: -10592.9 | I11: 148310.9 | J11: 0 | K11: -13560.9 | L11: 10592.9 | M11: 0 | N11: 0 | O11: 0 | P11: 0 | Q11: 0 | R11: 0 | S11: 0 | T11: 0 | U11: 0 | V11: 0 | W11: -13560.9 | X11: 0 | Y11: 10592.9
A12: 海尔智家 | B12: 600690 | C12: 600690.SH | D12: 场内 | E12: 场内 | F12: 0 | G12: 100000 | H12: 0 | I12: 0 | J12: 2116410 | K12: 0 | L12: 0 | M12: 0 | N12: 0 | O12: 0 | P12: 0 | Q12: 0 | R12: 36590 | S12: 0 | T12: -65000 | U12: 0 | V12: -71000 | W12: 0 | X12: -99410 | Y12: -99410
A13: 山西汾酒 | B13: 600809 | C13: 600809.SH | D13: 场内 | E13: 场内 | F13: 16000 | G13: 0 | H13: -121926.87 | I13: 2869126.9 | J13: 0 | K13: 0 | L13: -11040 | M13: -158486.87 | N13: 132966.87 | O13: 0 | P13: 0 | Q13: 0 | R13: 0 | S13: 0 | T13: 0 | U13: 0 | V13: 0 | W13: -158486.87 | X13: 0 | Y13: 121926.87
A14: 伊利股份 | B14: 600887 | C14: 600887.SH | D14: 场内 | E14: 场内 | F14: 0 | G14: 250000 | H14: 0 | I14: 0 | J14: 6544500 | K14: 0 | L14: 0 | M14: 0 | N14: -25300 | O14: 0 | P14: 64300 | Q14: 0 | R14: 281500 | S14: 0 | T14: -135000 | U14: 0 | V14: -387500 | W14: 0 | X14: -202000 | Y14: -202000
A15: 无锡银行 | B15: 600908 | C15: 600908.SH | D15: 场内 | E15: 场内 | F15: 0 | G15: 0 | H15: 0 | I15: 0 | J15: 0 | K15: 0 | L15: 0 | M15: 0 | N15: 0 | O15: 0 | P15: -41280 | Q15: -55280 | R15: 41280 | S15: 0 | T15: 0 | U15: 0 | V15: 0 | W15: -55280 | X15: 0 | Y15: 0
... A58: 卫龙美味 | B58: 9985 | C58: 9985.HK | D58: 深港 | E58: 深港 | F58: 0 | G58: 200000 | H58: 0 | I58: 0 | J58: 1917430.3 | K58: 0 | L58: 0 | M58: 0 | N58: -79610.43 | O58: 0 | P58: -839040.16 | Q58: 0 | R58: 15211.35 | S58: -1332578.2 | T58: 398668.14 | U58: 0 | V58: -43608 | W58: -1332578.2 | X58: -548379.1 | Y58: -548379.1
A59: 合计 | H59: =SUBTOTAL(9,H4:H58) -> -176258.88 | I59: =SUBTOTAL(9,I4:I58) -> 4534033.3 | J59: =SUBTOTAL(9,J4:J58) -> 7200070 | K59: =SUBTOTAL(9,K4:K58) -> 0 | L59: =SUBTOTAL(9,L4:L58) -> 232045.6 | M59: =SUBTOTAL(9,M4:M58) -> 0 | N59: =SUBTOTAL(9,N4:N58) -> 73844 | O59: =SUBTOTAL(9,O4:O58) -> 0 | ... Y59: =SUBTOTAL(9,Y4:Y58) -> -911757.73
A60: 累计 | H60: -6748100.7 | I60: 2.0831755e+08 | K60: -796677.84 | L60: -5286477.1 | M60: -491711.64 | N60: -6697679.6 | O60: -1239279.9 | P60: -8925499.4 | Q60: -1633918.1 | R60: -5988738.7 | S60: -2295758.4 | T60: -13175344 | U60: -2295758.4 | V60: -13233304 | W60: -2295758.4 | X60: -13233304 | Y60: -6485203
K63: 2026年1月.xlsx（客户），持仓公允: | L63: -5291979.1 | M63: ，1月底，差了5502元

Sheet 逐券汇总
E1: 差异 | Q1: 估值 | AC1: 报告
A2: 绩效归因产品口径一级分类 | B2: 绩效归因产品口径二级分类 | C2: 证券代码 | D2: 六级科目名称 | E2: 46023 | G2: 46054 | I2: 46082 | K2: 46113 | M2: 46143 | O2: 46174 | Q2: 46023 | S2: 46054 | U2: 46082 | W2: 46113 | Y2: 46143 | AA2: 46174 | AC2: 46023 | AE2: 46054 | AG2: 46082 | AI2: 46113 | AK2: 46143 | AM2: 46174
E3: RPNL | F3: MTM | G3: OCI价差 | H3: OCI公允 | I3: OCI价差 | J3: OCI公允 | K3: OCI价差 | L3: OCI公允 | M3: OCI价差 | N3: OCI公允 | O3: OCI价差 | P3: OCI公允 | Q3: OCI价差 | R3: OCI公允 | S3: OCI价差 | T3: OCI公允 | U3: OCI价差 | V3: OCI公允 | W3: OCI价差 | X3: OCI公允 | Y3: OCI价差 | Z3: OCI公允 | AA3: OCI价差 | AB3: OCI公允 | AC3: RPNL | AD3: MTM | AE3: OCI价差 | AF3: OCI公允 | AG3: OCI价差 | AH3: OCI公允 | AI3: OCI价差 | AJ3: OCI公允 | AK3: OCI价差 | AL3: OCI公允 | AM3: OCI价差 | AN3: OCI公允
A4: 权益类产品 | B4: 股票 | C4: 1 | D4: 平安银行 | E4: =AC4-Q4 -> 0 | F4: =AD4-R4 -> 0 | G4: =AE4-S4 -> 0 | H4: =AF4-T4 -> 0 | I4: =AG4-U4 -> 0 | J4: =AH4-V4 -> 0 | K4: =AI4-W4 -> 0 | L4: =AJ4-X4 -> 0 | ... P4: =AN4-AB4 -> 6606.48 | R4: -406000 | T4: 49000 | V4: 126000 | X4: 287000 | Z4: -392000 | AB4: 63393.52 | AC4: =SUMIFS('逐券逐月(WAVG)'!K:K,'逐券逐月(WAVG)'!$A:$A,逐券汇总!$D4) -> 0 | AD4: =SUMIFS('逐券逐月(WAVG)'!L:L,'逐券逐月(WAVG)'!$A:$A,逐券汇总!$D4) -> -406000 | AE4: =SUMIFS('逐券逐月(WAVG)'!M:M,'逐券逐月(WAVG)'!$A:$A,逐券汇总!$D4) -> 0 | AF4: =SUMIFS('逐券逐月(WAVG)'!N:N,'逐券逐月(WAVG)'!$A:$A,逐券汇总!$D4) -> 49000 | AG4: =SUMIFS('逐券逐月(WAVG)'!O:O,'逐券逐月(WAVG)'!$A:$A,逐券汇总!$D4) -> 0 | AH4: =SUMIFS('逐券逐月(WAVG)'!P:P,'逐券逐月(WAVG)'!$A:$A,逐券汇总!$D4) -> 126000 | AI4: =SUMIFS('逐券逐月(WAVG)'!Q:Q,'逐券逐月(WAVG)'!$A:$A,逐券汇总!$D4) -> 0 | AJ4: =SUMIFS('逐券逐月(WAVG)'!R:R,'逐券逐月(WAVG)'!$A:$A,逐券汇总!$D4) -> 287000 | AK4: =SUMIFS('逐券逐月(WAVG)'!S:S,'逐券逐月(WAVG)'!$A:$A,逐券汇总!$D4) -> 0 | AL4: =SUMIFS('逐券逐月(WAVG)'!T:T,'逐券逐月(WAVG)'!$A:$A,逐券汇总!$D4) -> -392000 | AM4: =SUMIFS('逐券逐月(WAVG)'!U:U,'逐券逐月(WAVG)'!$A:$A,逐券汇总!$D4) -> 0 | AN4: =SUMIFS('逐券逐月(WAVG)'!V:V,'逐券逐月(WAVG)'!$A:$A,逐券汇总!$D4) -> 70000
C5: 333 | D5: 美的集团 | E5: =AC5-Q5 -> 0 | F5: =AD5-R5 -> 0 | G5: =AE5-S5 -> 0 | H5: =AF5-T5 -> 204.95 | I5: =AG5-U5 -> 0 | J5: =AH5-V5 -> 49.47 | K5: =AI5-W5 -> 0 | L5: =AJ5-X5 -> 247.92 | ... P5: =AN5-AB5 -> 0 | T5: -53604.95 | V5: -100610.47 | X5: 420652.08 | Y5: 56977.13 | Z5: -266436.66 | AC5: =SUMIFS('逐券逐月(WAVG)'!K:K,'逐券逐月(WAVG)'!$A:$A,逐券汇总!$D5,'逐券逐月(WAVG)'!$B:$B,逐券汇总!$C5) -> 0 | AD5: =SUMIFS('逐券逐月(WAVG)'!L:L,'逐券逐月(WAVG)'!$A:$A,逐券汇总!$D5,'逐券逐月(WAVG)'!$B:$B,逐券汇总!$C5) -> 0 | AE5: =SUMIFS('逐券逐月(WAVG)'!M:M,'逐券逐月(WAVG)'!$A:$A,逐券汇总!$D5,'逐券逐月(WAVG)'!$B:$B,逐券汇总!$C5) -> 0 | AF5: =SUMIFS('逐券逐月(WAVG)'!N:N,'逐券逐月(WAVG)'!$A:$A,逐券汇总!$D5,'逐券逐月(WAVG)'!$B:$B,逐券汇总!$C5) -> -53400 | AG5: =SUMIFS('逐券逐月(WAVG)'!O:O,'逐券逐月(WAVG)'!$A:$A,逐券汇总!$D5,'逐券逐月(WAVG)'!$B:$B,逐券汇总!$C5) -> 0 | AH5: =SUMIFS('逐券逐月(WAVG)'!P:P,'逐券逐月(WAVG)'!$A:$A,逐券汇总!$D5,'逐券逐月(WAVG)'!$B:$B,逐券汇总!$C5) -> -100561 | AI5: =SUMIFS('逐券逐月(WAVG)'!Q:Q,'逐券逐月(WAVG)'!$A:$A,逐券汇总!$D5,'逐券逐月(WAVG)'!$B:$B,逐券汇总!$C5) -> 0 | AJ5: =SUMIFS('逐券逐月(WAVG)'!R:R,'逐券逐月(WAVG)'!$A:$A,逐券汇总!$D5,'逐券逐月(WAVG)'!$B:$B,逐券汇总!$C5) -> 420900 | AK5: =SUMIFS('逐券逐月(WAVG)'!S:S,'逐券逐月(WAVG)'!$A:$A,逐券汇总!$D5,'逐券逐月(WAVG)'!$B:$B,逐券汇总!$C5) -> 61939 | AL5: =SUMIFS('逐券逐月(WAVG)'!T:T,'逐券逐月(WAVG)'!$A:$A,逐券汇总!$D5,'逐券逐月(WAVG)'!$B:$B,逐券汇总!$C5) -> -266939 | AM5: =SUMIFS('逐券逐月(WAVG)'!U:U,'逐券逐月(WAVG)'!$A:$A,逐券汇总!$D5,'逐券逐月(WAVG)'!$B:$B,逐券汇总!$C5) -> 0 | AN5: =SUMIFS('逐券逐月(WAVG)'!V:V,'逐券逐月(WAVG)'!$A:$A,逐券汇总!$D5,'逐券逐月(WAVG)'!$B:$B,逐券汇总!$C5) -> 0
C6: 568 | D6: 泸州老窖 | E6: =AC6-Q6 -> 0 | F6: =AD6-R6 -> 0 | G6: =AE6-S6 -> 1658.92 | H6: =AF6-T6 -> 0 | I6: =AG6-U6 -> 0 | J6: =AH6-V6 -> 0 | K6: =AI6-W6 -> 0 | L6: =AJ6-X6 -> 0 | ... P6: =AN6-AB6 -> 0 | R6: 117000 | S6: -104139.85 | T6: 20594.93 | AC6: =SUMIFS('逐券逐月(WAVG)'!K:K,'逐券逐月(WAVG)'!$A:$A,逐券汇总!$D6) -> 0 | AD6: =SUMIFS('逐券逐月(WAVG)'!L:L,'逐券逐月(WAVG)'!$A:$A,逐券汇总!$D6) -> 117000 | AE6: =SUMIFS('逐券逐月(WAVG)'!M:M,'逐券逐月(WAVG)'!$A:$A,逐券汇总!$D6) -> -102480.93 | AF6: =SUMIFS('逐券逐月(WAVG)'!N:N,'逐券逐月(WAVG)'!$A:$A,逐券汇总!$D6) -> 20594.93 | AG6: =SUMIFS('逐券逐月(WAVG)'!O:O,'逐券逐月(WAVG)'!$A:$A,逐券汇总!$D6) -> 0 | AH6: =SUMIFS('逐券逐月(WAVG)'!P:P,'逐券逐月(WAVG)'!$A:$A,逐券汇总!$D6) -> 0 | AI6: =SUMIFS('逐券逐月(WAVG)'!Q:Q,'逐券逐月(WAVG)'!$A:$A,逐券汇总!$D6) -> 0 | AJ6: =SUMIFS('逐券逐月(WAVG)'!R:R,'逐券逐月(WAVG)'!$A:$A,逐券汇总!$D6) -> 0 | AK6: =SUMIFS('逐券逐月(WAVG)'!S:S,'逐券逐月(WAVG)'!$A:$A,逐券汇总!$D6) -> 0 | AL6: =SUMIFS('逐券逐月(WAVG)'!T:T,'逐券逐月(WAVG)'!$A:$A,逐券汇总!$D6) -> 0 | AM6: =SUMIFS('逐券逐月(WAVG)'!U:U,'逐券逐月(WAVG)'!$A:$A,逐券汇总!$D6) -> 0 | AN6: =SUMIFS('逐券逐月(WAVG)'!V:V,'逐券逐月(WAVG)'!$A:$A,逐券汇总!$D6) -> 0
C7: 858 | D7: 五 粮 液 | E7: =AC7-Q7 -> 1162.24 | F7: =AD7-R7 -> 0 | G7: =AE7-S7 -> 0 | H7: =AF7-T7 -> 0 | I7: =AG7-U7 -> 0 | J7: =AH7-V7 -> 0 | K7: =AI7-W7 -> 0 | L7: =AJ7-X7 -> 0 | ... P7: =AN7-AB7 -> 0 | Q7: -536812.14 | R7: 477168.9 | S7: 0 | AC7: =SUMIFS('逐券逐月(WAVG)'!K:K,'逐券逐月(WAVG)'!$A:$A,逐券汇总!$D7) -> -535649.9 | AD7: =SUMIFS('逐券逐月(WAVG)'!L:L,'逐券逐月(WAVG)'!$A:$A,逐券汇总!$D7) -> 477168.9 | AE7: =SUMIFS('逐券逐月(WAVG)'!M:M,'逐券逐月(WAVG)'!$A:$A,逐券汇总!$D7) -> 0 | AF7: =SUMIFS('逐券逐月(WAVG)'!N:N,'逐券逐月(WAVG)'!$A:$A,逐券汇总!$D7) -> 0 | AG7: =SUMIFS('逐券逐月(WAVG)'!O:O,'逐券逐月(WAVG)'!$A:$A,逐券汇总!$D7) -> 0 | AH7: =SUMIFS('逐券逐月(WAVG)'!P:P,'逐券逐月(WAVG)'!$A:$A,逐券汇总!$D7) -> 0 | AI7: =SUMIFS('逐券逐月(WAVG)'!Q:Q,'逐券逐月(WAVG)'!$A:$A,逐券汇总!$D7) -> 0 | AJ7: =SUMIFS('逐券逐月(WAVG)'!R:R,'逐券逐月(WAVG)'!$A:$A,逐券汇总!$D7) -> 0 | AK7: =SUMIFS('逐券逐月(WAVG)'!S:S,'逐券逐月(WAVG)'!$A:$A,逐券汇总!$D7) -> 0 | AL7: =SUMIFS('逐券逐月(WAVG)'!T:T,'逐券逐月(WAVG)'!$A:$A,逐券汇总!$D7) -> 0 | AM7: =SUMIFS('逐券逐月(WAVG)'!U:U,'逐券逐月(WAVG)'!$A:$A,逐券汇总!$D7) -> 0 | AN7: =SUMIFS('逐券逐月(WAVG)'!V:V,'逐券逐月(WAVG)'!$A:$A,逐券汇总!$D7) -> 0
C8: 2807 | D8: 江阴银行 | E8: =AC8-Q8 -> 0 | F8: =AD8-R8 -> 0 | G8: =AE8-S8 -> 0 | H8: =AF8-T8 -> 0 | I8: =AG8-U8 -> 0 | J8: =AH8-V8 -> 59.29 | K8: =AI8-W8 -> 575.95 | L8: =AJ8-X8 -> -59.29 | ... P8: =AN8-AB8 -> 0 | V8: -16859.29 | W8: -9375.95 | X8: 16859.29 | AC8: =SUMIFS('逐券逐月(WAVG)'!K:K,'逐券逐月(WAVG)'!$A:$A,逐券汇总!$D8) -> 0 | AD8: =SUMIFS('逐券逐月(WAVG)'!L:L,'逐券逐月(WAVG)'!$A:$A,逐券汇总!$D8) -> 0 | AE8: =SUMIFS('逐券逐月(WAVG)'!M:M,'逐券逐月(WAVG)'!$A:$A,逐券汇总!$D8) -> 0 | AF8: =SUMIFS('逐券逐月(WAVG)'!N:N,'逐券逐月(WAVG)'!$A:$A,逐券汇总!$D8) -> 0 | AG8: =SUMIFS('逐券逐月(WAVG)'!O:O,'逐券逐月(WAVG)'!$A:$A,逐券汇总!$D8) -> 0 | AH8: =SUMIFS('逐券逐月(WAVG)'!P:P,'逐券逐月(WAVG)'!$A:$A,逐券汇总!$D8) -> -16800 | AI8: =SUMIFS('逐券逐月(WAVG)'!Q:Q,'逐券逐月(WAVG)'!$A:$A,逐券汇总!$D8) -> -8800 | AJ8: =SUMIFS('逐券逐月(WAVG)'!R:R,'逐券逐月(WAVG)'!$A:$A,逐券汇总!$D8) -> 16800 | AK8: =SUMIFS('逐券逐月(WAVG)'!S:S,'逐券逐月(WAVG)'!$A:$A,逐券汇总!$D8) -> 0 | AL8: =SUMIFS('逐券逐月(WAVG)'!T:T,'逐券逐月(WAVG)'!$A:$A,逐券汇总!$D8) -> 0 | AM8: =SUMIFS('逐券逐月(WAVG)'!U:U,'逐券逐月(WAVG)'!$A:$A,逐券汇总!$D8) -> 0 | AN8: =SUMIFS('逐券逐月(WAVG)'!V:V,'逐券逐月(WAVG)'!$A:$A,逐券汇总!$D8) -> 0
C9: 2839 | D9: 张家港行 | E9: =AC9-Q9 -> 0 | F9: =AD9-R9 -> 0 | G9: =AE9-S9 -> 0 | H9: =AF9-T9 -> 0 | I9: =AG9-U9 -> 0 | J9: =AH9-V9 -> 58.84 | K9: =AI9-W9 -> 566.55 | L9: =AJ9-X9 -> -58.84 | ... P9: =AN9-AB9 -> 0 | V9: -20858.84 | W9: -19366.55 | X9: 20858.84 | AC9: =SUMIFS('逐券逐月(WAVG)'!K:K,'逐券逐月(WAVG)'!$A:$A,逐券汇总!$D9) -> 0 | AD9: =SUMIFS('逐券逐月(WAVG)'!L:L,'逐券逐月(WAVG)'!$A:$A,逐券汇总!$D9) -> 0 | AE9: =SUMIFS('逐券逐月(WAVG)'!M:M,'逐券逐月(WAVG)'!$A:$A,逐券汇总!$D9) -> 0 | AF9: =SUMIFS('逐券逐月(WAVG)'!N:N,'逐券逐月(WAVG)'!$A:$A,逐券汇总!$D9) -> 0 | AG9: =SUMIFS('逐券逐月(WAVG)'!O:O,'逐券逐月(WAVG)'!$A:$A,逐券汇总!$D9) -> 0 | AH9: =SUMIFS('逐券逐月(WAVG)'!P:P,'逐券逐月(WAVG)'!$A:$A,逐券汇总!$D9) -> -20800 | AI9: =SUMIFS('逐券逐月(WAVG)'!Q:Q,'逐券逐月(WAVG)'!$A:$A,逐券汇总!$D9) -> -18800 | AJ9: =SUMIFS('逐券逐月(WAVG)'!R:R,'逐券逐月(WAVG)'!$A:$A,逐券汇总!$D9) -> 20800 | AK9: =SUMIFS('逐券逐月(WAVG)'!S:S,'逐券逐月(WAVG)'!$A:$A,逐券汇总!$D9) -> 0 | AL9: =SUMIFS('逐券逐月(WAVG)'!T:T,'逐券逐月(WAVG)'!$A:$A,逐券汇总!$D9) -> 0 | AM9: =SUMIFS('逐券逐月(WAVG)'!U:U,'逐券逐月(WAVG)'!$A:$A,逐券汇总!$D9) -> 0 | AN9: =SUMIFS('逐券逐月(WAVG)'!V:V,'逐券逐月(WAVG)'!$A:$A,逐券汇总!$D9) -> 0
C10: 600036 | D10: 招商银行 | E10: =AC10-Q10 -> 0 | F10: =AD10-R10 -> 68.6 | G10: =AE10-S10 -> 0 | H10: =AF10-T10 -> 181.6 | I10: =AG10-U10 -> 0 | J10: =AH10-V10 -> 0 | K10: =AI10-W10 -> 0 | L10: =AJ10-X10 -> 0 | ... P10: =AN10-AB10 -> 0 | R10: -498025.6 | T10: -30594.6 | V10: 142500 | X10: -262500 | Z10: -65000 | AB10: 122500 | AC10: =SUMIFS('逐券逐月(WAVG)'!K:K,'逐券逐月(WAVG)'!$A:$A,逐券汇总!$D10) -> 0 | AD10: =SUMIFS('逐券逐月(WAVG)'!L:L,'逐券逐月(WAVG)'!$A:$A,逐券汇总!$D10) -> -497957 | AE10: =SUMIFS('逐券逐月(WAVG)'!M:M,'逐券逐月(WAVG)'!$A:$A,逐券汇总!$D10) -> 0 | AF10: =SUMIFS('逐券逐月(WAVG)'!N:N,'逐券逐月(WAVG)'!$A:$A,逐券汇总!$D10) -> -30413 | AG10: =SUMIFS('逐券逐月(WAVG)'!O:O,'逐券逐月(WAVG)'!$A:$A,逐券汇总!$D10) -> 0 | AH10: =SUMIFS('逐券逐月(WAVG)'!P:P,'逐券逐月(WAVG)'!$A:$A,逐券汇总!$D10) -> 142500 | AI10: =SUMIFS('逐券逐月(WAVG)'!Q:Q,'逐券逐月(WAVG)'!$A:$A,逐券汇总!$D10) -> 0 | AJ10: =SUMIFS('逐券逐月(WAVG)'!R:R,'逐券逐月(WAVG)'!$A:$A,逐券汇总!$D10) -> -262500 | AK10: =SUMIFS('逐券逐月(WAVG)'!S:S,'逐券逐月(WAVG)'!$A:$A,逐券汇总!$D10) -> 0 | AL10: =SUMIFS('逐券逐月(WAVG)'!T:T,'逐券逐月(WAVG)'!$A:$A,逐券汇总!$D10) -> -65000 | AM10: =SUMIFS('逐券逐月(WAVG)'!U:U,'逐券逐月(WAVG)'!$A:$A,逐券汇总!$D10) -> 0 | AN10: =SUMIFS('逐券逐月(WAVG)'!V:V,'逐券逐月(WAVG)'!$A:$A,逐券汇总!$D10) -> 122500
C11: 600519 | D11: 贵州茅台 | E11: =AC11-Q11 -> 76.02 | F11: =AD11-R11 -> 0 | G11: =AE11-S11 -> 0 | H11: =AF11-T11 -> 0 | I11: =AG11-U11 -> 0 | J11: =AH11-V11 -> 0 | K11: =AI11-W11 -> 0 | L11: =AJ11-X11 -> 0 | ... P11: =AN11-AB11 -> 0 | Q11: -13636.92 | R11: 10592.9 | S11: 0 | AC11: =SUMIFS('逐券逐月(WAVG)'!K:K,'逐券逐月(WAVG)'!$A:$A,逐券汇总!$D11) -> -13560.9 | AD11: =SUMIFS('逐券逐月(WAVG)'!L:L,'逐券逐月(WAVG)'!$A:$A,逐券汇总!$D11) -> 10592.9 | AE11: =SUMIFS('逐券逐月(WAVG)'!M:M,'逐券逐月(WAVG)'!$A:$A,逐券汇总!$D11) -> 0 | AF11: =SUMIFS('逐券逐月(WAVG)'!N:N,'逐券逐月(WAVG)'!$A:$A,逐券汇总!$D11) -> 0 | AG11: =SUMIFS('逐券逐月(WAVG)'!O:O,'逐券逐月(WAVG)'!$A:$A,逐券汇总!$D11) -> 0 | AH11: =SUMIFS('逐券逐月(WAVG)'!P:P,'逐券逐月(WAVG)'!$A:$A,逐券汇总!$D11) -> 0 | AI11: =SUMIFS('逐券逐月(WAVG)'!Q:Q,'逐券逐月(WAVG)'!$A:$A,逐券汇总!$D11) -> 0 | AJ11: =SUMIFS('逐券逐月(WAVG)'!R:R,'逐券逐月(WAVG)'!$A:$A,逐券汇总!$D11) -> 0 | AK11: =SUMIFS('逐券逐月(WAVG)'!S:S,'逐券逐月(WAVG)'!$A:$A,逐券汇总!$D11) -> 0 | AL11: =SUMIFS('逐券逐月(WAVG)'!T:T,'逐券逐月(WAVG)'!$A:$A,逐券汇总!$D11) -> 0 | AM11: =SUMIFS('逐券逐月(WAVG)'!U:U,'逐券逐月(WAVG)'!$A:$A,逐券汇总!$D11) -> 0 | AN11: =SUMIFS('逐券逐月(WAVG)'!V:V,'逐券逐月(WAVG)'!$A:$A,逐券汇总!$D11) -> 0
C12: 600690 | D12: 海尔智家 | E12: =AC12-Q12 -> 0 | F12: =AD12-R12 -> 0 | G12: =AE12-S12 -> 0 | H12: =AF12-T12 -> 0 | I12: =AG12-U12 -> 0 | J12: =AH12-V12 -> 0 | K12: =AI12-W12 -> 0 | L12: =AJ12-X12 -> 135.52 | ... P12: =AN12-AB12 -> 3564.84 | X12: 36454.48 | Z12: -65000 | AB12: -74564.84 | AC12: =SUMIFS('逐券逐月(WAVG)'!K:K,'逐券逐月(WAVG)'!$A:$A,逐券汇总!$D12,'逐券逐月(WAVG)'!$B:$B,逐券汇总!$C12) -> 0 | AD12: =SUMIFS('逐券逐月(WAVG)'!L:L,'逐券逐月(WAVG)'!$A:$A,逐券汇总!$D12,'逐券逐月(WAVG)'!$B:$B,逐券汇总!$C12) -> 0 | AE12: =SUMIFS('逐券逐月(WAVG)'!M:M,'逐券逐月(WAVG)'!$A:$A,逐券汇总!$D12,'逐券逐月(WAVG)'!$B:$B,逐券汇总!$C12) -> 0 | AF12: =SUMIFS('逐券逐月(WAVG)'!N:N,'逐券逐月(WAVG)'!$A:$A,逐券汇总!$D12,'逐券逐月(WAVG)'!$B:$B,逐券汇总!$C12) -> 0 | AG12: =SUMIFS('逐券逐月(WAVG)'!O:O,'逐券逐月(WAVG)'!$A:$A,逐券汇总!$D12,'逐券逐月(WAVG)'!$B:$B,逐券汇总!$C12) -> 0 | AH12: =SUMIFS('逐券逐月(WAVG)'!P:P,'逐券逐月(WAVG)'!$A:$A,逐券汇总!$D12,'逐券逐月(WAVG)'!$B:$B,逐券汇总!$C12) -> 0 | AI12: =SUMIFS('逐券逐月(WAVG)'!Q:Q,'逐券逐月(WAVG)'!$A:$A,逐券汇总!$D12,'逐券逐月(WAVG)'!$B:$B,逐券汇总!$C12) -> 0 | AJ12: =SUMIFS('逐券逐月(WAVG)'!R:R,'逐券逐月(WAVG)'!$A:$A,逐券汇总!$D12,'逐券逐月(WAVG)'!$B:$B,逐券汇总!$C12) -> 36590 | AK12: =SUMIFS('逐券逐月(WAVG)'!S:S,'逐券逐月(WAVG)'!$A:$A,逐券汇总!$D12,'逐券逐月(WAVG)'!$B:$B,逐券汇总!$C12) -> 0 | AL12: =SUMIFS('逐券逐月(WAVG)'!T:T,'逐券逐月(WAVG)'!$A:$A,逐券汇总!$D12,'逐券逐月(WAVG)'!$B:$B,逐券汇总!$C12) -> -65000 | AM12: =SUMIFS('逐券逐月(WAVG)'!U:U,'逐券逐月(WAVG)'!$A:$A,逐券汇总!$D12,'逐券逐月(WAVG)'!$B:$B,逐券汇总!$C12) -> 0 | AN12: =SUMIFS('逐券逐月(WAVG)'!V:V,'逐券逐月(WAVG)'!$A:$A,逐券汇总!$D12,'逐券逐月(WAVG)'!$B:$B,逐券汇总!$C12) -> -71000
C13: 600809 | D13: 山西汾酒 | E13: =AC13-Q13 -> 0 | F13: =AD13-R13 -> 0 | G13: =AE13-S13 -> 1529.13 | H13: =AF13-T13 -> 0 | I13: =AG13-U13 -> 0 | J13: =AH13-V13 -> 0 | K13: =AI13-W13 -> 0 | L13: =AJ13-X13 -> 0 | ... P13: =AN13-AB13 -> 0 | R13: -11040 | S13: -160016 | T13: 132966.87 | AC13: =SUMIFS('逐券逐月(WAVG)'!K:K,'逐券逐月(WAVG)'!$A:$A,逐券汇总!$D13) -> 0 | AD13: =SUMIFS('逐券逐月(WAVG)'!L:L,'逐券逐月(WAVG)'!$A:$A,逐券汇总!$D13) -> -11040 | AE13: =SUMIFS('逐券逐月(WAVG)'!M:M,'逐券逐月(WAVG)'!$A:$A,逐券汇总!$D13) -> -158486.87 | AF13: =SUMIFS('逐券逐月(WAVG)'!N:N,'逐券逐月(WAVG)'!$A:$A,逐券汇总!$D13) -> 132966.87 | AG13: =SUMIFS('逐券逐月(WAVG)'!O:O,'逐券逐月(WAVG)'!$A:$A,逐券汇总!$D13) -> 0 | AH13: =SUMIFS('逐券逐月(WAVG)'!P:P,'逐券逐月(WAVG)'!$A:$A,逐券汇总!$D13) -> 0 | AI13: =SUMIFS('逐券逐月(WAVG)'!Q:Q,'逐券逐月(WAVG)'!$A:$A,逐券汇总!$D13) -> 0 | AJ13: =SUMIFS('逐券逐月(WAVG)'!R:R,'逐券逐月(WAVG)'!$A:$A,逐券汇总!$D13) -> 0 | AK13: =SUMIFS('逐券逐月(WAVG)'!S:S,'逐券逐月(WAVG)'!$A:$A,逐券汇总!$D13) -> 0 | AL13: =SUMIFS('逐券逐月(WAVG)'!T:T,'逐券逐月(WAVG)'!$A:$A,逐券汇总!$D13) -> 0 | AM13: =SUMIFS('逐券逐月(WAVG)'!U:U,'逐券逐月(WAVG)'!$A:$A,逐券汇总!$D13) -> 0 | AN13: =SUMIFS('逐券逐月(WAVG)'!V:V,'逐券逐月(WAVG)'!$A:$A,逐券汇总!$D13) -> 0
C14: 600887 | D14: XD伊利股 | E14: =AC14-Q14 -> 0 | F14: =AD14-R14 -> 0 | G14: =AE14-S14 -> 0 | H14: =AF14-T14 -> 0 | I14: =AG14-U14 -> 0 | J14: =AH14-V14 -> 0 | K14: =AI14-W14 -> 0 | L14: =AJ14-X14 -> 0 | ... P14: =AN14-AB14 -> 0 | AA14: 277.12 | AC14: =SUMIFS('逐券逐月(WAVG)'!K:K,'逐券逐月(WAVG)'!$A:$A,逐券汇总!$D14) -> 0 | AD14: =SUMIFS('逐券逐月(WAVG)'!L:L,'逐券逐月(WAVG)'!$A:$A,逐券汇总!$D14) -> 0 | AE14: =SUMIFS('逐券逐月(WAVG)'!M:M,'逐券逐月(WAVG)'!$A:$A,逐券汇总!$D14) -> 0 | AF14: =SUMIFS('逐券逐月(WAVG)'!N:N,'逐券逐月(WAVG)'!$A:$A,逐券汇总!$D14) -> 0 | AG14: =SUMIFS('逐券逐月(WAVG)'!O:O,'逐券逐月(WAVG)'!$A:$A,逐券汇总!$D14) -> 0 | AH14: =SUMIFS('逐券逐月(WAVG)'!P:P,'逐券逐月(WAVG)'!$A:$A,逐券汇总!$D14) -> 0 | AI14: =SUMIFS('逐券逐月(WAVG)'!Q:Q,'逐券逐月(WAVG)'!$A:$A,逐券汇总!$D14) -> 0 | AJ14: =SUMIFS('逐券逐月(WAVG)'!R:R,'逐券逐月(WAVG)'!$A:$A,逐券汇总!$D14) -> 0 | AK14: =SUMIFS('逐券逐月(WAVG)'!S:S,'逐券逐月(WAVG)'!$A:$A,逐券汇总!$D14) -> 0 | AL14: =SUMIFS('逐券逐月(WAVG)'!T:T,'逐券逐月(WAVG)'!$A:$A,逐券汇总!$D14) -> 0 | AM14: =SUMIFS('逐券逐月(WAVG)'!U:U,'逐券逐月(WAVG)'!$A:$A,逐券汇总!$D14) -> 0 | AN14: =SUMIFS('逐券逐月(WAVG)'!V:V,'逐券逐月(WAVG)'!$A:$A,逐券汇总!$D14) -> 0
D15: 伊利股份 | E15: =AC15-Q15 -> 0 | F15: =AD15-R15 -> 0 | G15: =AE15-S15 -> 0 | H15: =AF15-T15 -> 185.4 | I15: =AG15-U15 -> 0 | J15: =AH15-V15 -> 149.87 | K15: =AI15-W15 -> 0 | L15: =AJ15-X15 -> 84.27 | ... P15: =AN15-AB15 -> -40483.91 | T15: -25485.4 | V15: 64150.13 | X15: 281415.73 | Z15: -135000 | AB15: -347016.09 | AC15: =SUMIFS('逐券逐月(WAVG)'!K:K,'逐券逐月(WAVG)'!$A:$A,逐券汇总!$D15) -> 0 | AD15: =SUMIFS('逐券逐月(WAVG)'!L:L,'逐券逐月(WAVG)'!$A:$A,逐券汇总!$D15) -> 0 | AE15: =SUMIFS('逐券逐月(WAVG)'!M:M,'逐券逐月(WAVG)'!$A:$A,逐券汇总!$D15) -> 0 | AF15: =SUMIFS('逐券逐月(WAVG)'!N:N,'逐券逐月(WAVG)'!$A:$A,逐券汇总!$D15) -> -25300 | AG15: =SUMIFS('逐券逐月(WAVG)'!O:O,'逐券逐月(WAVG)'!$A:$A,逐券汇总!$D15) -> 0 | AH15: =SUMIFS('逐券逐月(WAVG)'!P:P,'逐券逐月(WAVG)'!$A:$A,逐券汇总!$D15) -> 64300 | AI15: =SUMIFS('逐券逐月(WAVG)'!Q:Q,'逐券逐月(WAVG)'!$A:$A,逐券汇总!$D15) -> 0 | AJ15: =SUMIFS('逐券逐月(WAVG)'!R:R,'逐券逐月(WAVG)'!$A:$A,逐券汇总!$D15) -> 281500 | AK15: =SUMIFS('逐券逐月(WAVG)'!S:S,'逐券逐月(WAVG)'!$A:$A,逐券汇总!$D15) -> 0 | AL15: =SUMIFS('逐券逐月(WAVG)'!T:T,'逐券逐月(WAVG)'!$A:$A,逐券汇总!$D15) -> -135000 | AM15: =SUMIFS('逐券逐月(WAVG)'!U:U,'逐券逐月(WAVG)'!$A:$A,逐券汇总!$D15) -> 0 | AN15: =SUMIFS('逐券逐月(WAVG)'!V:V,'逐券逐月(WAVG)'!$A:$A,逐券汇总!$D15) -> -387500
C16: 600908 | D16: 无锡银行 | E16: =AC16-Q16 -> 0 | F16: =AD16-R16 -> 0 | G16: =AE16-S16 -> 0 | H16: =AF16-T16 -> 0 | I16: =AG16-U16 -> 0 | J16: =AH16-V16 -> 76.21 | K16: =AI16-W16 -> 716.04 | L16: =AJ16-X16 -> -76.21 | ... P16: =AN16-AB16 -> 0 | V16: -41356.21 | W16: -55996.04 | X16: 41356.21 | AC16: =SUMIFS('逐券逐月(WAVG)'!K:K,'逐券逐月(WAVG)'!$A:$A,逐券汇总!$D16) -> 0 | AD16: =SUMIFS('逐券逐月(WAVG)'!L:L,'逐券逐月(WAVG)'!$A:$A,逐券汇总!$D16) -> 0 | AE16: =SUMIFS('逐券逐月(WAVG)'!M:M,'逐券逐月(WAVG)'!$A:$A,逐券汇总!$D16) -> 0 | AF16: =SUMIFS('逐券逐月(WAVG)'!N:N,'逐券逐月(WAVG)'!$A:$A,逐券汇总!$D16) -> 0 | AG16: =SUMIFS('逐券逐月(WAVG)'!O:O,'逐券逐月(WAVG)'!$A:$A,逐券汇总!$D16) -> 0 | AH16: =SUMIFS('逐券逐月(WAVG)'!P:P,'逐券逐月(WAVG)'!$A:$A,逐券汇总!$D16) -> -41280 | AI16: =SUMIFS('逐券逐月(WAVG)'!Q:Q,'逐券逐月(WAVG)'!$A:$A,逐券汇总!$D16) -> -55280 | AJ16: =SUMIFS('逐券逐月(WAVG)'!R:R,'逐券逐月(WAVG)'!$A:$A,逐券汇总!$D16) -> 41280 | AK16: =SUMIFS('逐券逐月(WAVG)'!S:S,'逐券逐月(WAVG)'!$A:$A,逐券汇总!$D16) -> 0 | AL16: =SUMIFS('逐券逐月(WAVG)'!T:T,'逐券逐月(WAVG)'!$A:$A,逐券汇总!$D16) -> 0 | AM16: =SUMIFS('逐券逐月(WAVG)'!U:U,'逐券逐月(WAVG)'!$A:$A,逐券汇总!$D16) -> 0 | AN16: =SUMIFS('逐券逐月(WAVG)'!V:V,'逐券逐月(WAVG)'!$A:$A,逐券汇总!$D16) -> 0
C17: 600919 | D17: 江苏银行 | E17: =AC17-Q17 -> 0 | F17: =AD17-R17 -> 0 | G17: =AE17-S17 -> 0 | H17: =AF17-T17 -> 120.63 | I17: =AG17-U17 -> 0 | J17: =AH17-V17 -> 0 | K17: =AI17-W17 -> 1225.13 | L17: =AJ17-X17 -> -120.63 | ... P17: =AN17-AB17 -> 0 | T17: -20820.63 | V17: 102600 | W17: 73474.87 | X17: -81779.37 | AC17: =SUMIFS('逐券逐月(WAVG)'!K:K,'逐券逐月(WAVG)'!$A:$A,逐券汇总!$D17) -> 0 | AD17: =SUMIFS('逐券逐月(WAVG)'!L:L,'逐券逐月(WAVG)'!$A:$A,逐券汇总!$D17) -> 0 | AE17: =SUMIFS('逐券逐月(WAVG)'!M:M,'逐券逐月(WAVG)'!$A:$A,逐券汇总!$D17) -> 0 | AF17: =SUMIFS('逐券逐月(WAVG)'!N:N,'逐券逐月(WAVG)'!$A:$A,逐券汇总!$D17) -> -20700 | AG17: =SUMIFS('逐券逐月(WAVG)'!O:O,'逐券逐月(WAVG)'!$A:$A,逐券汇总!$D17) -> 0 | AH17: =SUMIFS('逐券逐月(WAVG)'!P:P,'逐券逐月(WAVG)'!$A:$A,逐券汇总!$D17) -> 102600 | AI17: =SUMIFS('逐券逐月(WAVG)'!Q:Q,'逐券逐月(WAVG)'!$A:$A,逐券汇总!$D17) -> 74700 | AJ17: =SUMIFS('逐券逐月(WAVG)'!R:R,'逐券逐月(WAVG)'!$A:$A,逐券汇总!$D17) -> -81900 | AK17: =SUMIFS('逐券逐月(WAVG)'!S:S,'逐券逐月(WAVG)'!$A:$A,逐券汇总!$D17) -> 0 | AL17: =SUMIFS('逐券逐月(WAVG)'!T:T,'逐券逐月(WAVG)'!$A:$A,逐券汇总!$D17) -> 0 | AM17: =SUMIFS('逐券逐月(WAVG)'!U:U,'逐券逐月(WAVG)'!$A:$A,逐券汇总!$D17) -> 0 | AN17: =SUMIFS('逐券逐月(WAVG)'!V:V,'逐券逐月(WAVG)'!$A:$A,逐券汇总!$D17) -> 0
C18: 601009 | D18: 南京银行 | E18: =AC18-Q18 -> 0 | F18: =AD18-R18 -> 0 | G18: =AE18-S18 -> 1902.09 | H18: =AF18-T18 -> 0 | I18: =AG18-U18 -> 0 | J18: =AH18-V18 -> 0 | K18: =AI18-W18 -> 0 | L18: =AJ18-X18 -> 0 | ... P18: =AN18-AB18 -> 0 | R18: -270000 | S18: 37807.46 | T18: 173290.45 | AC18: =SUMIFS('逐券逐月(WAVG)'!K:K,'逐券逐月(WAVG)'!$A:$A,逐券汇总!$D18) -> 0 | AD18: =SUMIFS('逐券逐月(WAVG)'!L:L,'逐券逐月(WAVG)'!$A:$A,逐券汇总!$D18) -> -270000 | AE18: =SUMIFS('逐券逐月(WAVG)'!M:M,'逐券逐月(WAVG)'!$A:$A,逐券汇总!$D18) -> 39709.55 | AF18: =SUMIFS('逐券逐月(WAVG)'!N:N,'逐券逐月(WAVG)'!$A:$A,逐券汇总!$D18) -> 173290.45 | AG18: =SUMIFS('逐券逐月(WAVG)'!O:O,'逐券逐月(WAVG)'!$A:$A,逐券汇总!$D18) -> 0 | AH18: =SUMIFS('逐券逐月(WAVG)'!P:P,'逐券逐月(WAVG)'!$A:$A,逐券汇总!$D18) -> 0 | AI18: =SUMIFS('逐券逐月(WAVG)'!Q:Q,'逐券逐月(WAVG)'!$A:$A,逐券汇总!$D18) -> 0 | AJ18: =SUMIFS('逐券逐月(WAVG)'!R:R,'逐券逐月(WAVG)'!$A:$A,逐券汇总!$D18) -> 0 | AK18: =SUMIFS('逐券逐月(WAVG)'!S:S,'逐券逐月(WAVG)'!$A:$A,逐券汇总!$D18) -> 0 | AL18: =SUMIFS('逐券逐月(WAVG)'!T:T,'逐券逐月(WAVG)'!$A:$A,逐券汇总!$D18) -> 0 | AM18: =SUMIFS('逐券逐月(WAVG)'!U:U,'逐券逐月(WAVG)'!$A:$A,逐券汇总!$D18) -> 0 | AN18: =SUMIFS('逐券逐月(WAVG)'!V:V,'逐券逐月(WAVG)'!$A:$A,逐券汇总!$D18) -> 0
C19: 601098 | D19: 中南传媒 | E19: =AC19-Q19 -> 0 | F19: =AD19-R19 -> 149.36 | G19: =AE19-S19 -> 0 | H19: =AF19-T19 -> 0 | I19: =AG19-U19 -> 0 | J19: =AH19-V19 -> 0 | K19: =AI19-W19 -> 0 | L19: =AJ19-X19 -> 0 | ... P19: =AN19-AB19 -> 0 | R19: -188149.36 | T19: 35000 | V19: -60000 | X19: 190000 | Z19: -240000 | AB19: 70000 | AC19: =SUMIFS('逐券逐月(WAVG)'!K:K,'逐券逐月(WAVG)'!$A:$A,逐券汇总!$D19) -> 0 | AD19: =SUMIFS('逐券逐月(WAVG)'!L:L,'逐券逐月(WAVG)'!$A:$A,逐券汇总!$D19) -> -188000 | AE19: =SUMIFS('逐券逐月(WAVG)'!M:M,'逐券逐月(WAVG)'!$A:$A,逐券汇总!$D19) -> 0 | AF19: =SUMIFS('逐券逐月(WAVG)'!N:N,'逐券逐月(WAVG)'!$A:$A,逐券汇总!$D19) -> 35000 | AG19: =SUMIFS('逐券逐月(WAVG)'!O:O,'逐券逐月(WAVG)'!$A:$A,逐券汇总!$D19) -> 0 | AH19: =SUMIFS('逐券逐月(WAVG)'!P:P,'逐券逐月(WAVG)'!$A:$A,逐券汇总!$D19) -> -60000 | AI19: =SUMIFS('逐券逐月(WAVG)'!Q:Q,'逐券逐月(WAVG)'!$A:$A,逐券汇总!$D19) -> 0 | AJ19: =SUMIFS('逐券逐月(WAVG)'!R:R,'逐券逐月(WAVG)'!$A:$A,逐券汇总!$D19) -> 190000 | AK19: =SUMIFS('逐券逐月(WAVG)'!S:S,'逐券逐月(WAVG)'!$A:$A,逐券汇总!$D19) -> 0 | AL19: =SUMIFS('逐券逐月(WAVG)'!T:T,'逐券逐月(WAVG)'!$A:$A,逐券汇总!$D19) -> -240000 | AM19: =SUMIFS('逐券逐月(WAVG)'!U:U,'逐券逐月(WAVG)'!$A:$A,逐券汇总!$D19) -> 0 | AN19: =SUMIFS('逐券逐月(WAVG)'!V:V,'逐券逐月(WAVG)'!$A:$A,逐券汇总!$D19) -> 70000
C20: 601166 | D20: 兴业银行 | E20: =AC20-Q20 -> 0 | F20: =AD20-R20 -> 59.88 | G20: =AE20-S20 -> 0 | H20: =AF20-T20 -> 182.86 | I20: =AG20-U20 -> 0 | J20: =AH20-V20 -> 0 | K20: =AI20-W20 -> 0 | L20: =AJ20-X20 -> 0 | ... P20: =AN20-AB20 -> 0 | R20: -705519.88 | T20: -240980.86 | V20: 255000 | X20: -445000 | Z20: 285000 | AB20: 20000 | AC20: =SUMIFS('逐券逐月(WAVG)'!K:K,'逐券逐月(WAVG)'!$A:$A,逐券汇总!$D20) -> 0 | AD20: =SUMIFS('逐券逐月(WAVG)'!L:L,'逐券逐月(WAVG)'!$A:$A,逐券汇总!$D20) -> -705460 | AE20: =SUMIFS('逐券逐月(WAVG)'!M:M,'逐券逐月(WAVG)'!$A:$A,逐券汇总!$D20) -> 0 | AF20: =SUMIFS('逐券逐月(WAVG)'!N:N,'逐券逐月(WAVG)'!$A:$A,逐券汇总!$D20) -> -240798 | AG20: =SUMIFS('逐券逐月(WAVG)'!O:O,'逐券逐月(WAVG)'!$A:$A,逐券汇总!$D20) -> 0 | AH20: =SUMIFS('逐券逐月(WAVG)'!P:P,'逐券逐月(WAVG)'!$A:$A,逐券汇总!$D20) -> 255000 | AI20: =SUMIFS('逐券逐月(WAVG)'!Q:Q,'逐券逐月(WAVG)'!$A:$A,逐券汇总!$D20) -> 0 | AJ20: =SUMIFS('逐券逐月(WAVG)'!R:R,'逐券逐月(WAVG)'!$A:$A,逐券汇总!$D20) -> -445000 | AK20: =SUMIFS('逐券逐月(WAVG)'!S:S,'逐券逐月(WAVG)'!$A:$A,逐券汇总!$D20) -> 0 | AL20: =SUMIFS('逐券逐月(WAVG)'!T:T,'逐券逐月(WAVG)'!$A:$A,逐券汇总!$D20) -> 285000 | AM20: =SUMIFS('逐券逐月(WAVG)'!U:U,'逐券逐月(WAVG)'!$A:$A,逐券汇总!$D20) -> 0 | AN20: =SUMIFS('逐券逐月(WAVG)'!V:V,'逐券逐月(WAVG)'!$A:$A,逐券汇总!$D20) -> 20000
C21: 601169 | D21: 北京银行 | E21: =AC21-Q21 -> 0 | F21: =AD21-R21 -> 0 | G21: =AE21-S21 -> 0 | H21: =AF21-T21 -> 0 | I21: =AG21-U21 -> 0 | J21: =AH21-V21 -> 0 | K21: =AI21-W21 -> 0 | L21: =AJ21-X21 -> 0 | ... P21: =AN21-AB21 -> 3098.65 | R21: -270000 | T21: 135000 | V21: 180000 | X21: -315000 | Z21: -315000 | AB21: 41901.35 | AC21: =SUMIFS('逐券逐月(WAVG)'!K:K,'逐券逐月(WAVG)'!$A:$A,逐券汇总!$D21) -> 0 | AD21: =SUMIFS('逐券逐月(WAVG)'!L:L,'逐券逐月(WAVG)'!$A:$A,逐券汇总!$D21) -> -270000 | AE21: =SUMIFS('逐券逐月(WAVG)'!M:M,'逐券逐月(WAVG)'!$A:$A,逐券汇总!$D21) -> 0 | AF21: =SUMIFS('逐券逐月(WAVG)'!N:N,'逐券逐月(WAVG)'!$A:$A,逐券汇总!$D21) -> 135000 | AG21: =SUMIFS('逐券逐月(WAVG)'!O:O,'逐券逐月(WAVG)'!$A:$A,逐券汇总!$D21) -> 0 | AH21: =SUMIFS('逐券逐月(WAVG)'!P:P,'逐券逐月(WAVG)'!$A:$A,逐券汇总!$D21) -> 180000 | AI21: =SUMIFS('逐券逐月(WAVG)'!Q:Q,'逐券逐月(WAVG)'!$A:$A,逐券汇总!$D21) -> 0 | AJ21: =SUMIFS('逐券逐月(WAVG)'!R:R,'逐券逐月(WAVG)'!$A:$A,逐券汇总!$D21) -> -315000 | AK21: =SUMIFS('逐券逐月(WAVG)'!S:S,'逐券逐月(WAVG)'!$A:$A,逐券汇总!$D21) -> 0 | AL21: =SUMIFS('逐券逐月(WAVG)'!T:T,'逐券逐月(WAVG)'!$A:$A,逐券汇总!$D21) -> -315000 | AM21: =SUMIFS('逐券逐月(WAVG)'!U:U,'逐券逐月(WAVG)'!$A:$A,逐券汇总!$D21) -> 0 | AN21: =SUMIFS('逐券逐月(WAVG)'!V:V,'逐券逐月(WAVG)'!$A:$A,逐券汇总!$D21) -> 45000
C22: 601577 | D22: 长沙银行 | E22: =AC22-Q22 -> 0 | F22: =AD22-R22 -> 0 | G22: =AE22-S22 -> 0 | H22: =AF22-T22 -> 0 | I22: =AG22-U22 -> 0 | J22: =AH22-V22 -> 63.15 | K22: =AI22-W22 -> 596.24 | L22: =AJ22-X22 -> -63.15 | ... P22: =AN22-AB22 -> 0 | V22: -21663.15 | W22: -40196.24 | X22: 21663.15 | AC22: =SUMIFS('逐券逐月(WAVG)'!K:K,'逐券逐月(WAVG)'!$A:$A,逐券汇总!$D22) -> 0 | AD22: =SUMIFS('逐券逐月(WAVG)'!L:L,'逐券逐月(WAVG)'!$A:$A,逐券汇总!$D22) -> 0 | AE22: =SUMIFS('逐券逐月(WAVG)'!M:M,'逐券逐月(WAVG)'!$A:$A,逐券汇总!$D22) -> 0 | AF22: =SUMIFS('逐券逐月(WAVG)'!N:N,'逐券逐月(WAVG)'!$A:$A,逐券汇总!$D22) -> 0 | AG22: =SUMIFS('逐券逐月(WAVG)'!O:O,'逐券逐月(WAVG)'!$A:$A,逐券汇总!$D22) -> 0 | AH22: =SUMIFS('逐券逐月(WAVG)'!P:P,'逐券逐月(WAVG)'!$A:$A,逐券汇总!$D22) -> -21600 | AI22: =SUMIFS('逐券逐月(WAVG)'!Q:Q,'逐券逐月(WAVG)'!$A:$A,逐券汇总!$D22) -> -39600 | AJ22: =SUMIFS('逐券逐月(WAVG)'!R:R,'逐券逐月(WAVG)'!$A:$A,逐券汇总!$D22) -> 21600 | AK22: =SUMIFS('逐券逐月(WAVG)'!S:S,'逐券逐月(WAVG)'!$A:$A,逐券汇总!$D22) -> 0 | AL22: =SUMIFS('逐券逐月(WAVG)'!T:T,'逐券逐月(WAVG)'!$A:$A,逐券汇总!$D22) -> 0 | AM22: =SUMIFS('逐券逐月(WAVG)'!U:U,'逐券逐月(WAVG)'!$A:$A,逐券汇总!$D22) -> 0 | AN22: =SUMIFS('逐券逐月(WAVG)'!V:V,'逐券逐月(WAVG)'!$A:$A,逐券汇总!$D22) -> 0
C23: 601818 | D23: 光大银行 | E23: =AC23-Q23 -> 0 | F23: =AD23-R23 -> 0 | G23: =AE23-S23 -> 0 | H23: =AF23-T23 -> 0 | I23: =AG23-U23 -> 0 | J23: =AH23-V23 -> 0 | K23: =AI23-W23 -> 0 | L23: =AJ23-X23 -> 0 | ... P23: =AN23-AB23 -> 0 | R23: -459000 | T23: -216000 | V23: -81000 | X23: -243000 | Z23: -54000 | AB23: 54000 | AC23: =SUMIFS('逐券逐月(WAVG)'!K:K,'逐券逐月(WAVG)'!$A:$A,逐券汇总!$D23) -> 0 | AD23: =SUMIFS('逐券逐月(WAVG)'!L:L,'逐券逐月(WAVG)'!$A:$A,逐券汇总!$D23) -> -459000 | AE23: =SUMIFS('逐券逐月(WAVG)'!M:M,'逐券逐月(WAVG)'!$A:$A,逐券汇总!$D23) -> 0 | AF23: =SUMIFS('逐券逐月(WAVG)'!N:N,'逐券逐月(WAVG)'!$A:$A,逐券汇总!$D23) -> -216000 | AG23: =SUMIFS('逐券逐月(WAVG)'!O:O,'逐券逐月(WAVG)'!$A:$A,逐券汇总!$D23) -> 0 | AH23: =SUMIFS('逐券逐月(WAVG)'!P:P,'逐券逐月(WAVG)'!$A:$A,逐券汇总!$D23) -> -81000 | AI23: =SUMIFS('逐券逐月(WAVG)'!Q:Q,'逐券逐月(WAVG)'!$A:$A,逐券汇总!$D23) -> 0 | AJ23: =SUMIFS('逐券逐月(WAVG)'!R:R,'逐券逐月(WAVG)'!$A:$A,逐券汇总!$D23) -> -243000 | AK23: =SUMIFS('逐券逐月(WAVG)'!S:S,'逐券逐月(WAVG)'!$A:$A,逐券汇总!$D23) -> 0 | AL23: =SUMIFS('逐券逐月(WAVG)'!T:T,'逐券逐月(WAVG)'!$A:$A,逐券汇总!$D23) -> -54000 | AM23: =SUMIFS('逐券逐月(WAVG)'!U:U,'逐券逐月(WAVG)'!$A:$A,逐券汇总!$D23) -> 0 | AN23: =SUMIFS('逐券逐月(WAVG)'!V:V,'逐券逐月(WAVG)'!$A:$A,逐券汇总!$D23) -> 54000
C24: 601825 | D24: 沪农商行 | E24: =AC24-Q24 -> 0 | F24: =AD24-R24 -> 0 | G24: =AE24-S24 -> 0 | H24: =AF24-T24 -> 82.84 | I24: =AG24-U24 -> 0 | J24: =AH24-V24 -> 0 | K24: =AI24-W24 -> 861.48 | L24: =AJ24-X24 -> -82.84 | ... P24: =AN24-AB24 -> 0 | T24: -27982.84 | V24: 105000 | W24: 89738.52 | X24: -77017.16 | AC24: =SUMIFS('逐券逐月(WAVG)'!K:K,'逐券逐月(WAVG)'!$A:$A,逐券汇总!$D24) -> 0 | AD24: =SUMIFS('逐券逐月(WAVG)'!L:L,'逐券逐月(WAVG)'!$A:$A,逐券汇总!$D24) -> 0 | AE24: =SUMIFS('逐券逐月(WAVG)'!M:M,'逐券逐月(WAVG)'!$A:$A,逐券汇总!$D24) -> 0 | AF24: =SUMIFS('逐券逐月(WAVG)'!N:N,'逐券逐月(WAVG)'!$A:$A,逐券汇总!$D24) -> -27900 | AG24: =SUMIFS('逐券逐月(WAVG)'!O:O,'逐券逐月(WAVG)'!$A:$A,逐券汇总!$D24) -> 0 | AH24: =SUMIFS('逐券逐月(WAVG)'!P:P,'逐券逐月(WAVG)'!$A:$A,逐券汇总!$D24) -> 105000 | AI24: =SUMIFS('逐券逐月(WAVG)'!Q:Q,'逐券逐月(WAVG)'!$A:$A,逐券汇总!$D24) -> 90600 | AJ24: =SUMIFS('逐券逐月(WAVG)'!R:R,'逐券逐月(WAVG)'!$A:$A,逐券汇总!$D24) -> -77100 | AK24: =SUMIFS('逐券逐月(WAVG)'!S:S,'逐券逐月(WAVG)'!$A:$A,逐券汇总!$D24) -> 0 | AL24: =SUMIFS('逐券逐月(WAVG)'!T:T,'逐券逐月(WAVG)'!$A:$A,逐券汇总!$D24) -> 0 | AM24: =SUMIFS('逐券逐月(WAVG)'!U:U,'逐券逐月(WAVG)'!$A:$A,逐券汇总!$D24) -> 0 | AN24: =SUMIFS('逐券逐月(WAVG)'!V:V,'逐券逐月(WAVG)'!$A:$A,逐券汇总!$D24) -> 0
C25: 601900 | D25: 南方传媒 | E25: =AC25-Q25 -> 1843.17 | F25: =AD25-R25 -> 0 | G25: =AE25-S25 -> 0 | H25: =AF25-T25 -> 0 | I25: =AG25-U25 -> 0 | J25: =AH25-V25 -> 0 | K25: =AI25-W25 -> 0 | L25: =AJ25-X25 -> 0 | ... P25: =AN25-AB25 -> 0 | Q25: 171789.54 | R25: 411896.29 | S25: 0 | AC25: =SUMIFS('逐券逐月(WAVG)'!K:K,'逐券逐月(WAVG)'!$A:$A,逐券汇总!$D25) -> 173632.71 | AD25: =SUMIFS('逐券逐月(WAVG)'!L:L,'逐券逐月(WAVG)'!$A:$A,逐券汇总!$D25) -> 411896.29 | AE25: =SUMIFS('逐券逐月(WAVG)'!M:M,'逐券逐月(WAVG)'!$A:$A,逐券汇总!$D25) -> 0 | AF25: =SUMIFS('逐券逐月(WAVG)'!N:N,'逐券逐月(WAVG)'!$A:$A,逐券汇总!$D25) -> 0 | AG25: =SUMIFS('逐券逐月(WAVG)'!O:O,'逐券逐月(WAVG)'!$A:$A,逐券汇总!$D25) -> 0 | AH25: =SUMIFS('逐券逐月(WAVG)'!P:P,'逐券逐月(WAVG)'!$A:$A,逐券汇总!$D25) -> 0 | AI25: =SUMIFS('逐券逐月(WAVG)'!Q:Q,'逐券逐月(WAVG)'!$A:$A,逐券汇总!$D25) -> 0 | AJ25: =SUMIFS('逐券逐月(WAVG)'!R:R,'逐券逐月(WAVG)'!$A:$A,逐券汇总!$D25) -> 0 | AK25: =SUMIFS('逐券逐月(WAVG)'!S:S,'逐券逐月(WAVG)'!$A:$A,逐券汇总!$D25) -> 0 | AL25: =SUMIFS('逐券逐月(WAVG)'!T:T,'逐券逐月(WAVG)'!$A:$A,逐券汇总!$D25) -> 0 | AM25: =SUMIFS('逐券逐月(WAVG)'!U:U,'逐券逐月(WAVG)'!$A:$A,逐券汇总!$D25) -> 0 | AN25: =SUMIFS('逐券逐月(WAVG)'!V:V,'逐券逐月(WAVG)'!$A:$A,逐券汇总!$D25) -> 0
C26: 603198 | D26: 迎驾贡酒 | E26: =AC26-Q26 -> 1313.8 | F26: =AD26-R26 -> 0 | G26: =AE26-S26 -> 0 | H26: =AF26-T26 -> 0 | I26: =AG26-U26 -> 0 | J26: =AH26-V26 -> 0 | K26: =AI26-W26 -> 0 | L26: =AJ26-X26 -> 0 | ... P26: =AN26-AB26 -> 0 | Q26: -310273.7 | R26: 264359.9 | S26: 0 | AC26: =SUMIFS('逐券逐月(WAVG)'!K:K,'逐券逐月(WAVG)'!$A:$A,逐券汇总!$D26) -> -308959.9 | AD26: =SUMIFS('逐券逐月(WAVG)'!L:L,'逐券逐月(WAVG)'!$A:$A,逐券汇总!$D26) -> 264359.9 | AE26: =SUMIFS('逐券逐月(WAVG)'!M:M,'逐券逐月(WAVG)'!$A:$A,逐券汇总!$D26) -> 0 | AF26: =SUMIFS('逐券逐月(WAVG)'!N:N,'逐券逐月(WAVG)'!$A:$A,逐券汇总!$D26) -> 0 | AG26: =SUMIFS('逐券逐月(WAVG)'!O:O,'逐券逐月(WAVG)'!$A:$A,逐券汇总!$D26) -> 0 | AH26: =SUMIFS('逐券逐月(WAVG)'!P:P,'逐券逐月(WAVG)'!$A:$A,逐券汇总!$D26) -> 0 | AI26: =SUMIFS('逐券逐月(WAVG)'!Q:Q,'逐券逐月(WAVG)'!$A:$A,逐券汇总!$D26) -> 0 | AJ26: =SUMIFS('逐券逐月(WAVG)'!R:R,'逐券逐月(WAVG)'!$A:$A,逐券汇总!$D26) -> 0 | AK26: =SUMIFS('逐券逐月(WAVG)'!S:S,'逐券逐月(WAVG)'!$A:$A,逐券汇总!$D26) -> 0 | AL26: =SUMIFS('逐券逐月(WAVG)'!T:T,'逐券逐月(WAVG)'!$A:$A,逐券汇总!$D26) -> 0 | AM26: =SUMIFS('逐券逐月(WAVG)'!U:U,'逐券逐月(WAVG)'!$A:$A,逐券汇总!$D26) -> 0 | AN26: =SUMIFS('逐券逐月(WAVG)'!V:V,'逐券逐月(WAVG)'!$A:$A,逐券汇总!$D26) -> 0
C27: 603369 | D27: 今世缘 | E27: =AC27-Q27 -> 1152.28 | F27: =AD27-R27 -> 0 | G27: =AE27-S27 -> 0 | H27: =AF27-T27 -> 0 | I27: =AG27-U27 -> 0 | J27: =AH27-V27 -> 0 | K27: =AI27-W27 -> 0 | L27: =AJ27-X27 -> 0 | ... P27: =AN27-AB27 -> 0 | Q27: -419369.95 | R27: 374195.67 | S27: 0 | AC27: =SUMIFS('逐券逐月(WAVG)'!K:K,'逐券逐月(WAVG)'!$A:$A,逐券汇总!$D27) -> -418217.67 | AD27: =SUMIFS('逐券逐月(WAVG)'!L:L,'逐券逐月(WAVG)'!$A:$A,逐券汇总!$D27) -> 374195.67 | AE27: =SUMIFS('逐券逐月(WAVG)'!M:M,'逐券逐月(WAVG)'!$A:$A,逐券汇总!$D27) -> 0 | AF27: =SUMIFS('逐券逐月(WAVG)'!N:N,'逐券逐月(WAVG)'!$A:$A,逐券汇总!$D27) -> 0 | AG27: =SUMIFS('逐券逐月(WAVG)'!O:O,'逐券逐月(WAVG)'!$A:$A,逐券汇总!$D27) -> 0 | AH27: =SUMIFS('逐券逐月(WAVG)'!P:P,'逐券逐月(WAVG)'!$A:$A,逐券汇总!$D27) -> 0 | AI27: =SUMIFS('逐券逐月(WAVG)'!Q:Q,'逐券逐月(WAVG)'!$A:$A,逐券汇总!$D27) -> 0 | AJ27: =SUMIFS('逐券逐月(WAVG)'!R:R,'逐券逐月(WAVG)'!$A:$A,逐券汇总!$D27) -> 0 | AK27: =SUMIFS('逐券逐月(WAVG)'!S:S,'逐券逐月(WAVG)'!$A:$A,逐券汇总!$D27) -> 0 | AL27: =SUMIFS('逐券逐月(WAVG)'!T:T,'逐券逐月(WAVG)'!$A:$A,逐券汇总!$D27) -> 0 | AM27: =SUMIFS('逐券逐月(WAVG)'!U:U,'逐券逐月(WAVG)'!$A:$A,逐券汇总!$D27) -> 0 | AN27: =SUMIFS('逐券逐月(WAVG)'!V:V,'逐券逐月(WAVG)'!$A:$A,逐券汇总!$D27) -> 0
C28: H00177 | D28: 江苏宁沪高速公路 | E28: =AC28-Q28 -> 0 | F28: =AD28-R28 -> 0 | G28: =AE28-S28 -> 0 | H28: =AF28-T28 -> 0 | I28: =AG28-U28 -> 0 | J28: =AH28-V28 -> 0 | K28: =AI28-W28 -> 0 | L28: =AJ28-X28 -> 0 | ... P28: =AN28-AB28 -> 0 | R28: 127935.6 | T28: -171944.5 | V28: 7897.5 | X28: 236692.3 | Z28: -120127.8 | AB28: 283260.9 | AC28: =SUMIFS('逐券逐月(WAVG)'!K:K,'逐券逐月(WAVG)'!$A:$A,逐券汇总!$D28) -> 0 | AD28: =SUMIFS('逐券逐月(WAVG)'!L:L,'逐券逐月(WAVG)'!$A:$A,逐券汇总!$D28) -> 127935.6 | AE28: =SUMIFS('逐券逐月(WAVG)'!M:M,'逐券逐月(WAVG)'!$A:$A,逐券汇总!$D28) -> 0 | AF28: =SUMIFS('逐券逐月(WAVG)'!N:N,'逐券逐月(WAVG)'!$A:$A,逐券汇总!$D28) -> -171944.5 | AG28: =SUMIFS('逐券逐月(WAVG)'!O:O,'逐券逐月(WAVG)'!$A:$A,逐券汇总!$D28) -> 0 | AH28: =SUMIFS('逐券逐月(WAVG)'!P:P,'逐券逐月(WAVG)'!$A:$A,逐券汇总!$D28) -> 7897.5 | AI28: =SUMIFS('逐券逐月(WAVG)'!Q:Q,'逐券逐月(WAVG)'!$A:$A,逐券汇总!$D28) -> 0 | AJ28: =SUMIFS('逐券逐月(WAVG)'!R:R,'逐券逐月(WAVG)'!$A:$A,逐券汇总!$D28) -> 236692.3 | AK28: =SUMIFS('逐券逐月(WAVG)'!S:S,'逐券逐月(WAVG)'!$A:$A,逐券汇总!$D28) -> 0 | AL28: =SUMIFS('逐券逐月(WAVG)'!T:T,'逐券逐月(WAVG)'!$A:$A,逐券汇总!$D28) -> -120127.8 | AM28: =SUMIFS('逐券逐月(WAVG)'!U:U,'逐券逐月(WAVG)'!$A:$A,逐券汇总!$D28) -> 0 | AN28: =SUMIFS('逐券逐月(WAVG)'!V:V,'逐券逐月(WAVG)'!$A:$A,逐券汇总!$D28) -> 283260.9
C29: H00300 | D29: 美的集团 | E29: =AC29-Q29 -> 0 | F29: =AD29-R29 -> 0 | G29: =AE29-S29 -> 9219.47 | H29: =AF29-T29 -> 0 | I29: =AG29-U29 -> 0 | J29: =AH29-V29 -> 0 | K29: =AI29-W29 -> 0 | L29: =AJ29-X29 -> 0 | ... P29: =AN29-AB29 -> 0 | R29: -4845.5 | S29: 1193681.3 | T29: -684712.61 | AC29: =SUMIFS('逐券逐月(WAVG)'!K:K,'逐券逐月(WAVG)'!$A:$A,逐券汇总!$D29)-AC5 -> 0 | AD29: =SUMIFS('逐券逐月(WAVG)'!L:L,'逐券逐月(WAVG)'!$A:$A,逐券汇总!$D29)-AD5 -> -4845.5 | AE29: =SUMIFS('逐券逐月(WAVG)'!M:M,'逐券逐月(WAVG)'!$A:$A,逐券汇总!$D29)-AE5 -> 1202900.8 | AF29: =SUMIFS('逐券逐月(WAVG)'!N:N,'逐券逐月(WAVG)'!$A:$A,逐券汇总!$D29)-AF5 -> -684712.61 | AG29: =SUMIFS('逐券逐月(WAVG)'!O:O,'逐券逐月(WAVG)'!$A:$A,逐券汇总!$D29)-AG5 -> 0 | AH29: =SUMIFS('逐券逐月(WAVG)'!P:P,'逐券逐月(WAVG)'!$A:$A,逐券汇总!$D29)-AH5 -> 0 | AI29: =SUMIFS('逐券逐月(WAVG)'!Q:Q,'逐券逐月(WAVG)'!$A:$A,逐券汇总!$D29)-AI5 -> 0 | AJ29: =SUMIFS('逐券逐月(WAVG)'!R:R,'逐券逐月(WAVG)'!$A:$A,逐券汇总!$D29)-AJ5 -> 0 | AK29: =SUMIFS('逐券逐月(WAVG)'!S:S,'逐券逐月(WAVG)'!$A:$A,逐券汇总!$D29)-AK5 -> 0 | AL29: =SUMIFS('逐券逐月(WAVG)'!T:T,'逐券逐月(WAVG)'!$A:$A,逐券汇总!$D29)-AL5 -> 0 | AM29: =SUMIFS('逐券逐月(WAVG)'!U:U,'逐券逐月(WAVG)'!$A:$A,逐券汇总!$D29)-AM5 -> 0 | AN29: =SUMIFS('逐券逐月(WAVG)'!V:V,'逐券逐月(WAVG)'!$A:$A,逐券汇总!$D29)-AN5 -> 0
C30: H00322 | D30: 康师傅控股 | E30: =AC30-Q30 -> 0 | F30: =AD30-R30 -> 595.69 | G30: =AE30-S30 -> 0 | H30: =AF30-T30 -> 0 | I30: =AG30-U30 -> 0 | J30: =AH30-V30 -> 0 | K30: =AI30-W30 -> 0 | L30: =AJ30-X30 -> 0 | ... P30: =AN30-AB30 -> 0 | R30: -7193.55 | T30: 579273.5 | V30: 13442 | X30: -616798 | Z30: -109525 | AB30: -38187.5 | AC30: =SUMIFS('逐券逐月(WAVG)'!K:K,'逐券逐月(WAVG)'!$A:$A,逐券汇总!$D30) -> 0 | AD30: =SUMIFS('逐券逐月(WAVG)'!L:L,'逐券逐月(WAVG)'!$A:$A,逐券汇总!$D30) -> -6597.86 | AE30: =SUMIFS('逐券逐月(WAVG)'!M:M,'逐券逐月(WAVG)'!$A:$A,逐券汇总!$D30) -> 0 | AF30: =SUMIFS('逐券逐月(WAVG)'!N:N,'逐券逐月(WAVG)'!$A:$A,逐券汇总!$D30) -> 579273.5 | AG30: =SUMIFS('逐券逐月(WAVG)'!O:O,'逐券逐月(WAVG)'!$A:$A,逐券汇总!$D30) -> 0 | AH30: =SUMIFS('逐券逐月(WAVG)'!P:P,'逐券逐月(WAVG)'!$A:$A,逐券汇总!$D30) -> 13442 | AI30: =SUMIFS('逐券逐月(WAVG)'!Q:Q,'逐券逐月(WAVG)'!$A:$A,逐券汇总!$D30) -> 0 | AJ30: =SUMIFS('逐券逐月(WAVG)'!R:R,'逐券逐月(WAVG)'!$A:$A,逐券汇总!$D30) -> -616798 | AK30: =SUMIFS('逐券逐月(WAVG)'!S:S,'逐券逐月(WAVG)'!$A:$A,逐券汇总!$D30) -> 0 | AL30: =SUMIFS('逐券逐月(WAVG)'!T:T,'逐券逐月(WAVG)'!$A:$A,逐券汇总!$D30) -> -109525 | AM30: =SUMIFS('逐券逐月(WAVG)'!U:U,'逐券逐月(WAVG)'!$A:$A,逐券汇总!$D30) -> 0 | AN30: =SUMIFS('逐券逐月(WAVG)'!V:V,'逐券逐月(WAVG)'!$A:$A,逐券汇总!$D30) -> -38187.5
C31: H00371 | D31: 北控水务集团 | E31: =AC31-Q31 -> 0 | F31: =AD31-R31 -> 0 | G31: =AE31-S31 -> 0 | H31: =AF31-T31 -> 0 | I31: =AG31-U31 -> 0 | J31: =AH31-V31 -> 0 | K31: =AI31-W31 -> 0 | L31: =AJ31-X31 -> 0 | ... P31: =AN31-AB31 -> 0 | R31: 370302 | T31: 161330 | V31: -160980 | X31: 29788 | Z31: -106784 | AB31: -404650 | AC31: =SUMIFS('逐券逐月(WAVG)'!K:K,'逐券逐月(WAVG)'!$A:$A,逐券汇总!$D31) -> 0 | AD31: =SUMIFS('逐券逐月(WAVG)'!L:L,'逐券逐月(WAVG)'!$A:$A,逐券汇总!$D31) -> 370302 | AE31: =SUMIFS('逐券逐月(WAVG)'!M:M,'逐券逐月(WAVG)'!$A:$A,逐券汇总!$D31) -> 0 | AF31: =SUMIFS('逐券逐月(WAVG)'!N:N,'逐券逐月(WAVG)'!$A:$A,逐券汇总!$D31) -> 161330 | AG31: =SUMIFS('逐券逐月(WAVG)'!O:O,'逐券逐月(WAVG)'!$A:$A,逐券汇总!$D31) -> 0 | AH31: =SUMIFS('逐券逐月(WAVG)'!P:P,'逐券逐月(WAVG)'!$A:$A,逐券汇总!$D31) -> -160980 | AI31: =SUMIFS('逐券逐月(WAVG)'!Q:Q,'逐券逐月(WAVG)'!$A:$A,逐券汇总!$D31) -> 0 | AJ31: =SUMIFS('逐券逐月(WAVG)'!R:R,'逐券逐月(WAVG)'!$A:$A,逐券汇总!$D31) -> 29788 | AK31: =SUMIFS('逐券逐月(WAVG)'!S:S,'逐券逐月(WAVG)'!$A:$A,逐券汇总!$D31) -> 0 | AL31: =SUMIFS('逐券逐月(WAVG)'!T:T,'逐券逐月(WAVG)'!$A:$A,逐券汇总!$D31) -> -106784 | AM31: =SUMIFS('逐券逐月(WAVG)'!U:U,'逐券逐月(WAVG)'!$A:$A,逐券汇总!$D31) -> 0 | AN31: =SUMIFS('逐券逐月(WAVG)'!V:V,'逐券逐月(WAVG)'!$A:$A,逐券汇总!$D31) -> -404650
C32: H00576 | D32: 浙江沪杭甬 | E32: =AC32-Q32 -> 0 | F32: =AD32-R32 -> 0 | G32: =AE32-S32 -> 0 | H32: =AF32-T32 -> 0 | I32: =AG32-U32 -> 0 | J32: =AH32-V32 -> 0 | K32: =AI32-W32 -> 0 | L32: =AJ32-X32 -> 0 | ... P32: =AN32-AB32 -> 0 | R32: 72754.2 | T32: -341229 | V32: 211824 | X32: 257930.4 | Z32: -910373.2 | AB32: 10260 | AC32: =SUMIFS('逐券逐月(WAVG)'!K:K,'逐券逐月(WAVG)'!$A:$A,逐券汇总!$D32) -> 0 | AD32: =SUMIFS('逐券逐月(WAVG)'!L:L,'逐券逐月(WAVG)'!$A:$A,逐券汇总!$D32) -> 72754.2 | AE32: =SUMIFS('逐券逐月(WAVG)'!M:M,'逐券逐月(WAVG)'!$A:$A,逐券汇总!$D32) -> 0 | AF32: =SUMIFS('逐券逐月(WAVG)'!N:N,'逐券逐月(WAVG)'!$A:$A,逐券汇总!$D32) -> -341229 | AG32: =SUMIFS('逐券逐月(WAVG)'!O:O,'逐券逐月(WAVG)'!$A:$A,逐券汇总!$D32) -> 0 | AH32: =SUMIFS('逐券逐月(WAVG)'!P:P,'逐券逐月(WAVG)'!$A:$A,逐券汇总!$D32) -> 211824 | AI32: =SUMIFS('逐券逐月(WAVG)'!Q:Q,'逐券逐月(WAVG)'!$A:$A,逐券汇总!$D32) -> 0 | AJ32: =SUMIFS('逐券逐月(WAVG)'!R:R,'逐券逐月(WAVG)'!$A:$A,逐券汇总!$D32) -> 257930.4 | AK32: =SUMIFS('逐券逐月(WAVG)'!S:S,'逐券逐月(WAVG)'!$A:$A,逐券汇总!$D32) -> 0 | AL32: =SUMIFS('逐券逐月(WAVG)'!T:T,'逐券逐月(WAVG)'!$A:$A,逐券汇总!$D32) -> -906031.56 | AM32: =SUMIFS('逐券逐月(WAVG)'!U:U,'逐券逐月(WAVG)'!$A:$A,逐券汇总!$D32) -> 0 | AN32: =SUMIFS('逐券逐月(WAVG)'!V:V,'逐券逐月(WAVG)'!$A:$A,逐券汇总!$D32) -> 10260
C33: H00728 | D33: 中国电信 | E33: =AC33-Q33 -> 0 | F33: =AD33-R33 -> 0 | G33: =AE33-S33 -> 0 | H33: =AF33-T33 -> 991.02 | I33: =AG33-U33 -> 0 | J33: =AH33-V33 -> 0 | K33: =AI33-W33 -> 3231.54 | L33: =AJ33-X33 -> -312.95 | ... P33: =AN33-AB33 -> 0 | R33: -87509.2 | T33: -743627.7 | V33: -166497 | W33: -474137.66 | X33: 861656.17 | Y33: -285936.45 | Z33: 712962.4 | AC33: =SUMIFS('逐券逐月(WAVG)'!K:K,'逐券逐月(WAVG)'!$A:$A,逐券汇总!$D33) -> 0 | AD33: =SUMIFS('逐券逐月(WAVG)'!L:L,'逐券逐月(WAVG)'!$A:$A,逐券汇总!$D33) -> -87509.2 | AE33: =SUMIFS('逐券逐月(WAVG)'!M:M,'逐券逐月(WAVG)'!$A:$A,逐券汇总!$D33) -> 0 | AF33: =SUMIFS('逐券逐月(WAVG)'!N:N,'逐券逐月(WAVG)'!$A:$A,逐券汇总!$D33) -> -742636.68 | AG33: =SUMIFS('逐券逐月(WAVG)'!O:O,'逐券逐月(WAVG)'!$A:$A,逐券汇总!$D33) -> 0 | AH33: =SUMIFS('逐券逐月(WAVG)'!P:P,'逐券逐月(WAVG)'!$A:$A,逐券汇总!$D33) -> -166497 | AI33: =SUMIFS('逐券逐月(WAVG)'!Q:Q,'逐券逐月(WAVG)'!$A:$A,逐券汇总!$D33) -> -470906.12 | AJ33: =SUMIFS('逐券逐月(WAVG)'!R:R,'逐券逐月(WAVG)'!$A:$A,逐券汇总!$D33) -> 861343.22 | AK33: =SUMIFS('逐券逐月(WAVG)'!S:S,'逐券逐月(WAVG)'!$A:$A,逐券汇总!$D33) -> -278059.51 | AL33: =SUMIFS('逐券逐月(WAVG)'!T:T,'逐券逐月(WAVG)'!$A:$A,逐券汇总!$D33) -> 712284.33 | AM33: =SUMIFS('逐券逐月(WAVG)'!U:U,'逐券逐月(WAVG)'!$A:$A,逐券汇总!$D33) -> 0 | AN33: =SUMIFS('逐券逐月(WAVG)'!V:V,'逐券逐月(WAVG)'!$A:$A,逐券汇总!$D33) -> 0
C34: H00762 | D34: 中国联通 | E34: =AC34-Q34 -> 0 | F34: =AD34-R34 -> 0 | G34: =AE34-S34 -> 0 | H34: =AF34-T34 -> 0 | I34: =AG34-U34 -> 0 | J34: =AH34-V34 -> 0 | K34: =AI34-W34 -> 3194.31 | L34: =AJ34-X34 -> -0.01 | ... P34: =AN34-AB34 -> -1371993.4 | R34: 111293.72 | T34: -586303 | V34: -441303.6 | W34: -713365.61 | X34: 898417.99 | Z34: 174848 | AA34: -1326515.7 | AB34: 1135883 | AC34: =SUMIFS('逐券逐月(WAVG)'!K:K,'逐券逐月(WAVG)'!$A:$A,逐券汇总!$D34) -> 0 | AD34: =SUMIFS('逐券逐月(WAVG)'!L:L,'逐券逐月(WAVG)'!$A:$A,逐券汇总!$D34) -> 111293.72 | AE34: =SUMIFS('逐券逐月(WAVG)'!M:M,'逐券逐月(WAVG)'!$A:$A,逐券汇总!$D34) -> 0 | AF34: =SUMIFS('逐券逐月(WAVG)'!N:N,'逐券逐月(WAVG)'!$A:$A,逐券汇总!$D34) -> -586303 | AG34: =SUMIFS('逐券逐月(WAVG)'!O:O,'逐券逐月(WAVG)'!$A:$A,逐券汇总!$D34) -> 0 | AH34: =SUMIFS('逐券逐月(WAVG)'!P:P,'逐券逐月(WAVG)'!$A:$A,逐券汇总!$D34) -> -441303.6 | AI34: =SUMIFS('逐券逐月(WAVG)'!Q:Q,'逐券逐月(WAVG)'!$A:$A,逐券汇总!$D34) -> -710171.3 | AJ34: =SUMIFS('逐券逐月(WAVG)'!R:R,'逐券逐月(WAVG)'!$A:$A,逐券汇总!$D34) -> 898417.98 | AK34: =SUMIFS('逐券逐月(WAVG)'!S:S,'逐券逐月(WAVG)'!$A:$A,逐券汇总!$D34) -> 0 | AL34: =SUMIFS('逐券逐月(WAVG)'!T:T,'逐券逐月(WAVG)'!$A:$A,逐券汇总!$D34) -> 174848 | AM34: =SUMIFS('逐券逐月(WAVG)'!U:U,'逐券逐月(WAVG)'!$A:$A,逐券汇总!$D34) -> 0 | AN34: =SUMIFS('逐券逐月(WAVG)'!V:V,'逐券逐月(WAVG)'!$A:$A,逐券汇总!$D34) -> -236110.4
C35: H00788 | D35: 中国铁塔 | E35: =AC35-Q35 -> 0 | F35: =AD35-R35 -> 4628.47 | G35: =AE35-S35 -> 0 | H35: =AF35-T35 -> 0 | I35: =AG35-U35 -> 0 | J35: =AH35-V35 -> 0 | K35: =AI35-W35 -> 1874.81 | L35: =AJ35-X35 -> -771.41 | ... P35: =AN35-AB35 -> 2218.42 | R35: -143798.5 | T35: -162402 | V35: -188796 | W35: -59246.93 | X35: 208148.34 | Z35: -539720 | AB35: -86453.42 | AC35: =SUMIFS('逐券逐月(WAVG)'!K:K,'逐券逐月(WAVG)'!$A:$A,逐券汇总!$D35) -> 0 | AD35: =SUMIFS('逐券逐月(WAVG)'!L:L,'逐券逐月(WAVG)'!$A:$A,逐券汇总!$D35) -> -139170.03 | AE35: =SUMIFS('逐券逐月(WAVG)'!M:M,'逐券逐月(WAVG)'!$A:$A,逐券汇总!$D35) -> 0 | AF35: =SUMIFS('逐券逐月(WAVG)'!N:N,'逐券逐月(WAVG)'!$A:$A,逐券汇总!$D35) -> -162402 | AG35: =SUMIFS('逐券逐月(WAVG)'!O:O,'逐券逐月(WAVG)'!$A:$A,逐券汇总!$D35) -> 0 | AH35: =SUMIFS('逐券逐月(WAVG)'!P:P,'逐券逐月(WAVG)'!$A:$A,逐券汇总!$D35) -> -188796 | AI35: =SUMIFS('逐券逐月(WAVG)'!Q:Q,'逐券逐月(WAVG)'!$A:$A,逐券汇总!$D35) -> -57372.12 | AJ35: =SUMIFS('逐券逐月(WAVG)'!R:R,'逐券逐月(WAVG)'!$A:$A,逐券汇总!$D35) -> 207376.93 | AK35: =SUMIFS('逐券逐月(WAVG)'!S:S,'逐券逐月(WAVG)'!$A:$A,逐券汇总!$D35) -> 0 | AL35: =SUMIFS('逐券逐月(WAVG)'!T:T,'逐券逐月(WAVG)'!$A:$A,逐券汇总!$D35) -> -539720 | AM35: =SUMIFS('逐券逐月(WAVG)'!U:U,'逐券逐月(WAVG)'!$A:$A,逐券汇总!$D35) -> 0 | AN35: =SUMIFS('逐券逐月(WAVG)'!V:V,'逐券逐月(WAVG)'!$A:$A,逐券汇总!$D35) -> -84235
C36: H00811 | D36: 新华文轩 | E36: =AC36-Q36 -> 0 | F36: =AD36-R36 -> 0 | G36: =AE36-S36 -> 0 | H36: =AF36-T36 -> 0 | I36: =AG36-U36 -> 0 | J36: =AH36-V36 -> 0 | K36: =AI36-W36 -> 0 | L36: =AJ36-X36 -> 0 | ... P36: =AN36-AB36 -> 0 | R36: 165194.7 | T36: -231835.5 | V36: 64788 | X36: -54009.6 | Z36: -156086.4 | AB36: -29751 | AC36: =SUMIFS('逐券逐月(WAVG)'!K:K,'逐券逐月(WAVG)'!$A:$A,逐券汇总!$D36) -> 0 | AD36: =SUMIFS('逐券逐月(WAVG)'!L:L,'逐券逐月(WAVG)'!$A:$A,逐券汇总!$D36) -> 165194.7 | AE36: =SUMIFS('逐券逐月(WAVG)'!M:M,'逐券逐月(WAVG)'!$A:$A,逐券汇总!$D36) -> 0 | AF36: =SUMIFS('逐券逐月(WAVG)'!N:N,'逐券逐月(WAVG)'!$A:$A,逐券汇总!$D36) -> -231835.5 | AG36: =SUMIFS('逐券逐月(WAVG)'!O:O,'逐券逐月(WAVG)'!$A:$A,逐券汇总!$D36) -> 0 | AH36: =SUMIFS('逐券逐月(WAVG)'!P:P,'逐券逐月(WAVG)'!$A:$A,逐券汇总!$D36) -> 64788 | AI36: =SUMIFS('逐券逐月(WAVG)'!Q:Q,'逐券逐月(WAVG)'!$A:$A,逐券汇总!$D36) -> 0 | AJ36: =SUMIFS('逐券逐月(WAVG)'!R:R,'逐券逐月(WAVG)'!$A:$A,逐券汇总!$D36) -> -54009.6 | AK36: =SUMIFS('逐券逐月(WAVG)'!S:S,'逐券逐月(WAVG)'!$A:$A,逐券汇总!$D36) -> 0 | AL36: =SUMIFS('逐券逐月(WAVG)'!T:T,'逐券逐月(WAVG)'!$A:$A,逐券汇总!$D36) -> -156086.4 | AM36: =SUMIFS('逐券逐月(WAVG)'!U:U,'逐券逐月(WAVG)'!$A:$A,逐券汇总!$D36) -> 0 | AN36: =SUMIFS('逐券逐月(WAVG)'!V:V,'逐券逐月(WAVG)'!$A:$A,逐券汇总!$D36) -> -29751
C37: H00836 | D37: 华润电力 | E37: =AC37-Q37 -> 0 | F37: =AD37-R37 -> 0 | G37: =AE37-S37 -> 3601.76 | H37: =AF37-T37 -> 0 | I37: =AG37-U37 -> 0 | J37: =AH37-V37 -> 0 | K37: =AI37-W37 -> 0 | L37: =AJ37-X37 -> 0 | ... P37: =AN37-AB37 -> 0 | R37: 59821.2 | S37: -152960.11 | T37: 172872.34 | AC37: =SUMIFS('逐券逐月(WAVG)'!K:K,'逐券逐月(WAVG)'!$A:$A,逐券汇总!$D37) -> 0 | AD37: =SUMIFS('逐券逐月(WAVG)'!L:L,'逐券逐月(WAVG)'!$A:$A,逐券汇总!$D37) -> 59821.2 | AE37: =SUMIFS('逐券逐月(WAVG)'!M:M,'逐券逐月(WAVG)'!$A:$A,逐券汇总!$D37) -> -149358.35 | AF37: =SUMIFS('逐券逐月(WAVG)'!N:N,'逐券逐月(WAVG)'!$A:$A,逐券汇总!$D37) -> 172872.34 | AG37: =SUMIFS('逐券逐月(WAVG)'!O:O,'逐券逐月(WAVG)'!$A:$A,逐券汇总!$D37) -> 0 | AH37: =SUMIFS('逐券逐月(WAVG)'!P:P,'逐券逐月(WAVG)'!$A:$A,逐券汇总!$D37) -> 0 | AI37: =SUMIFS('逐券逐月(WAVG)'!Q:Q,'逐券逐月(WAVG)'!$A:$A,逐券汇总!$D37) -> 0 | AJ37: =SUMIFS('逐券逐月(WAVG)'!R:R,'逐券逐月(WAVG)'!$A:$A,逐券汇总!$D37) -> 0 | AK37: =SUMIFS('逐券逐月(WAVG)'!S:S,'逐券逐月(WAVG)'!$A:$A,逐券汇总!$D37) -> 0 | AL37: =SUMIFS('逐券逐月(WAVG)'!T:T,'逐券逐月(WAVG)'!$A:$A,逐券汇总!$D37) -> 0 | AM37: =SUMIFS('逐券逐月(WAVG)'!U:U,'逐券逐月(WAVG)'!$A:$A,逐券汇总!$D37) -> 0 | AN37: =SUMIFS('逐券逐月(WAVG)'!V:V,'逐券逐月(WAVG)'!$A:$A,逐券汇总!$D37) -> 0
C38: H00883 | D38: 中国海洋石油 | E38: =AC38-Q38 -> 0 | F38: =AD38-R38 -> 0 | G38: =AE38-S38 -> 0 | H38: =AF38-T38 -> 3821.7 | I38: =AG38-U38 -> 0 | J38: =AH38-V38 -> 0 | K38: =AI38-W38 -> 0 | L38: =AJ38-X38 -> 0 | ... P38: =AN38-AB38 -> 0 | T38: -61393.91 | V38: 389148 | X38: 136066.8 | Y38: 114675.78 | Z38: -463820.89 | AC38: =SUMIFS('逐券逐月(WAVG)'!K:K,'逐券逐月(WAVG)'!$A:$A,逐券汇总!$D38) -> 0 | AD38: =SUMIFS('逐券逐月(WAVG)'!L:L,'逐券逐月(WAVG)'!$A:$A,逐券汇总!$D38) -> 0 | AE38: =SUMIFS('逐券逐月(WAVG)'!M:M,'逐券逐月(WAVG)'!$A:$A,逐券汇总!$D38) -> 0 | AF38: =SUMIFS('逐券逐月(WAVG)'!N:N,'逐券逐月(WAVG)'!$A:$A,逐券汇总!$D38) -> -57572.21 | AG38: =SUMIFS('逐券逐月(WAVG)'!O:O,'逐券逐月(WAVG)'!$A:$A,逐券汇总!$D38) -> 0 | AH38: =SUMIFS('逐券逐月(WAVG)'!P:P,'逐券逐月(WAVG)'!$A:$A,逐券汇总!$D38) -> 389148 | AI38: =SUMIFS('逐券逐月(WAVG)'!Q:Q,'逐券逐月(WAVG)'!$A:$A,逐券汇总!$D38) -> 0 | AJ38: =SUMIFS('逐券逐月(WAVG)'!R:R,'逐券逐月(WAVG)'!$A:$A,逐券汇总!$D38) -> 136066.8 | AK38: =SUMIFS('逐券逐月(WAVG)'!S:S,'逐券逐月(WAVG)'!$A:$A,逐券汇总!$D38) -> 122441.38 | AL38: =SUMIFS('逐券逐月(WAVG)'!T:T,'逐券逐月(WAVG)'!$A:$A,逐券汇总!$D38) -> -467642.59 | AM38: =SUMIFS('逐券逐月(WAVG)'!U:U,'逐券逐月(WAVG)'!$A:$A,逐券汇总!$D38) -> 0 | AN38: =SUMIFS('逐券逐月(WAVG)'!V:V,'逐券逐月(WAVG)'!$A:$A,逐券汇总!$D38) -> 0
C39: H00939 | D39: 建设银行 | E39: =AC39-Q39 -> 0 | F39: =AD39-R39 -> 0 | G39: =AE39-S39 -> 0 | H39: =AF39-T39 -> 0 | I39: =AG39-U39 -> 0 | J39: =AH39-V39 -> 0 | K39: =AI39-W39 -> 2552.26 | L39: =AJ39-X39 -> 0.01 | ... P39: =AN39-AB39 -> 480559.34 | R39: 148432.9 | T39: -57953.5 | V39: 467621 | W39: 170160.57 | X39: 69701.24 | Z39: -248582.4 | AA39: 425256.2 | AB39: -302700.14 | AC39: =SUMIFS('逐券逐月(WAVG)'!K:K,'逐券逐月(WAVG)'!$A:$A,逐券汇总!$D39) -> 0 | AD39: =SUMIFS('逐券逐月(WAVG)'!L:L,'逐券逐月(WAVG)'!$A:$A,逐券汇总!$D39) -> 148432.9 | AE39: =SUMIFS('逐券逐月(WAVG)'!M:M,'逐券逐月(WAVG)'!$A:$A,逐券汇总!$D39) -> 0 | AF39: =SUMIFS('逐券逐月(WAVG)'!N:N,'逐券逐月(WAVG)'!$A:$A,逐券汇总!$D39) -> -57953.5 | AG39: =SUMIFS('逐券逐月(WAVG)'!O:O,'逐券逐月(WAVG)'!$A:$A,逐券汇总!$D39) -> 0 | AH39: =SUMIFS('逐券逐月(WAVG)'!P:P,'逐券逐月(WAVG)'!$A:$A,逐券汇总!$D39) -> 467621 | AI39: =SUMIFS('逐券逐月(WAVG)'!Q:Q,'逐券逐月(WAVG)'!$A:$A,逐券汇总!$D39) -> 172712.83 | AJ39: =SUMIFS('逐券逐月(WAVG)'!R:R,'逐券逐月(WAVG)'!$A:$A,逐券汇总!$D39) -> 69701.25 | AK39: =SUMIFS('逐券逐月(WAVG)'!S:S,'逐券逐月(WAVG)'!$A:$A,逐券汇总!$D39) -> 0 | AL39: =SUMIFS('逐券逐月(WAVG)'!T:T,'逐券逐月(WAVG)'!$A:$A,逐券汇总!$D39) -> -248582.4 | AM39: =SUMIFS('逐券逐月(WAVG)'!U:U,'逐券逐月(WAVG)'!$A:$A,逐券汇总!$D39) -> 0 | AN39: =SUMIFS('逐券逐月(WAVG)'!V:V,'逐券逐月(WAVG)'!$A:$A,逐券汇总!$D39) -> 177859.2
C40: H00941 | D40: 中国移动 | E40: =AC40-Q40 -> 0 | F40: =AD40-R40 -> 0 | G40: =AE40-S40 -> 0 | H40: =AF40-T40 -> 0 | I40: =AG40-U40 -> 0 | J40: =AH40-V40 -> 0 | K40: =AI40-W40 -> 1600.73 | L40: =AJ40-X40 -> 0 | ... P40: =AN40-AB40 -> 0 | R40: -280257.6 | T40: -200868 | V40: 69750 | W40: -191322.13 | X40: 602684.3 | Z40: -9920 | AB40: -248752 | AC40: =SUMIFS('逐券逐月(WAVG)'!K:K,'逐券逐月(WAVG)'!$A:$A,逐券汇总!$D40) -> 0 | AD40: =SUMIFS('逐券逐月(WAVG)'!L:L,'逐券逐月(WAVG)'!$A:$A,逐券汇总!$D40) -> -280257.6 | AE40: =SUMIFS('逐券逐月(WAVG)'!M:M,'逐券逐月(WAVG)'!$A:$A,逐券汇总!$D40) -> 0 | AF40: =SUMIFS('逐券逐月(WAVG)'!N:N,'逐券逐月(WAVG)'!$A:$A,逐券汇总!$D40) -> -200868 | AG40: =SUMIFS('逐券逐月(WAVG)'!O:O,'逐券逐月(WAVG)'!$A:$A,逐券汇总!$D40) -> 0 | AH40: =SUMIFS('逐券逐月(WAVG)'!P:P,'逐券逐月(WAVG)'!$A:$A,逐券汇总!$D40) -> 69750 | AI40: =SUMIFS('逐券逐月(WAVG)'!Q:Q,'逐券逐月(WAVG)'!$A:$A,逐券汇总!$D40) -> -189721.4 | AJ40: =SUMIFS('逐券逐月(WAVG)'!R:R,'逐券逐月(WAVG)'!$A:$A,逐券汇总!$D40) -> 602684.3 | AK40: =SUMIFS('逐券逐月(WAVG)'!S:S,'逐券逐月(WAVG)'!$A:$A,逐券汇总!$D40) -> 0 | AL40: =SUMIFS('逐券逐月(WAVG)'!T:T,'逐券逐月(WAVG)'!$A:$A,逐券汇总!$D40) -> -9920 | AM40: =SUMIFS('逐券逐月(WAVG)'!U:U,'逐券逐月(WAVG)'!$A:$A,逐券汇总!$D40) -> 0 | AN40: =SUMIFS('逐券逐月(WAVG)'!V:V,'逐券逐月(WAVG)'!$A:$A,逐券汇总!$D40) -> -248752
...

Sheet Sheet3
A2: 六级科目名称
A4: 平安银行 | B4: =COUNTIF(A:A,A4) -> 1
A5: 美的集团 | B5: =COUNTIF(A:A,A5) -> 2
A6: 泸州老窖 | B6: =COUNTIF(A:A,A6) -> 1
A7: 五 粮 液 | B7: =COUNTIF(A:A,A7) -> 1
A8: 江阴银行 | B8: =COUNTIF(A:A,A8) -> 1
A9: 张家港行 | B9: =COUNTIF(A:A,A9) -> 1
A10: 招商银行 | B10: =COUNTIF(A:A,A10) -> 1
A11: 贵州茅台 | B11: =COUNTIF(A:A,A11) -> 1
A12: 海尔智家 | B12: =COUNTIF(A:A,A12) -> 2
A13: 山西汾酒 | B13: =COUNTIF(A:A,A13) -> 1
A14: XD伊利股 | B14: =COUNTIF(A:A,A14) -> 1
A15: 伊利股份 | B15: =COUNTIF(A:A,A15) -> 1
... A59: 卫龙美味 | B59: =COUNTIF(A:A,A59) -> 1

Sheet 逐月核对说明
A1: 项 | B1: 值
A2: 估值日 | B2: 2026-06-08
A3: 报告起点 | B3: 2026-01-01
A4: 月份锚点 | B4: 2026-01-31, 2026-02-28, 2026-03-31, 2026-04-30, 2026-05-31, 2026-06-08
A5: 成本口径 | B5: WAVG（第三轨）移动加权：期初成本入池，卖出按当时均价结转
A6: 期初MTM | B6: 期初持仓在 2026-01-01 盯市浮动 = qty×市价(CNY) − 期初成本
A7: 期初WAVG-持仓成本 | B7: 期初持仓成本合计(CNY)，即 WAVG 成本池起点
A8: WAVG-持仓成本 | B8: 估值日残余 WAVG 成本池（期末）
A9: 月度 RPNL | B9: 当月增量 = 累计 WAVG-RPNL(锚点) − 上月累计
A10: 月度 MTM | B10: 当月增量 = 累计 WAVG-MTM(锚点) − 上月累计；首月减期初MTM
A11: 末行「合计」 | B11: 仅逐券表：各列当月增量/期末值的 SUBTOTAL 求和
A12: 末行「累计」 | B12: 各月 RPNL/MTM 列填截至该月末的组合累计值（非增量）；与右侧累计列末月一致
... A15: 说明 | B15: 独立逐月核对簿（仅三 sheet）；不含领导考核 FIFO；可与 Part_II_a_第三轨 合计对账
